
# Created by Ruins mod version 17.2 Ingame Parser
# authoring Player: Shage_Jack

# TEMPLATE PARAMETER SETTINGS:
#
# criterion expression specifying mod ids required to load template
# may include plus (AND), minus (AND NOT), comma (OR), and parentheses
# all required mods listed must be present; no prohibited mods can be
requiredMods=
#
# likelihood this template will be chosen relative to all others
# e.g., a weight=6 template is chosen 3X as often as one with weight=2
weight=1
#
# list of dimensions in which this template may spawn, even if generic
# one or more dimension names, separated by commas (blank = all)
dimensionsToSpawnIn=
#
# list of other biomes in which this template may spawn
# biome corresponding to directory is always assumed, listed or not
# generic templates should leave this list empty
biomesToSpawnIn=
#
# criterion expression specifying types of biome where template spawns
# this is in addition to those explicitly listed as biomesToSpawnIn
# generic templates should leave this list empty
biomeTypesToSpawnIn=
#
# list of biomes in which this template may not spawn
# takes precedence over biomeTypesToSpawnIn, but NOT biomesToSpawnIn
# should be empty if biomeTypesToSpawnIn is empty
biomesToNotSpawnIn=
#
# depth template is pushed down into the surface when built
# offset is min/max range of random additional bury depth
embed_into_distance=0
random_height_offset=0,0
#
# whitelist/blacklist of block types on which template may be built
# specify one, not both; leave the other empty (both empty = allow all)
acceptable_target_blocks=
unacceptable_target_blocks=flowing_water,water,flowing_lava,lava
#
# size of template (#layers, #rows per layer, #blocks per row)
dimensions=14,15,20
#
# max number of missing blocks allowed in surface beneath template
allowable_overhang=0
#
# depth/height limit affected by terrain leveling
# also maximum bumpiness tolerated in surface beneath template
max_leveling=2
#
# padding applied to all sides of template horizontal footprint
# expands area affected by terrain leveling (-1 = no leveling)
leveling_buffer=0
#
# do not rotate template randomly when built (1 = no rotation)
preventRotation=1
#
# treat water/lava blocks as air and protect them from rule0 (1 = yes)
preserve_water=0
preserve_lava=0
#
# minimum distance this template must have from instances of itself
uniqueMinDistance=0
#
# min/max distances this template can be from world spawn (0 = no limit)
# only applies to overworld--i.e., dimension 0
spawnMinDistance=0
spawnMaxDistance=0
#
# other template built nearby whenever this one is
# syntax: <name>;<relativeX>;<maxYdifference>;<relativeZ>[;<chance>]
# may be used more than once to specify multiple neighbors
adjoining_template=

rule1=0,100,minecraft:grass-0
rule2=0,100,gregtech:concrete-6
rule3=0,100,gregtech:concrete-1
rule4=0,100,gregtech:concrete-4
rule5=0,100,gregtech:concrete-8
rule6=0,100,gregtech:concrete-10
rule7=0,100,gregtech:concrete-0
rule8=0,100,gregtech:concrete-7
rule9=0,100,gregtech:concrete-9
rule10=0,100,gregtech:concrete-5
rule11=0,100,gregtech:concrete-3
rule12=0,100,minecraft:tallgrass-1
rule13=0,100,minecraft:tallgrass-2
rule14=0,100,minecraft:double_plant-3
rule15=0,100,minecraft:double_plant-2
rule16=0,100,soviet:rubbish-2
rule17=0,100,soviet:green_beton_with_ralling-6
rule18=0,100,soviet:beton_with_ralling-6
rule19=0,100,mw:desk_right_alt1-1
rule20=0,100,mw:desk_corner_alt1-1
rule21=0,100,chisel:ironpane-2
rule22=0,100,soviet:rubbish-0
rule23=0,100,mw:desk_middle-0
rule24=0,100,soviet:rubbish-3
rule25=0,100,IInventory;immcraft:shelf;minecraft:air#0#0#0+minecraft:air#0#0#1+minecraft:air#0#0#2+minecraft:air#0#0#3+minecraft:air#0#0#4+minecraft:air#0#0#5+minecraft:air#0#0#6+minecraft:air#0#0#7+minecraft:air#0#0#8+minecraft:air#0#0#9+minecraft:air#0#0#10+minecraft:air#0#0#11+minecraft:air#0#0#12+minecraft:air#0#0#13+minecraft:air#0#0#14+minecraft:air#0#0#15-0
rule26=0,100,immersiveengineering:stone_decoration_stairs_concrete-0
rule27=0,100,soviet:soviet_chair-2
rule28=0,100,IInventory;immcraft:in_world_placer;minecraft:air#0#0#0+minecraft:air#0#0#1+minecraft:stick#1#0#2+minecraft:stick#1#0#3-0
rule29=0,100,immersiveengineering:stone_decoration_stairs_concrete-5
rule30=0,100,mw:desk_left-0
rule31=0,100,minecraft:dirt-1
rule32=0,100,immersiveengineering:stone_decoration_stairs_concrete-3
rule33=0,100,minecraft:double_plant-10
rule34=0,100,gregtech:concrete-2
rule35=0,100,soviet:green_beton_with_ralling-1
rule36=0,100,ChestGenHook:chests/apartmentbuilding1:5-2
rule37=0,100,mw:electric_box_opened-2
rule38=0,100,mw:electric_box-2
rule39=0,100,mw:electric_box-3
rule40=0,100,mw:electric_box_opened-3
rule41=0,100,soviet:vibro_wire_lever-3
rule42=0,100,soviet:soviet_bed-10
rule43=0,100,soviet:soviet_bed-2
rule44=0,100,soviet:toilet-1
rule45=0,100,ChestGenHook:chests/apartmentbuilding0:1-3
rule46=0,100,immersiveengineering:stone_decoration_stairs_concrete-4
rule47=0,100,soviet:rubbish-1
rule48=0,100,immersiveengineering:stone_decoration_stairs_concrete-1
rule49=0,100,soviet:wood_labshelf_upper_break-3
rule50=0,100,gregtech:concrete-11
rule51=0,100,mw:desk_middle-1
rule52=0,100,mw:desk_left-1
rule53=0,100,soviet:pipeangle-2
rule54=0,100,soviet:sink-0
rule55=0,100,soviet:comp-4
rule56=0,100,soviet:electro_board-3
rule57=0,100,soviet:sovietlamp_cracked-2
rule58=0,100,soviet:physical/copper_rings-2

layer
1,1,1,1,1,1,1,1,1,1,1,2,2,2,2,1,1,1,1,1
1,3,3,3,3,5,5,5,3,3,3,3,3,3,3,3,3,4,3,1
1,3,7,7,7,7,5,7,7,7,7,7,7,7,4,4,7,7,3,6
1,3,7,7,7,7,7,7,7,7,7,7,7,7,4,7,7,7,3,6
1,3,7,7,7,7,7,7,7,7,7,7,7,7,7,7,7,7,3,8
1,3,7,7,7,7,7,7,4,4,7,7,7,7,7,7,7,7,3,1
1,3,7,7,7,7,7,7,7,7,7,7,7,7,7,9,7,7,3,1
1,3,7,7,7,7,7,7,7,7,7,2,7,7,10,9,9,7,3,1
1,3,7,6,7,7,7,7,7,7,2,2,2,7,10,10,7,7,3,1
8,3,7,7,7,7,2,7,7,7,2,7,2,2,10,10,7,7,3,1
6,3,7,7,7,2,2,2,7,2,6,7,2,2,2,7,7,7,3,1
6,3,7,7,6,2,2,7,7,2,6,6,2,2,7,7,7,7,3,1
8,3,7,7,6,6,2,7,7,7,2,4,11,7,7,7,7,7,3,1
1,3,3,3,3,3,3,3,3,3,3,3,3,3,3,3,3,3,3,1
1,1,1,1,8,8,8,1,1,1,1,1,1,8,6,6,11,1,1,1
endlayer

layer
0,12,12,15,12,14,12,15,12,14,13,1,2,2,2,0,12,0,12,12
12,3,0,0,18,17,16,0,0,0,0,3,3,3,3,3,0,0,3,0
0,3,0,0,0,5,0,0,0,20,19,7,18,0,0,0,0,0,3,6
0,3,25,0,24,0,24,16,0,23,0,7,22,0,0,21,0,0,3,6
12,3,28,0,0,0,0,0,0,23,27,7,22,0,0,10,26,26,3,1
0,3,31,31,0,0,0,0,0,30,0,7,0,0,16,10,29,29,3,12
0,3,1,1,1,31,31,0,0,0,0,7,0,0,16,18,32,0,3,12
12,3,7,7,7,7,2,2,2,0,0,2,0,0,0,0,18,0,3,12
14,3,2,0,0,0,22,0,0,0,0,0,0,0,0,16,0,0,3,0
8,3,2,17,0,0,0,0,0,0,0,6,0,24,0,16,0,0,3,0
6,3,18,0,0,22,0,0,22,0,0,6,0,0,0,0,0,0,3,15
6,8,0,0,0,0,0,0,0,0,0,0,0,0,0,0,0,0,3,0
8,3,18,0,0,0,0,22,0,0,0,11,11,11,0,0,0,0,3,12
12,3,3,3,3,3,3,3,3,3,11,11,11,11,2,3,3,3,3,12
0,15,12,12,8,8,8,12,0,12,0,12,12,8,6,6,6,12,12,0
endlayer

layer
0,0,0,33,0,33,0,33,0,33,0,14,1,2,1,0,0,0,0,0
0,3,0,0,0,0,0,0,0,0,0,3,3,3,3,4,0,0,3,0
0,3,0,0,0,24,0,0,0,0,0,7,0,0,0,21,0,0,3,1
0,3,0,0,0,0,0,0,0,0,0,7,0,0,0,0,0,0,3,6
0,3,0,0,0,0,0,0,0,0,0,34,0,0,0,10,0,0,11,12
0,3,12,0,0,0,0,0,0,0,0,7,0,0,0,10,26,26,3,0
0,3,12,12,12,13,0,0,0,0,0,7,0,0,0,0,0,29,3,0
0,3,7,7,7,7,2,2,7,0,0,35,0,0,0,0,0,0,3,0
33,3,36,0,0,0,0,0,0,0,0,0,0,0,0,0,0,0,3,0
6,3,0,0,0,0,0,0,0,0,0,0,0,0,0,0,0,37,3,0
6,8,0,0,0,0,0,0,0,0,0,0,0,0,0,0,0,38,3,33
6,0,0,0,0,0,0,0,0,0,0,0,0,0,0,0,0,38,3,0
1,8,0,0,0,0,0,0,0,0,0,6,41,11,39,40,39,0,3,0
0,3,3,3,3,3,3,3,3,3,11,11,11,11,2,3,3,3,3,0
0,33,0,0,1,8,8,0,0,0,0,0,0,1,6,1,1,0,0,0
endlayer

layer
0,0,0,0,0,0,0,0,0,0,0,33,0,2,15,0,0,0,0,0
0,3,0,0,0,0,0,0,0,0,0,3,3,3,3,4,0,0,3,0
0,3,0,0,0,0,0,0,0,0,0,7,0,0,0,21,0,0,3,12
0,3,0,0,0,0,0,0,0,0,0,7,0,0,0,0,0,0,11,1
0,3,0,0,0,0,0,0,0,0,0,34,0,0,0,4,0,0,8,0
0,3,0,0,0,0,0,0,0,0,0,2,0,0,0,10,0,0,8,0
0,3,0,0,0,0,0,0,0,0,0,7,0,0,0,0,0,26,8,0
0,3,7,7,7,7,7,7,7,0,0,35,0,0,0,0,29,29,8,0
0,3,0,0,0,0,0,0,0,0,0,0,0,0,0,0,0,0,3,0
1,8,0,0,0,0,0,0,0,0,0,0,0,0,0,0,0,0,3,0
8,0,0,0,0,0,0,0,0,0,0,0,0,0,0,0,0,0,3,0
8,0,0,0,0,0,0,0,0,0,0,0,0,0,0,0,0,0,3,0
15,8,0,0,0,0,0,0,0,0,0,6,11,11,0,0,0,0,3,0
0,3,3,3,8,8,3,3,3,8,11,11,11,11,2,2,3,3,3,0
0,0,0,0,12,1,1,0,0,0,0,0,0,12,1,12,0,0,0,0
endlayer

layer
0,0,0,0,0,0,0,0,0,0,0,0,0,1,33,0,0,0,0,0
0,3,3,3,3,0,0,0,3,3,3,3,3,3,3,3,0,4,3,0
0,3,2,2,2,2,5,7,7,7,7,7,7,7,7,0,0,0,11,0
0,3,8,2,2,2,7,7,7,7,7,7,7,7,7,0,0,0,11,12
0,3,8,8,2,2,7,7,4,2,4,2,7,7,7,5,0,0,11,0
0,3,7,7,7,7,7,4,2,2,2,2,7,7,7,5,0,0,8,0
0,3,7,7,7,7,7,2,2,2,2,2,7,7,7,10,0,0,8,0
0,3,7,2,2,7,7,7,7,7,7,2,7,7,7,10,26,26,8,0
0,3,7,6,6,2,7,2,2,2,0,2,4,7,7,7,4,4,8,0
12,0,8,6,7,7,2,2,2,2,0,0,0,2,7,7,4,4,3,0
8,0,8,7,7,2,2,2,0,0,0,0,6,2,7,7,7,7,3,0
8,0,8,7,2,2,0,0,0,0,0,0,6,6,7,7,7,7,3,0
33,8,7,7,2,0,0,0,0,0,0,6,6,6,6,7,7,7,3,0
0,3,3,8,0,0,3,3,8,8,6,3,11,11,3,3,3,3,3,0
0,0,0,0,0,14,12,0,0,0,0,0,0,0,15,0,0,0,0,0
endlayer

layer
0,0,0,0,0,0,0,0,0,0,0,0,0,15,0,0,0,0,0,0
0,3,3,8,5,3,5,3,3,3,3,3,3,3,3,3,4,3,3,0
0,3,31,44,31,2,31,31,31,0,0,43,42,8,0,0,0,0,8,0
0,3,31,0,0,2,31,31,0,24,24,0,45,10,0,0,0,0,0,0
0,3,1,31,47,2,31,1,0,0,0,0,0,10,46,32,0,0,8,0
0,3,2,2,1,2,1,0,0,0,0,0,0,10,48,0,0,0,11,0
0,3,2,2,1,2,1,0,0,49,0,0,0,10,0,46,0,0,8,0
0,3,31,31,1,2,2,2,2,2,2,0,0,10,48,48,0,0,8,0
0,3,31,1,1,1,1,52,51,19,0,0,0,0,0,0,0,0,50,0
0,0,50,1,6,2,22,0,0,0,0,0,0,11,0,0,0,0,3,0
1,0,50,6,6,0,0,0,0,0,0,0,0,2,1,0,0,1,3,0
8,0,34,6,0,0,0,0,0,0,0,0,0,2,1,31,31,1,3,0
0,8,0,0,0,0,0,0,0,0,0,0,53,34,31,31,31,1,3,0
0,3,3,8,0,0,3,6,6,8,8,8,3,3,3,3,3,3,3,0
0,0,0,0,0,33,0,0,0,0,0,0,0,0,33,0,0,0,0,0
endlayer

layer
0,0,0,0,0,0,0,0,0,0,0,0,0,33,0,0,0,0,0,0
0,8,8,17,24,3,5,5,5,0,0,3,3,3,3,3,3,3,3,0
0,8,31,0,0,2,0,0,0,0,0,0,0,8,0,0,0,0,8,0
0,3,31,0,0,2,0,0,0,0,0,0,0,11,0,0,0,0,0,0
0,3,54,0,0,2,47,47,0,0,0,0,0,11,0,0,0,0,0,0
0,3,0,47,0,2,0,0,0,0,0,0,0,11,0,0,0,0,6,0
0,3,0,0,22,0,0,0,0,0,0,0,0,8,0,48,0,0,11,0
0,3,0,0,22,0,2,0,2,2,2,0,0,8,0,0,0,0,8,0
0,3,0,0,0,0,0,0,0,55,0,0,0,0,0,0,0,0,50,0
0,0,0,0,22,0,0,0,0,0,0,0,0,0,0,0,0,0,3,0
15,0,0,0,0,0,0,0,0,0,0,0,0,0,0,0,0,0,3,0
0,0,0,0,0,0,0,0,0,0,0,0,0,2,0,0,0,0,3,0
0,8,0,0,0,0,0,0,0,0,0,56,53,34,0,0,0,0,3,0
0,3,8,8,0,0,8,6,6,6,8,3,3,3,3,3,3,3,3,0
0,0,0,0,0,0,0,0,0,0,0,0,0,0,0,0,0,0,0,0
endlayer

layer
0,0,0,0,0,0,0,0,0,0,0,0,0,0,0,0,0,0,0,0
0,8,24,0,0,5,5,5,3,0,0,3,3,3,3,3,3,3,3,0
0,8,31,0,0,2,0,0,0,0,0,0,0,8,0,0,0,0,8,0
0,8,0,0,0,2,0,0,0,0,0,57,0,11,0,0,0,0,0,0
0,8,0,0,0,2,0,0,0,0,0,0,0,8,0,0,0,0,0,0
0,3,0,0,0,0,0,0,0,0,0,0,0,11,0,0,0,0,6,0
0,3,0,0,0,0,0,0,0,0,0,0,0,11,0,0,0,0,11,0
0,3,0,0,0,0,22,0,0,2,2,0,0,8,0,0,0,0,8,0
0,3,0,0,0,0,0,0,0,0,0,0,0,0,0,0,0,0,50,0
0,0,0,0,0,0,0,0,0,0,0,0,0,0,0,0,0,0,50,0
33,0,0,0,0,0,0,0,0,0,0,0,0,0,0,0,0,0,3,0
0,8,0,0,0,0,0,0,0,0,0,0,0,0,0,0,0,0,3,0
0,3,0,0,0,0,0,0,0,0,0,0,0,2,0,0,0,0,3,0
0,8,8,8,0,11,8,8,6,11,8,3,3,3,6,3,6,3,3,0
0,0,0,0,0,0,0,0,0,0,0,0,0,0,0,0,0,0,0,0
endlayer

layer
0,0,0,0,0,0,0,0,0,0,0,0,0,0,0,0,0,0,0,0
0,1,0,0,0,5,8,5,3,11,11,11,3,3,11,11,11,3,3,0
0,8,0,0,0,2,2,2,2,34,34,34,34,50,0,0,8,8,8,0
0,8,0,0,0,6,2,6,6,34,34,34,50,50,0,0,11,8,0,0
0,8,0,0,0,6,6,6,6,6,34,2,34,50,0,0,11,8,0,0
0,8,0,0,0,0,0,2,6,6,34,2,2,11,0,0,11,11,8,0
0,3,0,0,0,0,0,0,2,34,34,34,34,11,0,0,11,11,11,0
0,11,0,0,0,0,0,0,0,2,2,34,34,11,0,0,11,11,11,0
0,11,0,0,0,0,0,0,0,0,0,2,6,11,11,11,11,34,11,0
0,11,0,0,0,0,0,0,0,0,2,2,6,0,6,2,34,34,11,0
0,11,0,0,0,0,0,0,0,0,0,0,2,0,34,34,34,34,3,0
0,3,0,0,0,0,0,0,0,0,0,0,2,2,34,34,34,34,3,0
0,3,0,0,0,0,0,0,0,0,0,0,0,2,2,34,34,34,3,0
0,8,6,8,11,11,11,8,8,3,3,3,3,6,6,6,6,3,3,0
0,0,0,0,0,0,0,0,0,0,0,0,0,0,0,0,0,0,0,0
endlayer

layer
0,0,0,0,0,0,0,0,0,0,0,0,0,0,0,0,0,0,0,0
0,14,0,0,8,11,11,11,11,11,11,11,50,50,50,11,11,11,11,0
0,1,0,0,0,1,1,1,8,8,2,1,1,1,0,0,31,31,11,0
0,11,0,0,0,1,2,1,1,11,2,2,1,1,0,0,31,31,11,0
0,11,0,0,0,1,1,1,1,1,50,8,2,1,0,0,31,26,0,0
0,11,0,0,0,0,0,1,1,1,2,8,2,1,0,0,31,0,0,0
0,11,0,0,0,0,0,0,1,1,1,2,1,1,0,0,0,32,50,0
0,11,0,0,0,0,0,0,0,1,1,1,1,1,0,0,48,0,11,0
0,11,0,0,0,0,0,0,0,0,0,1,1,1,2,1,2,0,11,0
0,11,0,0,0,0,0,0,0,0,0,2,1,0,1,1,1,2,11,0
0,11,0,0,0,0,0,0,0,0,0,0,1,0,1,1,2,1,11,0
0,11,0,0,0,0,0,0,0,0,0,0,1,1,2,1,1,1,11,0
0,11,0,0,0,0,0,0,0,0,0,0,0,1,1,1,1,1,11,0
0,11,6,6,50,11,11,11,11,11,2,2,2,2,6,6,11,11,11,0
0,0,0,0,0,0,0,0,0,0,0,0,0,0,0,0,0,0,0,0
endlayer

layer
0,0,0,0,0,0,0,0,0,0,0,0,0,0,0,0,0,0,0,0
0,33,0,8,11,8,11,2,2,11,11,11,11,50,50,11,11,11,11,0
0,12,0,0,0,0,15,15,1,1,2,0,0,0,0,0,0,31,11,0
0,1,0,0,0,0,2,0,15,2,1,1,0,0,0,0,0,0,11,0
0,11,0,0,0,0,0,47,12,0,1,1,1,0,0,0,16,0,0,0
0,11,0,0,0,0,0,0,15,0,2,8,0,0,0,0,0,0,0,0
0,11,0,0,0,0,0,0,0,47,0,2,0,15,0,0,0,0,50,0
0,50,0,0,0,0,0,0,0,0,15,47,15,0,0,0,0,0,50,0
0,50,0,0,0,0,0,0,0,0,0,0,12,0,16,16,2,0,50,0
0,11,0,0,0,0,0,0,0,0,0,22,0,0,0,12,0,0,50,0
0,11,0,0,0,0,0,0,0,0,0,0,16,0,0,24,0,0,11,0
0,11,0,0,0,0,0,0,0,0,0,0,12,15,2,15,0,12,11,0
0,11,0,0,0,0,0,0,0,0,0,0,0,0,0,0,0,12,11,0
0,11,8,50,50,50,50,2,2,0,0,2,0,0,0,2,11,11,11,0
0,0,0,0,0,0,0,0,0,0,0,0,0,0,0,0,0,0,0,0
endlayer

layer
0,0,0,0,0,0,0,0,0,0,0,0,0,0,0,0,0,0,0,0
0,0,0,0,11,8,8,11,0,0,11,11,11,11,11,0,0,0,11,0
0,0,0,0,0,0,33,33,0,15,0,0,0,0,0,0,0,0,11,0
0,12,0,0,0,0,0,0,33,0,12,16,0,0,0,0,0,0,11,0
0,0,0,0,0,0,0,0,0,0,0,0,12,0,0,0,0,0,11,0
0,11,0,0,0,0,0,0,33,58,58,58,58,0,0,0,0,0,0,0
0,50,0,0,0,0,0,0,0,0,0,0,0,33,0,0,0,0,0,0
0,0,0,0,0,0,0,0,0,0,33,0,33,0,0,0,0,0,0,0
0,0,0,0,0,0,0,0,0,0,0,0,0,0,0,0,0,0,50,0
0,11,0,0,0,0,0,0,0,0,0,0,0,0,0,0,0,0,0,0
0,11,0,0,0,0,0,0,0,0,0,0,0,0,0,0,0,0,0,0
0,11,0,0,0,0,0,0,0,0,0,0,0,33,0,33,0,0,11,0
0,11,0,0,0,0,0,0,0,0,0,0,0,0,0,0,0,0,0,0
0,11,8,50,50,50,0,0,0,0,0,0,0,0,0,0,11,0,11,0
0,0,0,0,0,0,0,0,0,0,0,0,0,0,0,0,0,0,0,0
endlayer

layer
0,0,0,0,0,0,0,0,0,0,0,0,0,0,0,0,0,0,0,0
0,0,0,0,0,0,0,0,0,0,0,11,11,11,0,0,0,0,0,0
0,0,0,0,0,0,0,0,0,33,0,0,0,0,0,0,0,0,0,0
0,0,0,0,0,0,0,0,0,0,0,0,0,0,0,0,0,0,11,0
0,0,0,0,0,0,0,0,0,0,0,0,0,0,0,0,0,0,0,0
0,0,0,0,0,0,0,0,0,0,0,0,0,0,0,0,0,0,0,0
0,0,0,0,0,0,0,0,0,0,0,0,0,0,0,0,0,0,0,0
0,0,0,0,0,0,0,0,0,0,0,0,0,0,0,0,0,0,0,0
0,0,0,0,0,0,0,0,0,0,0,0,0,0,0,0,0,0,0,0
0,0,0,0,0,0,0,0,0,0,0,0,0,0,0,0,0,0,0,0
0,11,0,0,0,0,0,0,0,0,0,0,0,0,0,0,0,0,0,0
0,11,0,0,0,0,0,0,0,0,0,0,0,0,0,0,0,0,0,0
0,8,0,0,0,0,0,0,0,0,0,0,0,0,0,0,0,0,0,0
0,8,8,8,0,0,0,0,0,0,0,0,0,0,0,0,0,0,11,0
0,0,0,0,0,0,0,0,0,0,0,0,0,0,0,0,0,0,0,0
endlayer

layer
0,0,0,0,0,0,0,0,0,0,0,0,0,0,0,0,0,0,0,0
0,0,0,0,0,0,0,0,0,0,0,0,0,0,0,0,0,0,0,0
0,0,0,0,0,0,0,0,0,0,0,0,0,0,0,0,0,0,0,0
0,0,0,0,0,0,0,0,0,0,0,0,0,0,0,0,0,0,0,0
0,0,0,0,0,0,0,0,0,0,0,0,0,0,0,0,0,0,0,0
0,0,0,0,0,0,0,0,0,0,0,0,0,0,0,0,0,0,0,0
0,0,0,0,0,0,0,0,0,0,0,0,0,0,0,0,0,0,0,0
0,0,0,0,0,0,0,0,0,0,0,0,0,0,0,0,0,0,0,0
0,0,0,0,0,0,0,0,0,0,0,0,0,0,0,0,0,0,0,0
0,0,0,0,0,0,0,0,0,0,0,0,0,0,0,0,0,0,0,0
0,0,0,0,0,0,0,0,0,0,0,0,0,0,0,0,0,0,0,0
0,0,0,0,0,0,0,0,0,0,0,0,0,0,0,0,0,0,0,0
0,8,0,0,0,0,0,0,0,0,0,0,0,0,0,0,0,0,0,0
0,8,0,0,0,0,0,0,0,0,0,0,0,0,0,0,0,0,0,0
0,0,0,0,0,0,0,0,0,0,0,0,0,0,0,0,0,0,0,0
endlayer

