
# Created by Ruins mod version 17.2 Ingame Parser
# authoring Player: Shage_Jack

# TEMPLATE PARAMETER SETTINGS:
#
# criterion expression specifying mod ids required to load template
# may include plus (AND), minus (AND NOT), comma (OR), and parentheses
# all required mods listed must be present; no prohibited mods can be
requiredMods=
#
# likelihood this template will be chosen relative to all others
# e.g., a weight=6 template is chosen 3X as often as one with weight=2
weight=1
#
# list of dimensions in which this template may spawn, even if generic
# one or more dimension names, separated by commas (blank = all)
dimensionsToSpawnIn=
#
# list of other biomes in which this template may spawn
# biome corresponding to directory is always assumed, listed or not
# generic templates should leave this list empty
biomesToSpawnIn=
#
# criterion expression specifying types of biome where template spawns
# this is in addition to those explicitly listed as biomesToSpawnIn
# generic templates should leave this list empty
biomeTypesToSpawnIn=
#
# list of biomes in which this template may not spawn
# takes precedence over biomeTypesToSpawnIn, but NOT biomesToSpawnIn
# should be empty if biomeTypesToSpawnIn is empty
biomesToNotSpawnIn=
#
# depth template is pushed down into the surface when built
# offset is min/max range of random additional bury depth
embed_into_distance=0
random_height_offset=0,0
#
# whitelist/blacklist of block types on which template may be built
# specify one, not both; leave the other empty (both empty = allow all)
acceptable_target_blocks=
unacceptable_target_blocks=flowing_water,water,flowing_lava,lava
#
# size of template (#layers, #rows per layer, #blocks per row)
dimensions=13,16,16
#
# max number of missing blocks allowed in surface beneath template
allowable_overhang=0
#
# depth/height limit affected by terrain leveling
# also maximum bumpiness tolerated in surface beneath template
max_leveling=2
#
# padding applied to all sides of template horizontal footprint
# expands area affected by terrain leveling (-1 = no leveling)
leveling_buffer=0
#
# do not rotate template randomly when built (1 = no rotation)
preventRotation=1
#
# treat water/lava blocks as air and protect them from rule0 (1 = yes)
preserve_water=0
preserve_lava=0
#
# minimum distance this template must have from instances of itself
uniqueMinDistance=0
#
# min/max distances this template can be from world spawn (0 = no limit)
# only applies to overworld--i.e., dimension 0
spawnMinDistance=0
spawnMaxDistance=0
#
# other template built nearby whenever this one is
# syntax: <name>;<relativeX>;<maxYdifference>;<relativeZ>[;<chance>]
# may be used more than once to specify multiple neighbors
adjoining_template=

rule1=0,100,minecraft:grass-0
rule2=0,100,minecraft:dirt-0
rule3=0,100,soviet:ye_bricks_3_crack-0
rule4=0,100,soviet:kafels-3
rule5=0,100,soviet:kafels-6
rule6=0,100,soviet:kafels-0
rule7=0,100,minecraft:leaves-4
rule8=0,100,minecraft:leaves-12
rule9=0,100,soviet:ye_bricks_1-0
rule10=0,100,ChestGenHook:chests/drinkfoodplus:5-5
rule11=0,100,minecraft:sand-0
rule12=0,100,soviet:beton_stairs-6
rule13=0,100,soviet:beton_stairs-3
rule14=0,100,minecraft:dirt-1
rule15=0,100,soviet:beton_with_ralling-6
rule16=0,100,soviet:green_beton_with_ralling-6
rule17=0,100,soviet:rusty_iron_door-0
rule18=0,100,soviet:rubbish-1
rule19=0,100,soviet:rubbish-0
rule20=0,100,soviet:iron_beam-0
rule21=0,100,minecraft:double_plant-2
rule22=0,100,soviet:iron_beam_thin-0
rule23=0,100,minecraft:tallgrass-1
rule24=0,100,soviet:rubbish-2
rule25=0,100,soviet:rubbish-3
rule26=0,100,soviet:green_beton_with_ralling-2
rule27=0,100,soviet:betons-3
rule28=0,100,soviet:iron_beam_thin-2
rule29=0,100,ChestGenHook:chests/drinkfood:5-3
rule30=0,100,soviet:green_beton_with_ralling-3
rule31=0,100,soviet:beton_with_ralling-2
rule32=0,100,minecraft:double_plant-3
rule33=0,100,soviet:rusty_iron_door-9
rule34=0,100,minecraft:double_plant-10
rule35=0,100,soviet:beton_with_ralling-3
rule36=0,100,soviet:beton_with_ralling-4
rule37=0,100,soviet:betons-0
rule38=0,100,soviet:beton_with_ralling-1
rule39=0,100,soviet:betons-2
rule40=0,100,soviet:green_beton_with_ralling-1
rule41=0,100,minecraft:tallgrass-2

layer
2,2,2,1,1,1,1,1,1,1,1,1,1,1,1,1
2,3,3,3,3,3,3,3,3,3,3,3,3,3,3,1
2,3,6,5,6,6,5,4,3,3,3,3,3,3,3,1
2,3,6,6,5,6,5,5,3,3,3,3,3,3,3,1
1,3,6,4,6,6,5,4,3,3,3,3,3,3,3,1
1,3,6,5,4,6,6,6,6,4,4,5,6,5,3,1
1,3,6,5,6,5,5,5,6,5,4,6,5,4,3,1
1,4,4,4,5,5,6,4,4,6,4,6,5,6,3,1
1,4,4,6,6,4,6,4,4,6,6,5,5,6,3,1
1,3,5,4,6,6,6,6,6,4,6,6,4,5,3,1
1,3,5,6,4,5,6,4,6,6,4,6,6,6,3,1
1,3,4,6,4,4,6,5,6,4,4,5,6,4,3,1
1,3,6,5,4,5,4,4,6,4,6,5,5,4,3,1
1,3,5,4,5,5,6,6,4,4,5,4,4,5,3,1
1,3,3,3,3,3,3,3,3,3,3,3,3,3,3,1
1,1,1,1,1,1,1,1,1,1,1,1,1,1,1,1
endlayer

layer
3,3,3,8,7,7,0,7,7,7,7,7,7,7,7,0
3,9,3,3,3,9,9,9,9,9,9,9,9,9,3,8
3,9,9,16,15,1,14,1,13,12,11,11,11,10,9,8
3,9,16,16,0,14,1,1,13,12,11,11,11,11,9,8
7,3,16,0,18,18,14,14,9,9,9,9,17,9,9,7
8,9,0,19,0,9,9,14,14,14,11,11,11,11,9,7
8,3,20,20,20,9,9,9,14,14,14,14,14,11,9,7
21,0,0,0,9,9,9,9,7,7,14,14,14,14,9,7
23,0,0,15,1,1,15,22,22,0,22,22,22,9,9,0
8,9,0,0,25,0,3,3,3,15,24,15,16,9,9,7
8,3,0,16,0,16,3,3,16,3,24,15,9,26,9,0
8,9,7,0,28,28,1,22,22,3,22,22,22,27,9,8
23,3,25,0,1,1,1,15,0,25,16,27,27,29,9,8
8,9,0,16,24,1,24,7,15,15,3,24,27,14,9,0
8,3,3,9,9,9,9,9,9,3,9,3,9,9,9,7
23,8,7,7,7,7,7,0,8,7,7,7,8,8,7,0
endlayer

layer
0,0,7,8,0,0,7,7,0,0,0,7,7,7,0,0
7,7,7,30,9,9,3,9,9,9,9,9,9,9,3,0
7,31,0,0,0,0,0,0,0,13,12,11,11,11,3,8
7,9,0,0,0,32,32,0,0,13,12,11,11,11,9,8
8,9,0,0,0,0,21,0,9,3,3,9,33,9,9,7
8,9,0,0,0,24,0,0,0,0,0,11,11,11,3,7
0,9,0,0,0,24,15,24,0,0,0,0,11,11,9,0
34,0,0,0,0,15,15,25,7,0,0,0,0,11,9,0
0,0,0,0,32,23,0,22,22,0,22,22,22,0,9,0
0,9,0,0,0,0,25,25,15,0,0,0,0,9,9,0
8,9,7,0,0,0,15,15,0,0,0,0,16,0,9,0
8,3,0,0,28,28,23,22,22,0,22,22,22,16,9,0
8,3,0,0,23,32,21,0,0,0,0,16,16,14,9,0
8,9,0,0,0,23,0,7,0,0,16,0,16,14,9,0
0,9,9,16,3,9,9,9,9,3,9,9,9,3,9,0
0,0,0,7,7,0,0,8,7,0,7,0,0,0,0,0
endlayer

layer
0,0,0,8,0,0,0,0,0,0,8,0,0,0,0,0
0,7,0,35,9,3,9,9,9,9,9,9,3,9,9,0
7,26,0,0,0,0,0,0,0,0,13,12,11,11,9,7
0,9,0,0,0,34,34,0,0,0,13,12,11,11,9,0
8,3,0,0,0,0,34,0,9,3,9,9,9,9,3,0
7,3,0,0,0,0,0,0,0,0,0,0,11,11,3,7
0,3,0,0,0,0,0,0,0,0,0,0,0,0,9,0
0,0,0,0,0,0,0,7,7,0,0,0,0,0,9,0
0,0,0,0,34,0,0,0,0,0,0,0,0,0,9,0
0,9,0,0,0,0,0,0,0,0,0,0,0,16,9,0
0,9,7,0,0,0,0,0,0,0,31,26,0,0,3,0
0,9,0,0,0,0,0,0,0,35,37,37,36,0,9,0
0,9,0,0,0,34,34,0,0,0,38,38,0,1,9,0
0,9,0,0,0,0,0,0,7,0,0,0,0,14,3,0
0,9,16,0,15,3,3,9,9,9,9,9,9,9,9,0
0,0,0,0,0,0,0,7,0,0,0,0,0,0,0,0
endlayer

layer
0,0,0,0,0,0,0,0,0,0,8,0,0,0,0,0
0,0,0,0,9,9,3,9,3,3,9,9,9,3,9,0
0,0,0,0,0,0,37,37,0,0,0,13,37,37,9,0
0,9,0,0,0,35,37,37,0,0,0,13,39,37,9,0
0,9,0,0,0,35,37,37,37,37,37,39,27,39,3,0
8,9,0,0,0,0,35,37,37,37,39,27,27,27,9,7
8,9,0,0,0,0,0,38,38,38,38,40,27,27,9,0
0,9,0,0,0,0,0,7,0,0,0,0,40,40,9,0
0,3,0,0,0,0,0,0,0,0,0,0,0,0,9,0
0,9,0,0,0,0,0,0,0,0,0,0,0,0,9,0
0,9,7,0,0,0,0,0,0,0,0,0,0,0,9,0
0,9,0,0,0,0,0,0,0,0,15,16,0,0,9,0
0,9,0,0,0,0,0,0,0,0,0,0,0,23,9,0
0,9,0,0,0,0,0,0,7,0,0,0,0,1,9,0
0,0,0,0,0,15,3,9,3,3,9,9,3,3,9,0
0,0,0,0,0,0,0,7,0,0,0,0,0,0,0,0
endlayer

layer
0,0,0,0,0,0,0,0,0,0,8,0,0,0,0,0
0,0,0,0,15,9,3,9,3,9,3,9,9,3,9,0
0,0,0,0,0,0,0,0,0,0,0,0,11,11,9,0
0,9,0,0,0,0,3,0,0,0,0,0,0,11,3,0
0,9,0,0,0,0,3,3,0,0,0,0,0,0,9,0
0,9,0,0,0,0,0,22,22,22,0,0,0,0,9,7
8,3,0,0,0,0,0,0,7,0,0,0,0,0,9,0
8,9,0,0,0,0,0,0,7,0,0,0,0,0,9,0
0,3,0,0,0,0,0,0,0,0,0,0,0,0,3,0
0,9,0,0,0,0,0,0,0,0,0,0,0,0,3,0
0,9,7,0,0,0,0,0,0,0,0,0,0,0,3,0
0,9,0,0,0,0,0,0,0,0,0,0,0,0,3,0
0,9,0,0,0,0,0,0,0,0,0,0,0,0,9,0
0,9,0,0,0,0,0,0,7,0,0,0,0,23,15,0
0,0,0,0,0,0,9,9,3,9,9,3,3,0,0,0
0,0,0,0,0,0,0,8,0,0,0,0,0,0,0,0
endlayer

layer
0,0,0,0,0,0,0,0,0,0,7,8,0,0,0,0
0,0,0,0,0,15,9,3,9,9,9,9,9,9,3,0
0,0,0,0,0,0,0,0,0,0,0,0,0,11,9,0
0,15,0,0,0,0,15,0,0,0,0,0,0,0,9,0
0,15,0,0,0,0,15,15,0,0,0,0,0,0,9,0
0,3,0,0,0,0,0,22,22,22,0,0,0,0,9,0
0,9,0,0,0,0,0,0,8,0,0,0,0,0,3,7
7,3,0,0,0,0,0,0,0,0,0,0,0,0,9,0
8,9,0,0,0,0,0,0,0,0,0,0,0,0,9,0
0,9,7,0,0,0,0,0,0,0,0,0,0,0,9,0
0,9,8,0,0,0,0,0,0,0,0,0,0,0,9,0
0,3,0,0,0,0,0,0,0,0,0,0,0,0,9,0
0,9,0,0,0,0,0,0,0,0,0,0,0,0,15,0
0,9,0,0,0,0,0,0,0,7,0,0,0,0,0,0
0,0,0,0,0,0,15,9,3,9,15,15,0,0,0,0
0,0,0,0,0,0,0,0,8,0,0,0,0,0,0,0
endlayer

layer
0,0,0,0,0,0,0,0,0,0,0,8,0,0,0,0
0,0,0,0,0,0,9,3,9,9,9,9,3,9,9,0
0,0,0,0,0,0,0,0,0,0,0,0,0,0,9,0
0,0,0,0,0,0,0,0,0,0,0,0,0,0,3,0
0,0,0,0,0,0,0,0,0,0,0,0,0,0,9,0
0,9,0,0,0,0,0,0,0,0,0,0,0,0,9,0
0,9,0,0,0,0,0,0,8,0,0,0,0,0,9,7
0,9,0,0,0,0,0,0,0,0,0,0,0,0,3,0
7,3,0,0,0,0,0,0,0,0,0,0,0,0,3,0
7,9,7,0,0,0,0,0,0,0,0,0,0,0,9,0
0,3,0,0,0,0,0,0,0,0,0,0,0,0,9,0
0,3,0,0,0,0,0,0,0,0,0,0,0,0,3,0
0,9,0,0,0,0,0,0,0,0,0,0,0,0,0,0
0,3,0,0,0,0,0,0,0,7,0,0,0,0,0,0
0,0,0,0,0,0,0,15,7,15,0,0,0,0,0,0
0,0,0,0,0,0,0,0,0,0,0,0,0,0,0,0
endlayer

layer
0,0,0,0,0,0,0,0,0,0,7,7,0,0,0,0
0,0,0,0,0,0,9,3,9,3,9,9,3,9,9,0
0,0,0,0,0,0,0,0,0,0,0,0,0,0,3,0
0,0,0,0,0,0,0,0,0,0,0,0,0,0,9,0
0,0,0,0,0,0,0,0,0,0,0,0,0,0,9,0
0,0,0,0,0,0,0,0,0,0,0,0,0,0,9,0
0,15,0,0,0,0,0,0,8,8,0,0,0,0,9,7
0,3,0,0,0,0,0,0,0,0,0,0,0,0,9,7
0,3,0,0,0,0,0,0,0,0,0,0,0,0,9,0
0,7,7,0,0,0,0,0,0,0,0,0,0,0,15,0
0,15,0,0,0,0,0,0,0,0,0,0,0,0,15,0
0,15,0,0,0,0,0,0,0,0,0,0,0,0,0,0
0,3,0,0,0,0,0,0,0,0,0,0,0,0,0,0
0,0,0,0,0,0,0,0,0,0,0,0,0,0,0,0
0,0,0,0,0,0,0,0,0,0,0,0,0,0,0,0
0,0,0,0,0,0,0,0,0,0,0,0,0,0,0,0
endlayer

layer
0,0,0,0,0,0,0,0,0,0,7,0,0,0,0,0
0,0,0,0,0,0,0,9,9,9,9,9,9,9,9,0
0,0,0,0,0,0,0,3,9,9,9,3,9,3,9,0
0,0,0,0,0,0,0,9,3,9,9,9,9,3,9,0
0,0,0,0,0,0,0,0,0,3,9,3,3,3,9,0
0,0,0,0,0,0,0,0,0,7,3,3,3,3,3,0
0,0,0,0,0,0,0,0,0,8,7,0,7,3,9,0
0,15,0,0,0,0,0,0,0,0,0,0,0,0,9,7
0,0,0,0,0,0,0,0,0,0,0,0,0,0,0,0
0,0,0,0,0,0,0,0,0,0,0,0,0,0,0,0
0,0,0,0,0,0,0,0,0,0,0,0,0,0,0,0
0,0,0,0,0,0,0,0,0,0,0,0,0,0,0,0
0,0,0,0,0,0,0,0,0,0,0,0,0,0,0,0
0,0,0,0,0,0,0,0,0,0,0,0,0,0,0,0
0,0,0,0,0,0,0,0,0,0,0,0,0,0,0,0
0,0,0,0,0,0,0,0,0,0,0,0,0,0,0,0
endlayer

layer
0,0,0,0,0,0,0,0,0,0,0,0,0,0,0,0
0,0,0,0,0,0,0,0,1,1,8,1,1,1,0,0
0,0,0,0,0,0,0,1,1,1,1,1,1,1,1,0
0,0,0,0,0,0,0,1,1,1,1,1,1,1,1,0
0,0,0,0,0,0,0,0,0,0,1,1,1,1,1,0
0,0,0,0,0,0,0,0,0,0,7,7,1,7,1,0
0,0,0,0,0,0,0,0,0,0,0,7,0,7,0,0
0,0,0,0,0,0,0,0,0,0,0,0,0,0,7,0
0,0,0,0,0,0,0,0,0,0,0,0,0,0,0,0
0,0,0,0,0,0,0,0,0,0,0,0,0,0,0,0
0,0,0,0,0,0,0,0,0,0,0,0,0,0,0,0
0,0,0,0,0,0,0,0,0,0,0,0,0,0,0,0
0,0,0,0,0,0,0,0,0,0,0,0,0,0,0,0
0,0,0,0,0,0,0,0,0,0,0,0,0,0,0,0
0,0,0,0,0,0,0,0,0,0,0,0,0,0,0,0
0,0,0,0,0,0,0,0,0,0,0,0,0,0,0,0
endlayer

layer
0,0,0,0,0,0,0,0,0,0,0,0,0,0,0,0
0,0,0,0,0,0,0,0,32,0,0,8,0,0,0,0
0,0,0,0,0,0,0,41,21,21,0,21,8,0,21,0
0,0,0,0,0,0,0,0,41,32,0,0,7,21,0,0
0,0,0,0,0,0,0,0,0,0,32,21,7,7,7,0
0,0,0,0,0,0,0,0,0,0,0,0,7,0,0,0
0,0,0,0,0,0,0,0,0,0,0,0,0,0,0,0
0,0,0,0,0,0,0,0,0,0,0,0,0,0,0,0
0,0,0,0,0,0,0,0,0,0,0,0,0,0,0,0
0,0,0,0,0,0,0,0,0,0,0,0,0,0,0,0
0,0,0,0,0,0,0,0,0,0,0,0,0,0,0,0
0,0,0,0,0,0,0,0,0,0,0,0,0,0,0,0
0,0,0,0,0,0,0,0,0,0,0,0,0,0,0,0
0,0,0,0,0,0,0,0,0,0,0,0,0,0,0,0
0,0,0,0,0,0,0,0,0,0,0,0,0,0,0,0
0,0,0,0,0,0,0,0,0,0,0,0,0,0,0,0
endlayer

layer
0,0,0,0,0,0,0,0,0,0,0,0,0,0,0,0
0,0,0,0,0,0,0,0,34,0,0,0,0,0,0,0
0,0,0,0,0,0,0,0,34,34,0,34,0,0,34,0
0,0,0,0,0,0,0,0,0,34,0,0,0,34,0,0
0,0,0,0,0,0,0,0,0,0,34,34,0,0,0,0
0,0,0,0,0,0,0,0,0,0,0,0,0,0,0,0
0,0,0,0,0,0,0,0,0,0,0,0,0,0,0,0
0,0,0,0,0,0,0,0,0,0,0,0,0,0,0,0
0,0,0,0,0,0,0,0,0,0,0,0,0,0,0,0
0,0,0,0,0,0,0,0,0,0,0,0,0,0,0,0
0,0,0,0,0,0,0,0,0,0,0,0,0,0,0,0
0,0,0,0,0,0,0,0,0,0,0,0,0,0,0,0
0,0,0,0,0,0,0,0,0,0,0,0,0,0,0,0
0,0,0,0,0,0,0,0,0,0,0,0,0,0,0,0
0,0,0,0,0,0,0,0,0,0,0,0,0,0,0,0
0,0,0,0,0,0,0,0,0,0,0,0,0,0,0,0
endlayer

