
# Created by Ruins mod version 17.2 Ingame Parser
# authoring Player: Shage_Jack

# TEMPLATE PARAMETER SETTINGS:
#
# criterion expression specifying mod ids required to load template
# may include plus (AND), minus (AND NOT), comma (OR), and parentheses
# all required mods listed must be present; no prohibited mods can be
requiredMods=
#
# likelihood this template will be chosen relative to all others
# e.g., a weight=6 template is chosen 3X as often as one with weight=2
weight=1
#
# list of dimensions in which this template may spawn, even if generic
# one or more dimension names, separated by commas (blank = all)
dimensionsToSpawnIn=
#
# list of other biomes in which this template may spawn
# biome corresponding to directory is always assumed, listed or not
# generic templates should leave this list empty
biomesToSpawnIn=
#
# criterion expression specifying types of biome where template spawns
# this is in addition to those explicitly listed as biomesToSpawnIn
# generic templates should leave this list empty
biomeTypesToSpawnIn=
#
# list of biomes in which this template may not spawn
# takes precedence over biomeTypesToSpawnIn, but NOT biomesToSpawnIn
# should be empty if biomeTypesToSpawnIn is empty
biomesToNotSpawnIn=
#
# depth template is pushed down into the surface when built
# offset is min/max range of random additional bury depth
embed_into_distance=0
random_height_offset=0,0
#
# whitelist/blacklist of block types on which template may be built
# specify one, not both; leave the other empty (both empty = allow all)
acceptable_target_blocks=
unacceptable_target_blocks=flowing_water,water,flowing_lava,lava
#
# size of template (#layers, #rows per layer, #blocks per row)
dimensions=16,15,20
#
# max number of missing blocks allowed in surface beneath template
allowable_overhang=0
#
# depth/height limit affected by terrain leveling
# also maximum bumpiness tolerated in surface beneath template
max_leveling=2
#
# padding applied to all sides of template horizontal footprint
# expands area affected by terrain leveling (-1 = no leveling)
leveling_buffer=0
#
# do not rotate template randomly when built (1 = no rotation)
preventRotation=1
#
# treat water/lava blocks as air and protect them from rule0 (1 = yes)
preserve_water=0
preserve_lava=0
#
# minimum distance this template must have from instances of itself
uniqueMinDistance=0
#
# min/max distances this template can be from world spawn (0 = no limit)
# only applies to overworld--i.e., dimension 0
spawnMinDistance=0
spawnMaxDistance=0
#
# other template built nearby whenever this one is
# syntax: <name>;<relativeX>;<maxYdifference>;<relativeZ>[;<chance>]
# may be used more than once to specify multiple neighbors
adjoining_template=

rule1=0,100,minecraft:grass-0
rule2=0,100,gregtech:concrete-6
rule3=0,100,primal:cinis_block-0
rule4=0,100,minecraft:dirt-0
rule5=0,100,gregtech:concrete-1
rule6=0,100,soviet:betons-8
rule7=0,100,soviet:betons-9
rule8=0,100,gregtech:concrete-10
rule9=0,100,gregtech:concrete-7
rule10=0,100,gregtech:concrete-3
rule11=0,100,minecraft:tallgrass-1
rule12=0,100,minecraft:leaves-4
rule13=0,100,soviet:green_beton_with_ralling-4
rule14=0,100,gregtech:concrete-8
rule15=0,100,soviet:green_beton_with_ralling-3
rule16=0,100,gregtech:concrete-9
rule17=0,100,gregtech:concrete-5
rule18=0,100,minecraft:sand-0
rule19=0,100,soviet:beton_with_ralling-6
rule20=0,100,soviet:green_beton_with_ralling-1
rule21=0,100,chisel:ironpane-2
rule22=0,100,biomesoplenty:poison-1
rule23=0,100,soviet:rubbish-3
rule24=0,100,immersiveengineering:stone_decoration_stairs_concrete-0
rule25=0,100,biomesoplenty:poison-0
rule26=0,100,immersiveengineering:stone_decoration_stairs_concrete-5
rule27=0,100,soviet:rubbish-2
rule28=0,100,minecraft:dirt-1
rule29=0,100,immersiveengineering:stone_decoration_stairs_concrete-3
rule30=0,100,ChestGenHook:chests/apartmentbuilding1:5-2
rule31=0,100,minecraft:double_plant-3
rule32=0,100,soviet:green_beton_with_ralling-6
rule33=0,100,minecraft:double_plant-2
rule34=0,100,minecraft:leaves-12
rule35=0,100,gregtech:concrete-4
rule36=0,100,primal:ore_bog_iron-2
rule37=0,100,gregtech:concrete-2
rule38=0,100,minecraft:double_plant-10
rule39=0,100,mw:electric_box_opened-2
rule40=0,100,mw:electric_box-2
rule41=0,100,mw:electric_box-3
rule42=0,100,mw:electric_box_opened-3
rule43=0,100,soviet:vibro_wire_lever-3
rule44=0,100,soviet:rubbish-0
rule45=0,100,immersiveengineering:stone_decoration_stairs_concrete-2
rule46=0,100,ChestGenHook:chests/apartmentbuilding2:1-3
rule47=0,100,soviet:sink-1
rule48=0,100,soviet:wood_labshelf_upper_break-2
rule49=0,100,soviet:keyboard-2
rule50=0,100,soviet:toilet-2
rule51=0,100,soviet:comp-2
rule52=0,100,immersiveengineering:stone_decoration_stairs_concrete-1
rule53=0,100,soviet:wood_labshelf_upper-0
rule54=0,100,gregtech:concrete-11
rule55=0,100,soviet:pipeangle-2
rule56=0,100,soviet:rubbish-1
rule57=0,100,quark:colored_flowerpot_white-0
rule58=0,100,soviet:physical/copper_rings-3
rule59=0,100,soviet:electro_board-3
rule60=0,100,soviet:sovietlamp_cracked-2
rule61=0,100,minecraft:red_flower-3
rule62=0,100,minecraft:red_flower-8
rule63=0,100,minecraft:red_flower-0
rule64=0,100,minecraft:log-0
rule65=0,100,minecraft:yellow_flower-0
rule66=0,100,minecraft:leaves-0

layer
1,1,1,1,4,4,1,3,3,3,1,2,2,2,2,1,1,1,1,1
1,5,6,6,6,6,6,6,7,7,6,6,6,6,6,6,6,6,5,1
1,5,7,7,6,6,7,7,6,7,6,6,6,6,7,6,6,6,5,8
1,5,7,6,7,6,6,6,6,6,6,6,6,6,6,6,6,6,5,8
1,5,6,7,7,7,6,6,6,7,6,6,6,6,6,6,7,6,5,9
1,5,6,6,6,6,6,6,7,7,6,6,6,6,6,6,6,6,5,1
1,5,6,6,6,6,6,6,6,6,7,6,6,6,6,6,6,6,5,1
1,5,6,6,6,6,6,6,7,6,7,6,6,7,6,7,6,6,5,1
1,5,6,6,6,7,7,6,6,7,6,6,7,7,7,6,6,7,5,1
9,5,6,6,6,7,6,6,6,6,7,6,7,6,7,6,6,6,5,1
8,5,7,6,6,6,6,6,6,7,6,6,6,6,6,6,6,6,5,1
8,5,6,6,6,6,7,6,6,6,6,6,6,6,7,6,6,7,5,1
9,5,6,6,6,6,6,6,6,6,6,6,6,7,7,6,6,6,5,1
1,5,5,5,5,5,5,5,5,5,5,5,5,5,5,5,5,5,5,1
1,1,1,1,9,9,9,1,1,1,1,1,1,9,8,8,10,1,1,1
endlayer

layer
0,11,11,15,14,14,13,0,0,0,12,1,2,2,2,0,11,0,11,11
11,16,0,15,10,14,14,3,3,3,3,5,17,5,5,17,0,0,16,0
0,17,0,18,20,14,3,3,18,18,18,6,19,18,18,18,18,18,17,8
0,17,0,18,23,18,3,3,18,18,18,6,22,18,18,21,18,18,5,8
11,5,18,18,18,18,18,18,18,18,18,6,25,18,18,17,24,24,17,1
0,17,28,28,18,18,18,18,18,18,25,6,25,18,27,17,26,26,5,11
0,17,1,1,4,28,28,25,18,18,18,7,18,18,27,19,29,0,5,11
11,5,7,6,6,6,2,2,2,18,18,2,18,18,18,18,19,18,5,12
31,17,30,18,18,18,25,18,18,18,18,18,18,18,18,27,18,18,17,12
9,16,2,32,18,18,18,18,18,25,18,8,18,23,18,27,18,0,5,0
8,17,19,2,2,25,18,18,25,18,18,8,18,18,22,18,18,0,17,33
8,9,2,2,14,2,25,18,18,25,18,18,18,18,18,18,18,0,5,0
9,16,2,14,14,14,14,25,18,18,18,10,10,10,18,0,18,18,5,11
11,16,5,5,5,5,16,5,17,16,10,10,10,10,2,5,17,5,17,11
0,33,12,11,9,9,9,11,0,11,0,11,11,9,8,8,8,11,11,0
endlayer

layer
0,0,0,0,32,32,0,0,0,0,0,34,1,2,1,0,0,0,0,0
0,5,0,15,14,14,14,23,23,23,0,5,17,17,5,35,0,0,17,0
0,5,0,0,20,23,32,23,3,3,3,7,0,0,0,21,0,18,5,1
0,17,0,0,0,18,36,23,3,3,18,6,0,18,18,18,18,18,17,8
0,17,0,0,18,3,18,18,18,18,18,37,0,18,22,17,18,18,10,11
0,5,11,0,18,18,18,18,18,18,25,6,22,18,22,17,24,24,17,0
0,17,11,11,18,18,18,25,22,25,25,7,18,18,22,18,18,26,5,34
0,17,6,7,7,6,2,2,25,18,18,20,18,25,22,22,22,25,8,12
38,17,18,18,18,18,25,25,25,25,18,22,18,18,18,22,18,18,17,0
8,5,18,18,18,25,18,25,25,25,18,18,22,18,18,22,22,39,5,0
8,9,18,18,25,25,25,18,25,18,18,18,18,18,25,18,18,40,17,38
8,25,25,18,2,18,25,18,18,25,18,25,22,18,22,22,18,40,17,0
1,9,18,2,14,18,18,25,25,25,18,8,43,10,41,42,41,18,5,0
0,5,17,5,16,5,17,17,17,5,10,10,10,10,2,5,5,5,17,0
0,38,12,0,1,9,9,0,0,0,0,0,0,1,8,1,1,0,0,0
endlayer

layer
0,0,0,0,0,0,0,0,0,0,0,34,11,2,33,0,0,0,0,0
0,5,0,9,10,3,44,0,0,0,0,5,17,5,17,35,0,0,17,0
0,5,0,0,0,0,0,0,23,23,3,6,0,0,0,21,0,0,17,11
0,17,0,0,0,3,0,0,3,3,18,6,0,0,0,18,12,18,10,1
0,17,0,0,0,3,3,3,18,25,18,37,0,18,0,35,45,45,9,0
0,5,0,0,18,18,18,25,25,25,25,2,22,25,22,17,18,0,9,0
0,5,0,0,0,18,18,25,22,25,25,6,18,18,25,18,18,24,9,12
0,5,6,6,6,6,6,18,25,25,25,20,18,25,22,25,26,26,8,34
0,5,25,25,25,25,25,25,25,25,25,25,18,25,25,25,25,25,17,0
1,9,18,25,18,25,25,22,25,25,18,18,22,18,25,25,25,18,5,0
9,18,25,18,25,25,25,25,25,18,18,25,25,25,25,25,25,25,17,0
9,25,25,18,18,25,25,18,18,25,25,25,25,18,25,22,25,25,5,0
33,9,25,18,18,18,18,25,22,25,18,8,10,10,18,25,18,25,17,0
0,5,5,5,9,9,5,17,5,9,10,10,10,10,2,2,5,5,17,0
0,0,12,0,11,1,1,0,0,0,0,0,0,11,1,11,0,0,0,0
endlayer

layer
0,0,0,0,0,0,0,0,0,0,0,34,0,1,38,0,0,0,0,0
0,16,5,0,10,3,0,0,0,0,5,17,5,17,17,17,0,35,5,0
0,5,2,2,3,0,0,0,0,0,6,6,6,6,6,0,0,0,10,0
0,17,9,2,2,3,0,0,3,6,6,6,6,7,7,12,0,0,10,11
0,17,9,9,2,3,0,3,35,2,35,2,6,6,6,14,12,12,10,0
0,5,7,7,6,6,6,35,2,2,2,2,6,7,6,14,24,12,9,0
0,5,7,6,7,6,6,2,2,2,2,2,6,6,7,17,0,18,8,12
0,5,6,2,2,6,6,6,6,6,6,2,6,6,7,17,24,24,9,0
0,17,6,8,8,2,7,2,2,2,25,2,35,6,7,6,35,35,9,0
11,0,9,8,6,7,2,2,2,2,25,25,25,2,6,7,35,35,17,0
9,18,9,7,6,2,2,2,25,25,25,25,8,2,7,6,6,6,5,0
9,25,25,25,25,25,25,25,25,25,25,25,8,8,6,6,6,6,17,0
38,9,25,25,18,25,18,25,25,25,25,8,8,8,8,7,7,6,17,0
0,17,5,9,18,18,17,17,9,9,8,5,10,10,5,5,5,5,5,0
0,0,12,12,0,31,11,0,0,0,0,0,0,0,33,0,0,0,0,0
endlayer

layer
0,0,0,0,0,0,0,0,0,0,0,12,0,11,0,0,0,0,0,0
0,17,17,9,14,23,0,0,0,0,5,17,5,17,5,17,35,5,10,0
0,5,28,47,28,0,0,0,0,0,27,0,46,9,0,0,0,0,9,0
0,5,28,0,50,0,0,0,27,23,23,49,48,17,12,0,0,0,0,0
0,5,1,1,3,0,0,3,3,0,0,0,51,17,12,12,12,12,9,0
0,5,2,2,2,3,3,3,27,0,27,0,0,17,52,12,12,12,10,0
0,5,2,2,1,2,3,3,0,23,0,27,0,17,0,0,12,12,8,34
0,5,28,28,1,2,2,2,2,2,2,0,0,17,52,52,12,0,9,0
0,17,28,1,1,1,1,53,53,0,0,0,0,0,0,0,0,0,9,0
0,0,54,1,8,2,44,0,0,0,0,0,0,10,0,0,0,0,5,0
1,0,54,8,8,0,0,27,0,0,0,0,0,2,1,0,0,1,5,0
9,0,0,0,0,0,0,0,0,0,0,0,0,2,1,28,28,1,17,0
0,9,0,0,23,0,23,0,0,0,0,0,55,37,28,28,28,1,17,0
0,5,17,9,18,23,16,8,8,9,9,9,5,5,5,5,5,17,17,0
0,0,0,34,0,38,0,0,0,0,0,0,0,0,38,0,0,0,0,0
endlayer

layer
0,0,0,0,0,0,0,0,0,0,0,0,34,0,0,0,0,0,0,0
0,9,9,32,23,0,0,0,0,0,56,5,17,5,16,17,16,5,10,0
0,9,28,0,0,0,0,0,0,0,0,0,0,9,0,0,0,0,9,0
0,16,28,0,23,0,0,0,0,0,0,0,0,10,0,0,0,0,0,0
0,5,0,0,0,0,0,56,0,0,0,0,0,10,12,0,0,12,12,0
0,17,0,56,27,23,23,44,0,0,0,0,0,10,0,12,12,12,8,34
0,5,0,0,44,0,0,44,0,0,0,0,0,9,0,0,0,12,10,34
0,17,0,0,44,0,2,10,2,2,2,0,0,9,0,0,0,0,9,0
0,5,0,58,0,0,0,57,0,0,0,0,0,0,0,0,0,0,9,0
0,0,0,58,44,0,0,0,0,0,0,0,0,1,0,0,0,0,16,0
33,0,0,58,0,0,0,0,0,0,0,0,0,1,0,0,0,0,17,0
0,0,0,0,0,0,0,0,0,0,0,0,0,2,0,0,0,0,5,0
0,9,0,0,0,0,0,0,0,0,0,59,55,37,0,0,0,0,9,0
0,5,9,9,0,0,9,8,8,8,9,5,17,5,5,16,16,17,17,0
0,0,34,34,0,0,0,0,0,0,0,0,0,0,0,0,0,0,0,0
endlayer

layer
0,0,0,0,0,0,0,0,0,0,0,0,12,0,0,0,0,0,0,0
0,9,23,0,0,0,0,0,0,0,0,16,5,5,5,17,5,10,10,0
0,9,28,0,0,0,0,0,0,0,0,0,0,9,0,0,0,0,9,0
0,9,0,0,0,0,0,0,0,0,0,0,0,10,0,0,0,0,0,0
0,9,0,0,0,0,0,0,0,0,0,60,0,9,0,0,0,0,12,0
0,17,0,0,0,0,0,0,0,0,0,0,0,10,0,0,0,12,8,34
0,17,0,0,0,0,0,0,0,0,0,0,0,10,0,0,0,0,10,34
0,16,0,0,0,0,44,10,10,2,2,0,0,9,0,0,0,0,9,0
0,16,0,0,0,0,0,0,0,0,0,0,0,0,0,0,0,0,54,0
0,0,0,0,0,0,0,0,0,0,0,0,0,0,0,0,0,0,54,0
38,0,0,0,0,0,0,0,0,0,0,0,0,0,0,0,0,0,9,0
0,9,0,0,0,0,0,0,0,0,0,0,0,0,0,0,0,0,5,0
0,5,0,0,0,0,0,0,0,0,0,0,0,2,0,0,0,0,9,0
0,9,9,9,0,10,9,9,8,10,9,17,17,5,8,5,8,17,17,0
0,0,0,34,0,0,0,0,0,0,0,0,0,0,0,0,0,0,0,0
endlayer

layer
0,0,0,0,0,0,0,0,0,0,0,0,12,34,34,0,0,0,0,0
0,1,0,0,0,0,0,0,0,0,10,10,17,5,10,10,10,10,10,0
0,9,0,0,0,0,0,0,0,0,37,37,37,54,0,0,9,9,9,0
0,9,0,0,0,0,0,0,0,2,2,37,54,54,0,0,10,9,0,0
0,9,0,0,0,0,0,0,0,0,2,2,37,54,0,0,10,9,0,0
0,9,0,0,0,0,0,0,0,2,2,2,2,10,0,0,10,10,9,0
0,5,0,0,0,0,0,0,0,2,37,37,37,10,0,0,10,10,10,34
0,10,0,0,0,0,0,10,10,2,54,54,37,10,0,0,10,10,10,0
0,10,0,0,0,2,2,2,2,2,2,2,8,10,10,10,10,37,10,0
0,10,0,0,0,2,2,2,2,2,2,2,8,0,8,2,37,37,10,0
0,10,0,0,0,0,0,2,10,10,10,10,2,0,37,37,37,37,17,0
0,5,0,0,0,0,2,2,10,10,10,10,2,2,37,37,37,37,9,0
0,5,0,0,2,2,2,2,10,10,10,2,2,2,2,37,37,37,9,0
0,9,8,9,10,10,10,9,9,16,17,16,5,8,8,8,8,16,5,0
0,0,12,0,0,0,0,0,0,0,0,0,0,0,0,0,0,0,0,0
endlayer

layer
0,0,0,0,0,0,0,0,0,0,0,0,12,34,0,0,0,0,0,0
0,31,0,0,0,0,0,0,0,0,10,10,54,54,54,10,10,10,10,0
0,1,0,0,0,0,0,0,0,0,2,1,1,1,0,0,28,28,10,0
0,10,0,0,0,0,0,0,0,1,1,1,1,1,12,12,28,28,10,0
0,10,0,0,0,0,0,0,0,0,1,1,1,1,12,12,28,24,0,0
0,10,0,0,0,0,0,0,0,1,1,1,1,1,12,12,28,1,12,0
0,10,0,0,0,0,0,0,0,1,1,1,1,1,0,0,1,29,54,12
0,10,0,0,0,0,0,1,1,1,1,1,1,1,0,0,52,1,10,34
0,10,0,0,0,1,1,1,1,1,4,1,1,1,2,1,2,1,10,0
0,10,0,0,0,1,1,1,1,1,1,1,1,0,1,1,1,2,10,0
0,10,0,0,0,0,0,1,1,1,1,1,1,0,1,1,2,1,10,0
0,10,0,0,0,0,1,1,1,1,1,1,1,1,2,1,1,1,10,0
0,10,0,0,1,1,1,1,1,1,1,1,1,1,1,1,1,1,10,0
0,10,8,8,54,10,10,10,10,10,2,2,2,2,8,8,10,10,10,0
0,0,0,12,0,0,0,0,0,0,0,0,0,0,0,0,0,0,0,0
endlayer

layer
0,0,0,0,0,0,0,0,0,0,0,0,0,12,0,0,0,0,0,0
0,38,0,0,0,0,0,0,0,0,10,10,10,54,54,10,10,10,10,0
0,11,0,0,0,0,0,0,0,0,0,11,0,12,0,0,0,28,10,0
0,1,0,0,0,0,0,0,0,11,11,0,11,12,12,0,0,0,10,0
0,10,0,0,0,0,0,0,0,0,33,11,33,0,12,12,27,0,0,0
0,10,0,0,0,0,0,0,0,11,61,33,11,0,0,12,34,12,12,0
0,10,0,0,0,0,0,0,0,31,62,62,31,0,0,0,34,0,54,12
0,54,0,0,0,0,0,11,11,11,11,63,11,33,0,0,0,31,54,12
0,54,0,0,0,0,31,33,11,11,64,63,31,11,27,27,2,0,54,0
0,10,0,0,0,31,11,11,11,11,65,61,31,0,0,31,0,0,54,0
0,10,0,0,0,0,0,33,11,65,33,11,27,0,0,23,0,0,0,0
0,10,0,0,0,0,0,33,33,11,11,33,33,33,2,33,31,11,0,0
0,10,0,0,0,31,12,11,11,62,62,0,0,0,0,0,0,11,10,0
0,10,9,54,54,54,54,2,2,10,0,2,0,9,9,2,10,10,10,0
0,0,0,0,12,0,0,0,0,0,0,0,0,0,0,0,0,0,0,0
endlayer

layer
0,0,0,0,0,0,0,0,0,0,0,0,0,34,34,0,0,0,0,0
0,0,0,0,0,0,0,0,0,0,0,0,10,34,10,0,0,0,10,0
0,0,0,0,0,0,0,0,0,0,0,0,0,12,0,0,0,0,10,0
0,11,0,0,0,0,0,0,0,0,0,0,0,12,0,0,0,0,10,0
0,10,0,0,0,0,0,0,0,0,38,0,38,12,12,12,0,0,10,0
0,10,0,0,0,0,0,0,0,0,0,38,0,0,0,0,34,12,0,0
0,54,0,0,0,0,0,0,0,38,0,0,38,0,0,0,34,0,12,0
0,10,0,0,0,0,0,0,0,0,0,0,0,38,0,0,0,38,0,0
0,10,0,0,0,0,38,38,0,0,64,0,38,0,0,0,0,0,54,0
0,10,0,0,0,38,0,0,0,0,0,0,38,0,0,38,0,0,0,0
0,10,0,0,0,0,0,38,0,0,38,0,0,0,0,0,0,0,0,0
0,10,0,0,0,0,0,38,38,0,0,38,38,38,0,38,38,0,0,0
0,10,0,0,0,38,12,0,0,0,0,0,0,0,0,0,0,0,0,0
0,10,9,54,54,54,10,10,10,10,0,0,0,0,0,0,0,0,0,0
0,0,0,0,0,12,0,0,0,0,0,0,0,0,0,0,0,0,0,0
endlayer

layer
0,0,0,0,0,0,0,0,0,0,0,0,0,0,0,0,0,0,0,0
0,0,0,0,0,0,0,0,0,0,0,0,0,0,0,0,0,0,0,0
0,0,0,0,0,0,0,0,0,0,0,0,0,0,0,0,0,0,0,0
0,0,0,0,0,0,0,0,0,0,0,0,0,12,0,0,0,0,0,0
0,0,0,0,0,0,0,0,0,0,0,0,0,0,0,0,0,0,0,0
0,0,0,0,0,0,0,0,0,0,0,0,0,0,0,0,0,0,0,0
0,10,0,0,0,0,0,0,0,66,66,66,0,0,0,0,0,0,0,0
0,0,0,0,0,0,0,0,66,66,66,66,66,0,0,0,0,0,0,0
0,10,0,0,0,0,0,0,66,66,64,66,66,0,0,0,0,0,0,0
0,10,0,0,0,0,0,0,66,66,66,66,66,0,0,0,0,0,0,0
0,10,0,0,0,0,0,0,66,66,66,66,66,0,0,0,0,0,0,0
0,10,0,0,0,0,0,0,0,0,0,0,0,0,0,0,0,0,0,0
0,9,0,0,0,0,0,0,0,0,0,0,0,0,0,0,0,0,0,0
0,9,9,9,0,12,12,0,0,0,0,0,0,0,0,0,0,0,0,0
0,0,0,0,0,12,0,0,0,0,0,0,0,0,0,0,0,0,0,0
endlayer

layer
0,0,0,0,0,0,0,0,0,0,0,0,0,0,0,0,0,0,0,0
0,0,0,0,0,0,0,0,0,0,0,0,0,0,0,0,0,0,0,0
0,0,0,0,0,0,0,0,0,0,0,0,0,0,0,0,0,0,0,0
0,0,0,0,0,0,0,0,0,0,0,0,0,0,0,0,0,0,0,0
0,0,0,0,0,0,0,0,0,0,0,0,0,0,0,0,0,0,0,0
0,0,0,0,0,0,0,0,0,0,0,0,0,0,0,0,0,0,0,0
0,0,0,0,0,0,0,0,0,66,66,66,66,0,0,0,0,0,0,0
0,0,0,0,0,0,0,0,66,66,66,66,66,0,0,0,0,0,0,0
0,0,0,0,0,0,0,0,66,66,64,66,66,0,0,0,0,0,0,0
0,0,0,0,0,0,0,0,66,66,66,66,66,0,0,0,0,0,0,0
0,0,0,0,0,0,0,0,0,66,66,66,0,0,0,0,0,0,0,0
0,0,0,0,0,0,0,0,0,0,0,0,0,0,0,0,0,0,0,0
0,0,0,0,0,0,0,0,0,0,0,0,0,0,0,0,0,0,0,0
0,0,0,0,0,0,0,0,0,0,0,0,0,0,0,0,0,0,0,0
0,0,0,0,0,0,0,0,0,0,0,0,0,0,0,0,0,0,0,0
endlayer

layer
0,0,0,0,0,0,0,0,0,0,0,0,0,0,0,0,0,0,0,0
0,0,0,0,0,0,0,0,0,0,0,0,0,0,0,0,0,0,0,0
0,0,0,0,0,0,0,0,0,0,0,0,0,0,0,0,0,0,0,0
0,0,0,0,0,0,0,0,0,0,0,0,0,0,0,0,0,0,0,0
0,0,0,0,0,0,0,0,0,0,0,0,0,0,0,0,0,0,0,0
0,0,0,0,0,0,0,0,0,0,0,0,0,0,0,0,0,0,0,0
0,0,0,0,0,0,0,0,0,0,0,0,0,0,0,0,0,0,0,0
0,0,0,0,0,0,0,0,0,0,66,66,0,0,0,0,0,0,0,0
0,0,0,0,0,0,0,0,0,66,64,66,0,0,0,0,0,0,0,0
0,0,0,0,0,0,0,0,0,0,66,66,0,0,0,0,0,0,0,0
0,0,0,0,0,0,0,0,0,0,0,0,0,0,0,0,0,0,0,0
0,0,0,0,0,0,0,0,0,0,0,0,0,0,0,0,0,0,0,0
0,0,0,0,0,0,0,0,0,0,0,0,0,0,0,0,0,0,0,0
0,0,0,0,0,0,0,0,0,0,0,0,0,0,0,0,0,0,0,0
0,0,0,0,0,0,0,0,0,0,0,0,0,0,0,0,0,0,0,0
endlayer

layer
0,0,0,0,0,0,0,0,0,0,0,0,0,0,0,0,0,0,0,0
0,0,0,0,0,0,0,0,0,0,0,0,0,0,0,0,0,0,0,0
0,0,0,0,0,0,0,0,0,0,0,0,0,0,0,0,0,0,0,0
0,0,0,0,0,0,0,0,0,0,0,0,0,0,0,0,0,0,0,0
0,0,0,0,0,0,0,0,0,0,0,0,0,0,0,0,0,0,0,0
0,0,0,0,0,0,0,0,0,0,0,0,0,0,0,0,0,0,0,0
0,0,0,0,0,0,0,0,0,0,0,0,0,0,0,0,0,0,0,0
0,0,0,0,0,0,0,0,0,0,66,0,0,0,0,0,0,0,0,0
0,0,0,0,0,0,0,0,0,66,66,66,0,0,0,0,0,0,0,0
0,0,0,0,0,0,0,0,0,0,66,0,0,0,0,0,0,0,0,0
0,0,0,0,0,0,0,0,0,0,0,0,0,0,0,0,0,0,0,0
0,0,0,0,0,0,0,0,0,0,0,0,0,0,0,0,0,0,0,0
0,0,0,0,0,0,0,0,0,0,0,0,0,0,0,0,0,0,0,0
0,0,0,0,0,0,0,0,0,0,0,0,0,0,0,0,0,0,0,0
0,0,0,0,0,0,0,0,0,0,0,0,0,0,0,0,0,0,0,0
endlayer

