
# Created by Ruins mod version 17.2 Ingame Parser
# authoring Player: Shage_Jack

# TEMPLATE PARAMETER SETTINGS:
#
# criterion expression specifying mod ids required to load template
# may include plus (AND), minus (AND NOT), comma (OR), and parentheses
# all required mods listed must be present; no prohibited mods can be
requiredMods=
#
# likelihood this template will be chosen relative to all others
# e.g., a weight=6 template is chosen 3X as often as one with weight=2
weight=1
#
# list of dimensions in which this template may spawn, even if generic
# one or more dimension names, separated by commas (blank = all)
dimensionsToSpawnIn=
#
# list of other biomes in which this template may spawn
# biome corresponding to directory is always assumed, listed or not
# generic templates should leave this list empty
biomesToSpawnIn=
#
# criterion expression specifying types of biome where template spawns
# this is in addition to those explicitly listed as biomesToSpawnIn
# generic templates should leave this list empty
biomeTypesToSpawnIn=
#
# list of biomes in which this template may not spawn
# takes precedence over biomeTypesToSpawnIn, but NOT biomesToSpawnIn
# should be empty if biomeTypesToSpawnIn is empty
biomesToNotSpawnIn=
#
# depth template is pushed down into the surface when built
# offset is min/max range of random additional bury depth
embed_into_distance=0
random_height_offset=0,0
#
# whitelist/blacklist of block types on which template may be built
# specify one, not both; leave the other empty (both empty = allow all)
acceptable_target_blocks=
unacceptable_target_blocks=flowing_water,water,flowing_lava,lava
#
# size of template (#layers, #rows per layer, #blocks per row)
dimensions=28,38,36
#
# max number of missing blocks allowed in surface beneath template
allowable_overhang=0
#
# depth/height limit affected by terrain leveling
# also maximum bumpiness tolerated in surface beneath template
max_leveling=2
#
# padding applied to all sides of template horizontal footprint
# expands area affected by terrain leveling (-1 = no leveling)
leveling_buffer=0
#
# do not rotate template randomly when built (1 = no rotation)
preventRotation=1
#
# treat water/lava blocks as air and protect them from rule0 (1 = yes)
preserve_water=0
preserve_lava=0
#
# minimum distance this template must have from instances of itself
uniqueMinDistance=0
#
# min/max distances this template can be from world spawn (0 = no limit)
# only applies to overworld--i.e., dimension 0
spawnMinDistance=0
spawnMaxDistance=0
#
# other template built nearby whenever this one is
# syntax: <name>;<relativeX>;<maxYdifference>;<relativeZ>[;<chance>]
# may be used more than once to specify multiple neighbors
adjoining_template=

rule1=0,100,minecraft:grass-0
rule2=0,100,soviet:light_bricks2-0
rule3=0,100,soviet:light_bricks2_crack-0
rule4=0,100,soviet:blue_tilled_block-0
rule5=0,100,minecraft:dirt-0
rule6=0,100,gregtech:meta_block_compressed_6-14
rule7=0,100,primal:cinis_block-0
rule8=0,100,soviet:beton_with_ralling-6
rule9=0,100,primal:ore_bog_iron-2
rule10=0,100,soviet:blue_tilled_block-3
rule11=0,100,soviet:road_asphalt-1
rule12=0,100,minecraft:double_plant-3
rule13=0,100,minecraft:tallgrass-1
rule14=0,100,minecraft:leaves-4
rule15=0,100,minecraft:red_flower-0
rule16=0,100,minecraft:leaves-12
rule17=0,100,minecraft:double_plant-2
rule18=0,100,minecraft:dirt-1
rule19=0,100,soviet:rubbish-2
rule20=0,60,minecraft:web-0
rule21=0,100,ChestGenHook:chests/simple_dungeon:5-5
rule22=0,60,quark:monster_box-0
rule23=0,100,ChestGenHook:chests/apartmentbuilding1:5-4
rule24=0,100,bibliocraft:bookcase-0
rule25=0,100,immcraft:bookshelf-3
rule26=0,100,soviet:rubbish-3
rule27=0,100,soviet:rubbish-1
rule28=0,100,immcraft:bookshelf-0
rule29=0,100,immcraft:bookshelf-1
rule30=0,60,MobSpawner:cave_spider
rule31=0,100,chisel:cobblestone-7
rule32=0,100,chisel:bookshelf_darkoak-4
rule33=0,100,ChestGenHook:chests/simple_dungeon:5-2
rule34=0,100,soviet:rubbish-0
rule35=0,100,minecraft:yellow_flower-0
rule36=0,100,soviet:beton_with_ralling-3
rule37=0,100,minecraft:red_flower-8
rule38=0,100,soviet:beton_with_ralling-1
rule39=0,100,minecraft:red_flower-3
rule40=0,100,soviet:street_fence-0
rule41=0,100,soviet:street_light_down_2-0
rule42=0,100,minecraft:double_plant-10
rule43=0,100,soviet:beton_with_ralling-2
rule44=0,100,soviet:street_light_middle-0
rule45=0,100,soviet:street_light_top_2-0
rule46=0,100,biomesoplenty:hive-0
rule47=0,100,biomesoplenty:hive-3
rule48=0,100,biomesoplenty:hive-2

layer
1,1,1,1,1,1,1,1,1,1,1,1,1,1,1,1,1,1,1,1,1,1,1,1,1,1,1,1,1,1,1,1,1,1,1,1
1,1,1,1,1,1,1,1,1,1,1,1,1,1,1,1,1,1,1,1,1,1,1,1,1,1,1,1,1,1,1,1,1,1,1,1
1,1,1,3,3,2,3,2,2,2,3,1,1,2,2,2,2,2,2,2,3,2,2,3,3,3,3,3,2,3,3,2,2,2,1,1
1,1,1,2,4,4,4,4,4,4,4,1,1,1,4,4,4,4,4,4,4,4,4,4,4,4,4,4,4,4,4,4,4,2,1,1
1,1,1,2,4,4,4,4,4,4,4,4,1,1,1,4,4,4,4,4,4,4,4,4,4,4,4,4,4,4,4,4,4,2,1,1
1,1,1,3,4,4,4,4,4,4,4,4,4,1,1,5,1,4,4,4,4,4,4,4,4,4,4,4,4,4,4,4,4,2,1,1
1,1,1,2,4,4,4,4,4,4,4,4,4,4,4,1,1,4,4,4,4,4,4,4,4,4,4,4,4,4,4,4,4,3,1,1
1,1,1,2,4,4,4,4,4,4,4,4,4,4,4,4,4,4,4,4,4,4,4,4,4,4,4,4,4,4,4,4,4,2,1,1
1,1,1,2,4,4,4,4,4,4,4,4,4,4,4,4,4,4,4,4,4,4,4,4,4,4,4,4,4,4,4,4,4,2,1,1
1,1,1,2,4,4,4,4,4,4,4,4,4,4,4,4,4,4,4,4,4,4,4,4,4,4,4,4,4,4,4,4,4,2,1,1
1,1,1,2,4,4,4,4,4,4,4,4,4,4,4,4,4,4,4,4,4,4,4,4,4,4,4,4,4,4,4,4,4,2,1,1
1,1,1,2,4,4,4,4,4,4,4,4,4,4,4,4,4,4,4,4,4,4,4,4,4,4,4,4,4,4,4,4,4,2,1,1
1,1,1,3,4,4,4,4,4,4,4,4,4,4,4,4,4,4,4,4,4,4,4,4,4,4,4,4,4,4,4,4,4,3,1,1
1,1,1,3,4,4,4,4,4,4,4,4,4,4,4,4,4,6,6,4,4,4,4,4,4,4,4,4,4,4,4,4,4,2,1,1
1,1,1,2,4,4,4,4,4,4,4,4,4,4,4,4,6,6,7,6,4,4,4,4,4,4,4,4,4,4,4,4,4,3,1,1
1,1,1,3,4,4,4,4,4,4,4,4,4,4,4,6,6,7,7,7,6,4,4,4,4,4,4,4,4,4,4,4,4,3,1,1
1,1,1,3,4,4,4,4,4,4,4,4,4,4,6,7,7,7,7,6,4,4,4,4,4,4,4,4,4,4,4,4,4,3,1,1
1,1,1,3,4,4,4,4,4,4,4,4,4,4,6,7,7,9,7,7,6,6,8,4,4,4,4,4,4,4,4,4,4,3,1,1
1,1,1,2,4,4,4,4,4,4,4,4,4,4,6,7,9,7,7,7,6,6,8,4,4,4,4,4,4,4,4,4,4,2,1,1
1,1,1,3,4,4,4,4,4,4,4,4,4,4,4,6,7,7,7,7,6,6,4,4,4,4,4,4,4,4,4,4,4,3,1,1
1,1,1,2,4,4,4,4,4,4,4,4,4,4,4,4,6,7,6,6,6,8,4,4,4,4,4,4,4,4,4,4,4,2,1,1
1,1,1,1,2,4,4,4,4,4,4,4,4,4,4,4,6,6,4,4,4,4,4,4,4,4,4,4,4,4,4,4,2,1,1,1
1,1,1,1,3,4,4,4,4,4,4,4,4,4,4,4,4,4,4,4,4,4,4,4,4,4,4,4,4,4,4,4,3,1,1,1
1,1,1,1,3,4,4,4,4,4,4,4,4,4,4,4,4,4,4,4,4,4,4,4,4,4,4,4,4,4,4,4,3,1,1,1
1,1,1,1,1,2,4,4,4,4,4,4,4,4,4,4,4,4,4,4,4,4,4,4,4,4,4,4,4,4,4,3,1,1,1,1
1,1,1,1,1,3,4,4,4,4,4,4,4,4,4,4,4,4,4,4,4,4,4,4,4,4,4,4,4,4,4,2,1,1,1,1
1,1,1,1,1,1,2,4,4,4,4,4,4,4,4,4,4,4,4,4,4,4,4,4,4,4,4,4,4,4,3,1,1,1,1,1
1,1,1,1,1,1,1,3,4,4,4,4,4,4,4,4,4,4,4,4,4,4,4,4,4,4,4,4,4,2,1,1,1,1,1,1
1,1,1,1,1,1,1,1,2,4,4,4,4,4,4,4,4,4,4,4,4,4,4,4,4,4,4,4,2,1,1,1,1,1,1,1
1,1,1,1,1,1,1,1,1,2,4,4,4,4,4,4,4,4,4,4,4,4,4,4,4,4,4,2,1,1,1,1,1,1,1,1
1,1,1,1,1,1,1,1,1,1,2,2,4,4,4,4,4,4,4,4,4,4,4,4,4,3,2,1,1,1,1,1,1,1,1,1
1,1,1,1,1,1,1,1,1,1,1,1,2,2,2,4,4,4,4,4,4,4,3,2,2,1,1,1,1,1,1,1,1,1,1,1
1,1,1,1,1,1,1,1,1,1,1,1,1,1,1,2,3,10,10,10,3,2,1,1,1,1,1,1,1,1,1,1,1,1,1,1
1,1,1,1,1,1,1,1,1,1,1,1,1,1,1,1,1,11,11,11,1,1,1,1,1,1,1,1,1,1,1,1,1,1,1,1
1,1,1,1,1,1,1,1,1,1,1,1,1,1,1,1,1,11,11,11,1,1,1,1,1,1,1,1,1,1,1,1,1,1,1,1
1,1,1,1,1,1,1,1,1,1,1,1,1,1,1,1,1,11,11,11,1,1,1,1,1,1,1,1,1,1,1,1,1,1,1,1
1,1,1,1,1,1,1,1,1,1,1,1,1,1,1,1,1,11,11,11,1,1,1,1,1,1,1,1,1,1,1,1,1,1,1,1
1,1,1,1,1,1,1,1,1,1,1,1,1,1,1,1,1,11,11,11,1,1,1,1,1,1,1,1,1,1,1,1,1,1,1,1
endlayer

layer
13,13,13,13,12,13,12,13,13,13,13,14,14,12,0,14,0,14,0,15,12,13,12,0,13,0,14,14,13,14,12,14,14,13,12,0
0,17,14,13,14,14,14,13,13,14,14,16,14,14,14,14,13,14,13,14,13,0,13,14,13,14,14,14,13,14,13,14,14,16,14,16
0,13,14,2,3,3,3,2,2,3,3,14,14,3,2,2,3,2,3,3,3,2,3,3,3,3,3,3,3,3,3,3,2,3,13,0
13,13,0,3,14,22,21,14,14,14,14,14,14,0,0,0,0,20,0,0,0,0,20,19,0,1,18,18,18,18,18,18,18,3,14,0
13,13,14,3,14,24,24,24,16,16,20,0,14,14,0,20,0,0,0,20,20,0,0,0,0,1,1,1,18,18,22,23,18,3,14,14
13,13,13,3,22,24,24,24,19,16,0,0,14,14,14,22,0,0,20,19,0,0,19,0,0,0,0,1,1,25,25,25,18,2,14,0
0,12,14,3,27,14,14,27,0,0,0,0,19,20,14,14,20,20,0,26,20,20,0,0,0,26,22,16,1,1,18,18,18,3,14,0
0,0,14,3,24,0,0,24,24,0,19,29,28,0,14,14,14,14,0,0,0,0,0,0,0,0,16,16,16,1,1,18,18,3,14,14
0,0,14,2,24,27,0,24,24,0,26,29,28,0,0,0,14,14,14,30,0,0,0,14,14,14,16,20,16,14,18,18,18,3,13,13
0,14,14,3,24,0,0,24,24,26,0,29,30,0,0,0,0,14,14,14,14,14,14,0,0,0,0,0,0,0,14,3,3,3,14,0
12,0,14,2,24,0,0,24,24,0,0,0,0,27,0,0,0,0,26,14,14,0,0,8,0,0,0,0,0,30,0,14,0,3,14,0
0,0,0,2,0,0,27,20,0,0,20,0,20,0,0,0,26,0,0,30,0,19,0,31,31,20,0,0,0,0,0,14,20,2,14,14
0,0,14,3,28,27,0,0,0,22,0,20,0,0,0,26,0,6,6,8,26,0,26,0,0,31,20,20,0,20,0,14,20,3,14,12
0,0,0,3,28,0,20,32,32,32,32,0,0,26,0,8,6,0,0,6,8,0,26,0,0,31,31,0,0,0,27,0,0,2,14,14
0,0,14,2,28,20,20,0,8,8,0,0,26,0,8,6,33,0,0,6,6,31,0,0,0,31,20,26,0,0,0,0,0,3,0,12
0,0,0,3,24,0,27,0,0,27,8,20,0,8,6,6,26,0,26,0,6,8,31,31,8,20,0,0,24,27,34,0,20,3,16,14
0,0,0,2,24,0,0,8,8,0,0,0,0,6,26,0,0,0,0,0,6,8,20,22,0,20,0,20,24,30,0,0,0,2,13,13
12,14,14,2,24,0,34,34,8,0,26,0,8,6,0,0,0,0,0,26,0,6,0,0,0,20,0,19,24,0,0,0,0,2,14,12
0,0,13,3,24,20,0,8,8,20,0,0,20,6,26,20,0,22,0,0,0,6,20,20,19,0,0,0,24,27,0,20,29,2,14,12
13,13,0,2,0,20,0,20,19,0,26,0,19,0,6,0,0,20,26,0,6,6,0,0,0,0,0,0,24,0,20,20,32,3,14,14
12,13,14,2,0,20,0,0,20,0,30,0,20,19,8,6,0,0,0,6,6,0,0,0,0,0,0,26,0,19,0,22,32,2,14,12
13,13,13,14,2,28,0,0,26,0,0,26,20,8,31,6,6,6,6,8,0,0,0,26,0,20,0,0,0,0,0,29,3,14,35,13
0,0,0,14,3,28,22,0,0,0,20,0,8,31,31,8,31,8,8,27,0,26,20,0,8,0,0,26,8,0,0,29,2,0,0,13
0,12,13,14,3,28,0,0,20,0,20,36,31,31,31,31,31,20,0,0,0,0,26,8,0,31,31,0,0,0,20,29,2,14,0,12
13,13,13,13,14,2,28,20,0,30,20,36,31,31,31,31,31,8,27,0,26,0,0,31,31,31,31,26,0,0,0,3,14,14,37,12
13,13,13,0,14,3,28,20,27,20,0,0,38,38,38,38,38,27,20,0,0,20,0,31,31,31,30,8,0,0,0,3,14,0,0,12
13,15,0,13,14,14,3,20,0,20,0,0,0,0,20,0,20,0,8,8,20,20,24,31,31,22,26,0,0,20,3,14,0,0,0,13
13,0,35,35,0,0,0,2,34,0,0,0,34,8,27,8,0,20,0,0,0,0,24,38,38,0,8,0,20,2,14,14,13,0,0,12
13,13,13,17,13,0,0,0,3,0,0,0,0,20,0,0,0,27,0,8,0,8,24,0,34,20,0,0,2,14,14,13,13,0,13,0
15,13,13,13,13,0,39,14,14,3,0,0,0,0,0,0,0,0,0,0,20,0,0,0,0,20,20,2,16,14,0,13,13,13,13,12
13,13,13,13,13,13,13,0,14,14,3,3,0,0,0,0,0,0,0,20,0,34,0,0,0,2,3,14,14,0,0,39,13,13,13,0
0,13,17,39,13,13,0,0,0,12,14,14,2,3,3,22,2,0,40,40,3,22,3,2,3,14,14,0,13,13,13,13,0,13,13,12
0,13,17,13,17,13,13,13,12,0,0,13,14,14,0,3,2,0,40,40,3,3,14,16,0,16,0,13,13,35,13,17,13,12,13,0
0,13,0,0,13,17,13,0,13,0,0,14,14,14,13,14,12,0,0,0,0,14,14,14,13,13,17,13,12,13,13,0,13,13,13,13
0,12,0,35,0,13,13,17,13,13,13,0,12,13,13,13,0,0,0,0,0,13,13,13,13,13,13,12,13,13,0,35,13,13,13,13
0,12,0,13,13,13,39,13,13,13,13,13,12,12,37,13,0,0,0,0,0,17,13,13,13,12,13,15,13,13,13,13,15,13,13,0
0,0,0,12,13,0,15,12,15,17,17,13,13,13,0,13,41,0,0,0,13,13,13,13,17,17,0,13,0,0,0,0,17,13,13,0
0,0,0,0,0,0,13,15,13,13,15,0,0,0,13,12,12,0,0,0,0,12,13,13,17,0,15,0,13,0,0,0,0,0,13,0
endlayer

layer
0,0,0,14,42,0,42,0,14,0,0,0,0,42,0,0,14,0,14,0,42,0,42,16,0,14,14,0,14,0,42,0,0,0,42,0
0,42,0,14,0,14,14,14,14,14,14,16,14,0,14,0,0,14,0,14,14,14,14,14,14,0,0,0,14,0,14,14,14,14,0,0
0,0,14,2,2,2,2,2,2,3,3,0,14,2,3,2,3,2,3,2,3,2,3,2,2,3,2,3,3,2,2,2,3,3,16,0
0,14,14,3,14,14,14,14,0,14,20,14,14,0,0,0,0,0,0,0,0,0,0,0,0,20,0,18,18,18,18,18,18,3,0,0
0,0,14,2,14,24,24,24,16,16,0,20,0,20,0,0,0,0,0,0,20,20,0,0,0,0,0,0,1,18,18,18,18,2,14,0
0,0,0,2,14,24,24,24,20,0,0,0,0,14,20,20,0,0,0,20,0,0,0,0,0,0,0,0,0,14,25,25,18,3,0,0
0,42,14,2,0,16,0,0,0,0,0,0,20,0,0,0,0,0,20,0,0,0,0,20,20,20,0,0,20,14,18,18,18,3,0,0
0,0,14,3,24,0,0,24,24,20,0,0,0,0,0,20,14,0,20,0,0,0,0,0,0,0,16,0,16,14,14,3,3,14,14,0
0,0,0,2,24,20,0,24,24,0,0,0,20,0,0,0,14,0,14,0,0,0,0,0,14,0,0,0,0,14,3,3,3,14,16,0
0,0,0,2,24,0,0,24,24,20,0,0,0,0,0,20,0,0,14,14,0,14,14,0,0,0,0,0,0,0,0,14,14,14,16,0
42,0,14,2,24,0,0,0,0,0,0,20,0,0,0,0,20,20,0,0,0,0,0,0,0,0,0,20,0,0,20,0,0,3,16,0
0,0,14,3,0,0,0,20,20,20,0,0,0,0,0,43,0,0,0,0,20,0,43,43,0,0,0,0,0,0,0,20,20,3,0,0
0,0,14,2,28,0,0,0,0,0,0,0,0,0,36,31,31,31,0,20,0,36,31,31,31,0,0,0,0,0,0,0,0,3,0,42
0,0,14,2,28,20,0,32,20,32,32,0,20,20,31,31,31,31,0,0,0,36,31,31,31,0,0,20,20,0,20,0,0,2,14,0
0,0,0,2,0,20,20,0,0,0,20,0,20,0,31,31,31,0,20,0,0,0,31,31,31,8,0,0,20,0,0,0,0,2,0,42
0,0,0,2,24,0,20,20,0,20,0,0,0,0,38,38,38,0,20,20,26,0,0,0,20,0,0,0,0,0,0,0,20,2,0,0
0,14,14,3,24,0,0,0,0,0,0,20,0,20,20,0,20,20,0,0,0,0,0,0,20,0,0,0,0,0,20,0,0,3,16,14
42,0,0,2,24,0,20,0,0,20,0,20,0,0,0,0,0,0,0,0,0,0,0,0,0,0,0,0,0,0,0,0,0,3,14,42
0,0,0,3,0,0,20,0,0,0,20,0,0,0,0,0,20,0,0,20,0,20,0,0,0,0,20,0,0,0,0,20,0,2,14,42
0,0,0,2,0,0,0,0,0,0,0,0,20,0,0,20,20,0,0,0,20,0,0,0,0,0,0,0,0,0,0,0,32,2,0,0
42,0,14,2,0,0,0,0,20,0,0,0,0,0,0,26,20,0,20,0,20,0,20,0,0,0,20,0,20,26,0,0,32,2,0,42
0,0,0,0,2,28,0,0,0,0,0,0,0,0,0,0,0,0,0,0,0,0,20,0,0,20,0,0,0,0,0,29,3,14,0,0
0,0,0,16,3,28,20,0,0,20,0,0,0,0,0,20,0,0,20,0,0,0,20,0,0,20,0,0,0,20,0,29,2,14,0,0
0,42,0,16,3,28,20,0,20,20,0,0,8,0,0,0,0,0,20,0,0,20,0,0,0,0,0,0,0,0,0,29,2,14,0,42
0,0,0,0,14,3,28,0,0,0,0,0,8,8,8,8,8,0,0,0,0,0,20,20,8,0,20,0,20,0,0,2,0,0,0,42
0,0,0,0,0,2,28,0,0,0,0,0,20,0,0,0,0,0,0,0,0,0,0,8,8,0,0,0,0,0,20,2,14,16,0,42
0,0,0,0,0,0,3,0,0,0,20,0,0,0,0,0,0,0,0,0,0,0,24,8,8,0,0,0,0,0,3,14,14,16,0,0
0,0,0,0,0,0,14,2,0,20,0,20,0,0,20,0,0,0,0,0,0,0,24,0,0,0,0,20,0,3,14,14,0,0,0,42
0,0,0,42,0,0,0,0,2,0,0,0,0,0,0,0,0,0,0,0,20,20,24,0,0,0,0,20,3,14,0,0,0,0,0,0
0,0,0,0,0,0,0,14,0,2,0,0,0,0,0,20,0,0,0,0,20,0,0,0,20,0,20,2,16,14,0,0,0,0,0,42
0,0,0,0,0,0,0,0,14,14,2,3,0,0,0,20,0,0,0,0,20,0,0,20,0,3,3,0,16,0,0,0,0,0,0,0
0,0,42,0,0,0,0,0,0,42,14,0,3,2,3,0,2,0,0,0,3,0,2,2,3,14,14,0,0,0,0,0,0,0,0,42
0,0,42,0,42,0,0,0,42,0,0,0,14,14,14,3,3,0,0,0,2,3,14,0,16,0,0,0,0,0,0,42,0,42,0,0
0,0,0,0,0,42,0,0,0,0,0,0,0,0,0,14,42,0,0,0,14,14,0,0,0,0,42,0,42,0,0,0,0,0,0,0
0,42,0,0,0,0,0,42,0,0,0,0,42,0,0,14,0,0,0,0,0,0,0,0,0,0,0,42,0,0,0,0,0,0,0,0
0,42,0,0,0,0,0,0,0,0,0,0,42,42,0,0,0,0,0,0,0,42,0,0,0,42,0,0,0,0,0,0,0,0,0,0
0,0,0,42,0,0,0,42,0,42,42,0,0,0,0,0,44,0,0,0,0,0,0,0,42,42,0,0,0,0,0,0,42,0,0,0
0,0,0,0,0,0,0,0,0,0,0,0,0,0,0,42,42,0,0,0,0,42,0,0,42,0,0,0,0,0,0,0,0,0,0,0
endlayer

layer
0,0,0,0,0,0,0,0,0,0,0,0,0,0,0,0,0,0,0,0,0,0,0,0,14,14,14,0,0,0,0,0,0,0,0,0
0,0,0,14,14,0,0,14,0,14,0,0,0,14,14,14,14,0,0,0,14,14,0,14,0,14,14,0,0,14,14,0,16,14,0,0
0,0,14,2,2,3,2,3,3,2,2,0,14,3,3,2,3,3,3,2,2,2,3,2,3,2,2,2,2,3,3,2,2,3,14,0
0,0,0,3,14,14,14,14,0,0,20,0,0,0,20,0,20,0,0,0,0,0,0,0,0,20,0,0,0,0,0,18,0,3,0,0
0,0,0,3,0,24,24,24,16,0,0,0,0,0,0,0,0,0,0,0,0,0,0,0,0,0,0,0,20,0,14,14,18,3,14,0
0,14,14,3,0,24,24,24,0,0,0,20,20,0,0,0,0,20,0,0,20,0,0,0,0,0,0,0,20,0,14,14,1,2,14,0
0,0,0,2,0,20,0,0,0,20,0,0,0,0,0,0,20,0,0,0,0,0,0,0,0,20,20,20,20,0,14,3,3,3,14,0
0,0,0,3,24,0,0,24,24,20,0,0,0,20,0,0,0,0,0,0,0,0,20,0,0,0,0,0,0,0,0,14,14,14,0,0
0,0,0,3,24,0,20,24,24,0,0,0,0,0,0,20,0,0,0,0,0,20,0,0,0,0,0,0,0,14,14,14,14,14,14,0
0,0,14,2,24,0,0,24,24,0,0,20,0,0,0,0,0,0,0,0,20,0,0,0,0,0,20,20,0,0,0,20,14,0,0,0
0,0,0,2,0,0,0,0,0,20,0,20,0,0,0,0,20,0,0,0,0,0,0,20,20,0,0,0,0,0,0,0,0,3,16,0
0,0,0,2,0,0,0,0,0,0,0,0,0,0,0,20,0,20,0,20,0,0,0,0,20,20,0,0,0,0,0,20,0,2,0,0
0,0,14,3,0,0,20,20,20,0,0,20,0,0,0,8,0,27,0,20,0,0,8,0,20,0,20,0,0,0,0,0,0,3,0,0
0,0,0,3,0,20,0,0,20,32,32,20,0,0,27,0,27,0,0,0,0,0,0,0,0,0,0,0,0,0,0,20,0,3,0,0
0,0,14,2,20,0,20,0,0,0,0,0,0,0,0,20,27,20,0,0,0,0,20,0,0,0,0,0,0,20,0,0,0,2,0,0
0,0,14,2,0,20,0,20,0,0,0,20,0,0,0,0,0,0,0,0,0,20,20,0,0,0,0,20,0,20,0,0,0,2,0,0
0,0,0,2,24,0,0,0,0,0,0,20,0,0,0,0,0,0,0,20,0,0,0,0,0,20,0,20,0,0,0,0,0,2,0,0
0,0,14,2,24,0,0,0,0,0,20,0,0,20,0,0,0,20,0,0,0,0,0,0,0,0,0,0,0,0,0,20,0,2,0,0
0,0,14,3,0,0,0,0,20,0,0,0,0,0,0,0,0,0,0,0,0,0,0,0,0,0,0,0,20,0,0,0,0,3,0,0
0,0,14,3,20,0,20,0,0,0,0,0,20,20,0,20,20,20,0,0,0,0,20,0,0,0,0,0,20,0,0,0,0,2,14,0
0,0,14,2,0,0,20,0,0,0,0,0,0,0,20,0,0,0,20,0,20,0,0,0,20,0,0,0,0,0,20,0,32,3,14,0
0,0,0,0,3,20,0,0,0,0,0,0,0,0,0,0,0,0,0,0,0,0,0,0,0,20,0,0,20,0,0,29,2,14,0,0
0,0,0,16,2,0,0,0,0,20,0,0,0,0,0,0,20,20,0,0,0,20,0,0,0,0,0,0,0,0,0,29,2,0,0,0
0,0,0,0,2,0,0,0,0,0,0,0,0,0,0,0,0,0,20,0,0,0,20,0,0,20,0,0,0,0,0,0,3,0,0,0
0,0,0,0,0,3,0,0,0,20,0,0,0,0,0,0,0,0,0,0,0,0,0,0,20,0,0,0,0,20,0,3,0,0,0,0
0,0,0,0,14,3,0,20,0,0,0,0,0,0,0,0,0,0,0,0,0,0,20,0,0,0,20,20,0,0,0,3,14,16,0,0
0,0,0,0,0,0,3,0,0,0,20,20,0,0,0,0,0,20,0,20,0,0,0,20,20,20,0,0,20,0,2,0,0,0,0,0
0,0,0,0,0,0,14,2,0,0,0,0,20,0,0,0,20,0,20,0,0,0,0,0,0,0,0,0,0,3,14,0,0,0,0,0
0,0,0,0,0,0,0,14,2,20,0,0,0,0,20,0,20,0,0,0,0,20,0,0,0,20,0,0,3,0,0,0,0,0,0,0
0,0,0,0,0,0,0,14,14,3,0,0,0,20,0,0,0,0,20,0,0,0,0,0,0,0,0,3,0,0,0,0,0,0,0,0
0,0,0,0,0,0,0,0,0,14,3,2,0,0,0,0,0,0,20,0,20,20,20,0,0,2,3,14,0,0,0,0,0,0,0,0
0,0,0,0,0,0,0,0,0,0,14,14,3,2,2,0,3,0,0,0,3,0,3,2,3,0,0,0,0,0,0,0,0,0,0,0
0,0,0,0,0,0,0,0,0,0,0,0,14,0,14,2,2,0,0,0,3,2,14,14,14,0,0,0,0,0,0,0,0,0,0,0
0,0,0,0,0,0,0,0,0,0,0,0,0,0,0,14,0,0,0,0,14,0,14,0,0,0,0,0,0,0,0,0,0,0,0,0
0,0,0,0,0,0,0,0,0,0,0,0,0,0,0,14,0,0,0,0,14,0,0,0,0,0,0,0,0,0,0,0,0,0,0,0
0,0,0,0,0,0,0,0,0,0,0,0,0,0,0,0,0,0,0,0,0,0,0,0,0,0,0,0,0,0,0,0,0,0,0,0
0,0,0,0,0,0,0,0,0,0,0,0,0,0,0,0,44,0,0,0,0,0,0,0,0,0,0,0,0,0,0,0,0,0,0,0
0,0,0,0,0,0,0,0,0,0,0,0,0,0,0,0,0,0,0,0,0,0,0,0,0,0,0,0,0,0,0,0,0,0,0,0
endlayer

layer
0,0,0,0,0,0,0,0,0,0,0,0,0,0,0,0,0,0,0,0,0,0,0,0,0,0,0,0,0,0,0,0,0,0,0,0
0,0,0,16,14,0,0,0,0,0,0,0,0,14,0,0,0,0,0,0,0,0,0,0,0,0,0,0,14,0,14,0,0,0,0,0
0,0,16,3,3,2,3,2,2,3,2,3,3,3,3,2,2,3,3,2,2,3,3,2,3,2,2,2,3,3,3,2,2,3,0,0
0,0,0,2,14,14,20,0,0,0,0,0,0,0,20,0,20,0,0,20,20,0,0,0,0,20,0,0,0,0,20,20,0,3,14,0
0,0,0,3,0,0,0,0,0,0,0,20,0,0,0,0,20,0,0,0,20,0,0,0,0,0,0,20,0,0,20,0,0,3,14,0
0,0,0,3,0,0,20,0,0,20,0,20,0,0,0,0,20,0,0,0,0,20,20,0,0,0,0,20,0,20,20,20,20,3,0,0
0,0,0,3,20,0,20,0,0,0,0,0,20,20,20,0,20,0,0,0,0,0,0,0,0,0,0,20,0,0,0,14,16,14,0,0
0,0,0,3,0,0,20,0,0,0,0,0,0,0,0,0,20,0,0,0,0,0,0,0,0,20,20,0,0,0,0,16,16,0,0,0
0,0,0,3,0,20,0,20,0,0,0,0,0,0,20,0,0,0,0,0,0,20,0,20,0,0,0,20,0,0,0,14,16,16,0,0
0,0,0,3,0,0,0,0,0,0,20,0,0,20,0,20,0,20,0,20,0,0,20,0,0,0,0,0,0,0,0,0,16,0,0,0
0,0,0,2,0,0,0,0,0,0,0,0,0,0,20,0,0,0,0,0,0,0,0,0,20,0,0,0,20,0,0,0,0,3,0,0
0,0,0,2,0,0,0,0,0,0,20,0,0,0,20,0,0,20,0,0,0,0,0,0,0,20,0,0,20,0,20,0,0,2,0,0
0,0,0,2,0,20,0,0,0,0,0,0,0,0,20,20,0,0,0,0,0,0,20,0,0,0,0,0,20,0,0,0,0,3,0,0
0,0,0,3,0,20,0,0,0,20,0,20,20,0,0,0,0,0,0,0,0,0,0,0,20,0,0,0,0,0,0,20,0,3,0,0
0,0,0,3,0,0,0,20,0,0,0,0,0,0,0,0,0,0,0,0,0,20,0,0,0,0,0,20,0,0,0,20,0,3,0,0
0,0,0,3,20,20,0,20,0,0,0,0,0,0,0,0,20,0,0,0,0,20,0,20,0,0,0,0,20,0,0,0,0,2,0,0
0,0,0,2,0,0,20,20,20,0,0,0,0,0,0,0,0,20,0,0,0,0,0,0,20,0,0,20,0,0,0,0,0,2,0,0
0,0,0,2,0,0,20,0,0,0,20,20,20,20,0,0,0,0,0,0,0,0,0,0,20,0,0,0,0,0,0,0,0,3,0,0
0,0,14,2,0,20,0,0,0,20,0,20,0,0,20,0,20,0,0,0,0,0,0,0,0,20,20,0,0,20,0,0,0,3,0,0
0,0,0,3,0,20,0,0,0,0,0,20,0,0,0,0,0,0,0,0,0,20,0,0,20,0,0,0,0,0,0,0,0,2,0,0
0,0,0,3,0,0,20,0,0,0,20,0,0,0,20,0,0,0,0,0,0,0,0,0,0,0,20,0,0,0,0,0,0,2,0,0
0,0,0,0,3,20,0,0,0,0,0,0,0,0,0,20,0,0,0,0,0,0,20,0,0,0,20,0,0,0,0,0,3,0,0,0
0,0,0,14,3,0,0,0,0,0,0,0,0,0,0,0,0,0,0,0,0,0,0,0,0,0,0,0,20,20,0,0,2,0,0,0
0,0,0,0,2,0,20,0,0,0,0,0,0,0,0,0,0,0,0,0,0,20,0,0,20,0,0,0,0,0,0,0,2,0,0,0
0,0,0,0,0,2,20,0,20,0,20,0,0,0,20,0,20,0,0,0,20,0,0,0,0,0,0,20,0,20,0,3,0,0,0,0
0,0,0,0,14,2,0,0,20,0,0,0,0,0,0,0,0,0,20,0,0,20,0,0,0,20,0,20,0,0,0,3,14,14,0,0
0,0,0,0,0,14,3,0,0,0,0,20,20,0,0,0,0,0,0,0,0,0,20,0,20,0,0,0,0,0,2,0,0,0,0,0
0,0,0,0,0,0,14,2,0,20,0,0,0,0,0,0,20,0,20,0,0,20,0,0,20,0,0,0,0,3,0,0,0,0,0,0
0,0,0,0,0,0,0,16,3,0,0,0,0,0,0,0,20,0,0,0,0,0,0,0,0,0,20,0,3,0,0,0,0,0,0,0
0,0,0,0,0,0,0,0,0,3,20,20,0,20,0,0,0,0,0,0,0,0,0,0,0,0,0,2,0,0,0,0,0,0,0,0
0,0,0,0,0,0,0,0,0,0,3,3,0,0,0,0,0,0,0,20,0,20,0,20,0,2,3,0,0,0,0,0,0,0,0,0
0,0,0,0,0,0,0,0,0,0,0,0,3,3,2,0,3,3,2,3,3,0,2,2,2,0,0,0,0,0,0,0,0,0,0,0
0,0,0,0,0,0,0,0,0,0,0,0,0,0,0,3,2,3,2,2,3,2,14,14,0,0,0,0,0,0,0,0,0,0,0,0
0,0,0,0,0,0,0,0,0,0,0,0,0,0,0,14,14,14,0,0,0,14,0,0,0,0,0,0,0,0,0,0,0,0,0,0
0,0,0,0,0,0,0,0,0,0,0,0,0,0,0,0,14,0,0,0,14,0,0,0,0,0,0,0,0,0,0,0,0,0,0,0
0,0,0,0,0,0,0,0,0,0,0,0,0,0,0,0,0,0,0,0,0,0,0,0,0,0,0,0,0,0,0,0,0,0,0,0
0,0,0,0,0,0,0,0,0,0,0,0,0,0,0,0,44,0,0,0,0,0,0,0,0,0,0,0,0,0,0,0,0,0,0,0
0,0,0,0,0,0,0,0,0,0,0,0,0,0,0,0,0,0,0,0,0,0,0,0,0,0,0,0,0,0,0,0,0,0,0,0
endlayer

layer
0,0,0,0,0,0,0,0,0,0,0,0,0,0,0,0,0,0,0,0,0,0,0,0,0,0,0,0,0,0,0,0,0,0,0,0
0,0,0,16,14,0,0,0,0,0,0,0,0,0,0,0,0,0,0,0,0,0,0,0,0,0,0,0,0,0,0,0,0,0,0,0
0,0,0,2,2,3,2,3,3,3,3,2,3,2,3,3,3,2,3,3,3,3,2,3,2,2,3,3,3,2,3,2,2,3,0,0
0,0,14,2,0,14,0,0,0,0,0,0,0,0,0,0,0,0,0,0,20,0,20,0,0,0,0,20,0,0,0,0,0,2,16,0
0,0,0,2,0,14,0,0,20,0,0,20,20,0,0,20,0,0,20,0,20,0,0,20,0,0,0,20,0,0,0,20,0,2,0,0
0,0,0,2,0,0,0,0,0,0,0,0,20,0,0,0,20,0,0,0,0,20,0,0,0,0,0,0,0,20,0,0,0,3,16,0
0,0,0,3,0,20,0,0,20,0,0,0,0,0,20,20,0,0,20,0,20,0,0,0,0,0,0,0,0,0,20,0,0,0,0,0
0,0,0,3,0,0,0,0,20,20,0,20,20,0,0,0,20,0,0,0,20,0,0,0,0,20,20,20,0,20,0,20,16,0,0,0
0,0,0,2,0,0,0,0,0,0,0,0,0,20,0,20,0,0,0,0,0,0,0,0,20,20,0,0,20,0,20,0,0,0,0,0
0,0,0,2,0,0,0,20,0,0,0,0,0,0,0,0,20,20,0,0,0,0,0,0,0,0,0,0,0,0,0,0,16,0,0,0
0,0,0,3,0,20,0,0,0,0,0,20,0,0,0,0,0,0,0,0,20,20,0,0,0,0,0,0,20,20,0,0,20,3,0,0
0,0,0,2,0,0,0,0,0,20,0,0,20,0,0,20,0,0,20,0,0,20,0,0,0,0,0,0,0,0,0,0,0,3,0,0
0,0,0,2,0,0,0,0,20,20,0,0,0,20,0,20,0,0,0,0,0,0,0,0,0,20,0,20,0,0,0,0,0,3,0,0
0,0,0,2,20,0,20,0,0,0,0,0,20,20,0,0,20,0,0,0,0,0,0,0,0,20,0,0,0,0,0,0,0,2,0,0
0,0,0,2,0,0,0,0,20,0,0,0,0,0,0,0,0,0,0,0,0,0,0,0,20,0,0,0,20,0,0,0,0,2,0,0
0,0,0,2,0,0,0,0,20,0,0,0,0,0,0,20,0,0,0,0,0,0,0,0,0,0,0,0,0,0,0,0,20,2,0,0
0,0,0,3,0,0,0,0,0,0,0,20,0,0,0,0,0,0,0,20,0,0,0,0,20,0,0,0,0,0,0,0,0,2,0,0
0,0,0,3,20,0,0,20,0,0,0,0,0,0,0,0,0,20,0,0,20,0,0,20,20,0,0,0,0,0,0,0,0,3,0,0
0,0,0,2,20,0,0,0,0,0,0,20,0,0,0,20,20,20,0,0,0,0,0,0,0,0,20,0,0,20,0,0,0,3,0,0
0,0,14,2,0,0,0,20,20,20,0,0,0,20,20,0,0,0,0,20,0,20,0,0,0,0,0,0,0,0,20,0,0,3,0,0
0,0,0,2,0,0,0,20,0,20,0,0,0,0,0,0,0,0,0,0,0,0,0,20,0,20,0,0,0,0,20,20,0,2,0,0
0,0,0,0,3,0,0,0,0,0,0,20,20,20,0,20,20,0,0,0,0,20,0,20,0,0,0,0,0,20,0,0,2,0,0,0
0,0,0,0,2,0,0,0,20,0,0,0,0,0,0,20,20,0,0,0,0,0,0,20,20,0,20,0,0,20,0,0,2,0,0,0
0,0,0,0,3,0,0,0,0,0,0,0,0,0,20,0,0,0,0,0,0,0,0,0,0,0,0,0,0,0,0,0,2,0,0,0
0,0,0,0,0,3,20,0,20,0,20,0,0,0,0,0,0,20,0,0,0,0,0,0,0,0,0,20,0,0,0,2,14,0,0,0
0,0,0,0,0,3,20,0,0,0,0,0,0,0,0,0,0,0,0,0,0,0,0,0,0,0,20,20,0,0,0,2,14,14,0,0
0,0,0,0,0,0,2,0,0,20,0,0,0,0,20,0,0,0,0,0,0,0,0,0,0,0,0,20,0,20,3,0,0,0,0,0
0,0,0,0,0,0,14,2,0,0,0,0,0,0,0,0,20,0,0,0,20,0,20,0,0,0,0,0,0,3,0,0,0,0,0,0
0,0,0,0,0,0,0,16,3,0,0,0,0,0,20,0,0,0,20,0,0,0,0,0,0,0,20,0,3,0,0,0,0,0,0,0
0,0,0,0,0,0,0,0,0,2,0,0,20,20,0,0,0,0,0,20,0,20,0,20,20,0,20,3,0,0,0,0,0,0,0,0
0,0,0,0,0,0,0,0,0,0,3,2,20,20,0,20,0,0,0,0,0,0,0,0,0,3,3,0,0,0,0,0,0,0,0,0
0,0,0,0,0,0,0,0,0,0,0,0,3,2,2,0,20,0,30,0,0,0,3,3,3,0,0,0,0,0,0,0,0,0,0,0
0,0,0,0,0,0,0,0,0,0,0,0,0,0,0,2,2,3,2,3,2,3,0,0,0,0,0,0,0,0,0,0,0,0,0,0
0,0,0,0,0,0,0,0,0,0,0,0,0,0,0,0,0,14,14,14,14,0,0,0,0,0,0,0,0,0,0,0,0,0,0,0
0,0,0,0,0,0,0,0,0,0,0,0,0,0,0,0,0,0,0,0,0,0,0,0,0,0,0,0,0,0,0,0,0,0,0,0
0,0,0,0,0,0,0,0,0,0,0,0,0,0,0,0,0,0,0,0,0,0,0,0,0,0,0,0,0,0,0,0,0,0,0,0
0,0,0,0,0,0,0,0,0,0,0,0,0,0,0,0,45,0,0,0,0,0,0,0,0,0,0,0,0,0,0,0,0,0,0,0
0,0,0,0,0,0,0,0,0,0,0,0,0,0,0,0,0,0,0,0,0,0,0,0,0,0,0,0,0,0,0,0,0,0,0,0
endlayer

layer
0,0,0,0,0,0,0,0,0,0,0,0,0,0,0,0,0,0,0,0,0,0,0,0,0,0,0,0,0,0,0,0,0,0,0,0
0,0,0,16,14,14,0,0,0,0,0,0,0,0,0,0,0,0,0,0,0,0,0,0,0,0,0,0,0,0,0,0,0,0,0,0
0,0,0,3,3,2,3,3,3,3,3,3,2,3,2,3,2,3,2,3,3,3,3,2,3,2,3,3,3,3,3,2,2,2,0,0
0,0,16,3,0,0,0,0,20,0,0,20,0,20,0,0,0,0,0,0,0,0,0,0,0,0,0,0,20,0,0,0,0,3,16,0
0,0,0,2,0,14,14,0,0,0,0,0,0,0,0,20,0,0,0,0,0,0,0,0,0,0,0,0,0,0,0,0,0,3,16,14
0,0,0,2,0,14,0,0,0,0,0,0,0,20,0,20,0,0,0,0,0,0,0,0,0,0,0,0,0,20,0,0,0,3,16,0
0,0,0,2,20,0,0,0,0,0,0,0,0,0,20,0,0,0,0,0,0,20,0,20,20,0,0,0,0,0,0,20,0,3,0,0
0,0,0,3,0,0,0,0,0,0,20,0,20,0,0,0,0,0,20,0,0,0,0,0,0,0,0,20,0,0,20,0,0,3,0,0
0,0,0,3,0,0,0,0,0,0,0,0,0,0,0,0,0,0,20,0,0,0,0,20,0,0,0,20,0,0,0,0,0,0,0,0
0,0,0,3,0,0,20,0,0,0,0,0,0,0,20,0,0,20,0,0,0,0,0,20,0,20,20,0,0,0,0,0,16,0,0,0
0,0,0,2,0,0,0,20,0,0,0,0,0,20,20,0,0,0,20,0,0,20,0,20,0,20,0,0,0,0,0,0,20,3,0,0
0,0,0,2,20,20,20,0,0,0,0,20,20,0,0,0,20,0,0,0,0,0,0,20,0,0,0,0,0,0,0,0,0,2,0,0
0,0,0,3,20,0,0,0,20,0,0,0,20,0,0,0,0,0,20,0,20,0,0,0,0,20,20,0,0,0,20,0,0,3,0,0
0,0,0,2,20,0,20,0,0,0,0,0,0,0,0,0,0,0,0,0,0,0,0,20,0,0,20,0,0,0,0,0,0,3,0,0
0,0,0,2,0,0,0,0,0,0,0,0,0,20,0,0,0,0,0,0,0,0,0,0,0,0,0,20,0,0,0,0,20,2,0,0
0,0,0,3,0,0,0,0,20,0,0,0,0,0,0,0,0,20,0,0,0,0,0,0,20,0,20,0,0,0,0,0,0,3,0,0
0,0,0,2,20,0,0,0,0,0,0,0,20,0,0,0,0,20,0,0,20,0,20,0,0,20,0,0,0,0,20,0,0,3,0,0
0,0,0,3,0,20,0,0,20,0,20,0,20,0,0,0,20,0,0,0,0,0,0,0,0,0,20,0,20,0,0,0,20,2,0,0
0,0,0,3,0,0,0,20,0,0,0,20,0,0,0,0,0,0,0,0,0,0,0,0,0,0,0,0,0,0,20,20,0,3,0,0
0,0,0,3,0,0,0,0,0,0,0,0,20,0,0,0,0,0,0,20,0,0,0,0,20,20,0,0,20,0,0,0,20,2,0,0
0,0,0,3,0,20,0,0,0,0,0,0,20,0,0,0,0,0,0,0,0,0,0,0,0,0,0,0,0,0,20,0,0,2,0,0
0,0,0,0,2,0,0,0,0,0,20,0,0,0,0,0,0,0,20,20,0,0,0,0,0,0,0,0,20,0,0,0,2,0,0,0
0,0,0,0,2,0,0,0,0,0,0,20,0,0,0,0,20,0,0,0,20,0,0,0,0,0,0,0,0,20,0,0,3,0,0,0
0,0,0,0,2,0,0,0,0,0,0,0,0,0,20,20,0,0,0,0,0,0,20,0,0,0,0,0,0,0,0,0,3,0,0,0
0,0,0,0,0,2,0,0,0,0,0,0,0,0,0,0,0,0,0,20,20,20,0,0,0,20,20,0,0,0,20,2,0,0,0,0
0,0,0,0,0,2,0,20,20,0,0,0,0,0,0,20,0,0,0,20,20,0,0,0,20,0,0,0,20,0,0,3,0,0,0,0
0,0,0,0,0,0,3,0,0,0,0,0,0,0,0,0,0,0,0,20,0,0,0,0,0,20,0,0,0,20,3,14,14,0,0,0
0,0,0,0,0,0,14,2,0,0,0,0,0,0,0,0,0,0,0,0,0,0,0,0,0,0,0,0,0,3,0,0,0,0,0,0
0,0,0,0,0,0,0,16,3,0,20,0,0,0,20,0,0,0,0,0,0,20,0,0,0,0,0,0,3,0,0,0,0,0,0,0
0,0,0,0,0,0,0,0,0,2,0,0,20,20,20,20,20,0,20,0,0,0,0,0,0,0,0,3,0,0,0,0,0,0,0,0
0,0,0,0,0,0,0,0,0,0,3,2,0,20,0,0,0,0,0,0,0,0,0,20,0,3,2,0,0,0,0,0,0,0,0,0
0,0,0,0,0,0,0,0,0,0,0,0,3,2,3,0,20,0,0,0,20,0,3,3,2,0,0,0,0,0,0,0,0,0,0,0
0,0,0,0,0,0,0,0,0,0,0,0,0,0,0,3,2,3,2,3,3,2,0,0,0,0,0,0,0,0,0,0,0,0,0,0
0,0,0,0,0,0,0,0,0,0,0,0,0,0,0,0,14,14,0,14,14,0,0,0,0,0,0,0,0,0,0,0,0,0,0,0
0,0,0,0,0,0,0,0,0,0,0,0,0,0,0,0,0,0,0,0,0,0,0,0,0,0,0,0,0,0,0,0,0,0,0,0
0,0,0,0,0,0,0,0,0,0,0,0,0,0,0,0,0,0,0,0,0,0,0,0,0,0,0,0,0,0,0,0,0,0,0,0
0,0,0,0,0,0,0,0,0,0,0,0,0,0,0,0,0,0,0,0,0,0,0,0,0,0,0,0,0,0,0,0,0,0,0,0
0,0,0,0,0,0,0,0,0,0,0,0,0,0,0,0,0,0,0,0,0,0,0,0,0,0,0,0,0,0,0,0,0,0,0,0
endlayer

layer
0,0,0,0,0,0,0,0,0,0,0,0,0,0,0,0,0,0,0,0,0,0,0,0,0,0,0,0,0,0,0,0,0,0,0,0
0,0,0,0,14,14,0,0,0,0,0,0,0,0,0,0,0,0,0,0,0,0,0,0,0,0,0,0,0,0,0,0,0,0,0,0
0,0,0,2,2,2,3,3,2,2,2,2,3,3,3,2,2,2,3,2,2,2,2,3,2,2,2,3,3,2,2,2,2,2,0,0
0,0,14,3,0,0,20,0,0,0,20,0,0,0,0,0,0,0,0,0,20,0,0,0,0,0,0,20,0,0,0,20,0,2,0,0
0,0,0,3,20,14,14,20,0,0,20,0,0,0,0,0,0,0,0,0,0,0,20,0,0,0,0,0,20,0,0,0,0,2,16,0
0,0,0,3,0,14,0,20,0,0,0,0,0,0,0,20,0,0,0,0,20,0,20,20,20,0,0,20,0,0,0,0,0,2,0,0
0,0,0,3,0,20,0,0,0,0,0,0,0,0,0,0,20,0,0,0,0,0,0,0,0,0,20,0,0,0,20,0,0,2,0,0
0,0,0,3,0,0,0,0,20,0,0,0,0,0,0,0,0,0,0,0,0,0,20,0,0,0,20,20,0,20,0,0,0,2,0,0
0,0,0,3,20,0,20,20,0,20,20,0,20,20,0,0,0,0,0,0,0,0,0,0,0,0,0,0,0,20,20,0,0,3,0,0
0,0,0,3,0,0,20,0,20,0,20,20,0,0,0,20,0,0,0,0,0,0,20,0,0,0,0,0,0,0,0,0,0,3,0,0
0,0,0,2,0,20,0,0,0,0,0,0,0,0,0,20,0,0,0,0,0,0,0,20,0,20,20,0,20,0,0,0,0,2,0,0
0,0,0,2,0,0,0,0,0,20,0,0,0,0,0,0,0,20,0,20,20,0,0,0,0,20,0,0,0,0,0,0,0,2,0,0
0,0,0,2,0,20,20,0,0,0,0,0,0,0,20,0,0,0,0,0,0,0,20,0,0,0,0,20,0,0,0,0,20,3,0,0
0,0,0,2,0,0,0,0,0,20,0,20,0,0,0,0,0,0,0,20,0,0,0,0,0,20,0,0,0,0,0,0,0,2,0,0
0,0,0,2,20,0,0,0,20,0,0,0,0,0,20,0,0,0,0,0,0,20,0,0,0,0,0,0,0,0,0,20,0,2,0,0
0,0,0,2,0,0,0,0,0,0,0,0,20,20,0,0,0,0,0,0,0,0,0,20,0,0,0,20,0,0,0,0,0,3,0,0
0,0,0,3,0,20,0,0,0,0,0,0,0,0,20,0,0,20,20,0,0,0,0,20,0,20,0,0,0,0,20,20,20,2,0,0
0,0,0,2,20,20,0,0,0,0,0,0,0,0,0,0,0,0,0,0,0,0,20,0,0,0,0,20,0,0,0,0,20,3,0,0
0,0,0,3,0,0,0,0,0,0,0,0,0,0,20,20,0,20,20,20,0,0,0,0,0,20,20,0,0,20,0,0,20,3,0,0
0,0,0,3,0,0,0,20,20,20,0,0,0,0,0,0,0,0,0,0,0,0,0,0,0,0,0,0,0,0,20,0,0,2,0,0
0,0,0,2,0,20,0,0,0,0,0,0,0,0,0,0,20,0,0,0,0,20,0,0,20,0,0,0,0,0,20,0,0,3,0,0
0,0,0,0,2,0,0,0,0,0,0,20,0,0,20,20,0,20,0,0,0,0,20,0,0,0,0,0,0,0,0,0,3,0,0,0
0,0,0,0,2,0,0,0,20,0,0,20,20,20,0,0,0,0,0,0,0,0,0,0,20,0,0,0,0,0,0,20,3,0,0,0
0,0,0,0,3,0,20,0,0,20,20,0,0,0,20,0,20,0,0,0,20,20,0,0,0,0,0,0,0,0,20,20,2,0,0,0
0,0,0,0,0,2,20,0,20,0,0,0,0,0,0,20,0,0,0,0,20,0,0,20,0,0,0,0,0,0,0,2,14,0,0,0
0,0,0,0,0,2,0,0,0,0,0,0,0,0,0,20,0,0,20,0,0,0,0,0,0,0,0,0,0,0,0,2,14,0,0,0
0,0,0,0,0,0,2,0,0,0,0,0,20,20,0,0,0,0,0,0,0,20,20,0,0,0,0,0,0,0,3,14,0,0,0,0
0,0,0,0,0,0,0,3,0,0,0,0,0,0,0,20,0,20,0,0,0,0,20,0,0,20,20,0,0,2,0,0,0,0,0,0
0,0,0,0,0,0,0,16,3,0,0,0,0,0,0,20,0,20,0,0,0,0,20,20,0,0,0,0,3,0,0,0,0,0,0,0
0,0,0,0,0,0,0,0,0,2,0,0,0,0,20,0,20,20,0,20,0,0,0,0,0,20,0,3,0,0,0,0,0,0,0,0
0,0,0,0,0,0,0,0,0,0,2,2,0,0,20,0,0,20,0,0,0,0,0,20,20,2,2,0,0,0,0,0,0,0,0,0
0,0,0,0,0,0,0,0,0,0,0,0,3,2,2,0,0,20,20,0,0,0,3,3,3,0,0,0,0,0,0,0,0,0,0,0
0,0,0,0,0,0,0,0,0,0,0,0,0,0,0,2,2,3,3,3,2,2,0,0,0,0,0,0,0,0,0,0,0,0,0,0
0,0,0,0,0,0,0,0,0,0,0,0,0,0,0,0,0,0,0,0,0,0,0,0,0,0,0,0,0,0,0,0,0,0,0,0
0,0,0,0,0,0,0,0,0,0,0,0,0,0,0,0,0,0,0,0,0,0,0,0,0,0,0,0,0,0,0,0,0,0,0,0
0,0,0,0,0,0,0,0,0,0,0,0,0,0,0,0,0,0,0,0,0,0,0,0,0,0,0,0,0,0,0,0,0,0,0,0
0,0,0,0,0,0,0,0,0,0,0,0,0,0,0,0,0,0,0,0,0,0,0,0,0,0,0,0,0,0,0,0,0,0,0,0
0,0,0,0,0,0,0,0,0,0,0,0,0,0,0,0,0,0,0,0,0,0,0,0,0,0,0,0,0,0,0,0,0,0,0,0
endlayer

layer
0,0,0,0,0,0,0,0,0,0,0,0,0,0,0,0,0,0,0,0,0,0,0,0,0,0,0,0,0,0,0,0,0,0,0,0
0,0,0,16,14,14,0,0,0,0,0,0,0,0,0,0,0,0,0,0,0,0,0,0,0,0,0,0,0,0,0,0,0,0,0,0
0,0,16,2,3,2,3,3,3,3,3,2,2,3,3,2,2,3,3,2,2,3,3,2,3,3,2,3,2,3,2,2,3,3,0,0
0,0,0,2,0,0,0,20,0,0,20,0,0,0,0,0,20,0,0,0,0,0,20,0,0,0,0,0,0,0,0,0,0,3,14,0
0,0,0,3,0,20,0,0,0,0,0,0,0,0,20,0,0,0,0,0,0,0,0,0,0,0,0,20,0,0,0,0,0,3,14,0
0,0,0,2,20,14,0,0,0,0,0,0,20,0,0,0,0,0,0,0,0,0,0,0,0,0,20,0,0,0,0,20,0,3,14,0
0,0,0,3,0,0,0,0,0,0,0,0,0,0,0,0,0,0,0,0,0,20,0,0,0,0,0,0,0,0,0,0,20,2,0,0
0,0,0,2,20,0,0,0,0,0,20,0,0,0,20,0,0,0,0,0,20,20,0,20,0,0,0,0,20,0,0,0,0,3,0,0
0,0,0,3,0,0,20,20,0,20,0,0,0,0,0,20,0,0,20,0,20,0,0,0,0,0,14,0,20,20,0,0,0,2,0,0
0,0,0,2,0,0,0,0,20,20,0,0,20,0,0,0,0,20,0,20,0,0,0,0,0,0,0,0,0,0,0,0,0,3,0,0
0,0,0,3,20,0,20,0,0,0,0,20,20,0,0,0,0,0,0,20,0,0,20,0,0,0,0,0,0,20,0,0,0,3,0,0
0,0,0,2,0,0,0,0,20,0,0,0,0,0,0,0,0,0,20,0,20,0,0,0,0,0,0,0,0,0,20,0,0,3,0,0
0,0,0,2,0,20,0,0,0,0,0,20,0,0,0,20,0,0,0,0,20,0,0,20,0,0,0,0,20,0,0,0,0,2,0,0
0,0,0,2,0,0,0,0,0,0,0,0,0,0,0,0,0,0,0,20,0,20,0,0,0,0,0,0,0,0,0,0,0,2,0,0
0,0,0,2,20,0,0,0,0,0,0,0,0,0,0,0,0,0,0,0,0,20,0,0,0,20,0,20,20,0,0,0,0,2,0,0
0,0,0,2,0,0,20,0,0,0,0,0,0,0,20,0,0,0,20,20,0,0,20,20,0,0,0,0,0,0,0,0,20,2,0,0
0,0,0,3,0,0,0,0,20,0,0,0,0,0,0,0,0,20,0,0,0,20,0,20,0,0,0,0,0,0,0,0,0,2,0,0
0,0,0,3,0,0,0,0,0,0,0,0,20,0,0,0,0,20,0,0,0,0,0,0,0,0,20,0,0,0,0,0,0,3,0,0
0,0,0,2,20,20,0,0,0,0,0,0,0,20,0,20,0,0,0,0,0,20,20,0,0,20,0,0,0,0,0,0,20,3,0,0
0,0,0,3,0,20,0,0,0,20,0,0,0,0,20,20,0,0,0,20,0,0,0,20,0,0,0,0,0,0,20,0,0,3,0,0
0,0,0,2,0,0,20,0,0,0,0,0,0,0,0,0,0,0,20,0,0,0,0,0,0,20,0,20,0,0,20,0,0,2,0,0
0,0,0,0,2,0,0,0,0,0,0,20,20,0,0,0,0,20,0,20,0,0,0,0,0,0,0,20,0,0,0,0,2,0,0,0
0,0,0,0,3,0,20,0,0,0,0,0,0,0,0,0,0,0,0,0,0,0,0,20,0,20,0,0,0,0,0,20,2,0,0,0
0,0,0,0,2,0,0,0,0,0,0,20,0,20,0,20,0,0,20,0,0,0,0,20,0,0,0,0,0,20,0,0,3,0,0,0
0,0,0,0,0,3,0,0,0,0,0,0,0,0,0,0,0,0,0,0,0,0,0,20,0,20,0,0,0,0,0,2,0,0,0,0
0,0,0,0,0,3,0,0,0,0,0,20,0,0,20,0,20,0,0,0,0,0,0,0,0,0,0,0,20,0,0,3,14,0,0,0
0,0,0,0,0,0,2,0,20,0,20,0,20,0,0,0,0,0,0,0,0,0,0,0,0,0,0,0,0,0,2,0,14,0,0,0
0,0,0,0,0,0,0,3,20,0,0,0,0,20,0,0,0,0,0,0,0,0,0,0,0,20,0,0,0,2,0,0,0,0,0,0
0,0,0,0,0,0,0,16,2,0,0,20,0,20,20,20,20,0,0,0,0,0,0,0,0,0,0,0,2,0,0,0,0,0,0,0
0,0,0,0,0,0,0,14,16,3,0,0,0,0,20,0,0,0,0,0,0,20,0,0,0,0,20,3,0,0,0,0,0,0,0,0
0,0,0,0,0,0,0,0,0,0,2,2,0,0,0,0,0,20,0,0,0,0,20,0,0,3,2,0,0,0,0,0,0,0,0,0
0,0,0,0,0,0,0,0,0,0,0,0,3,3,3,0,0,0,0,0,0,0,2,3,3,0,0,0,0,0,0,0,0,0,0,0
0,0,0,0,0,0,0,0,0,0,0,0,0,0,0,2,3,2,3,3,3,2,0,0,0,0,0,0,0,0,0,0,0,0,0,0
0,0,0,0,0,0,0,0,0,0,0,0,0,0,0,0,0,0,0,0,0,0,0,0,0,0,0,0,0,0,0,0,0,0,0,0
0,0,0,0,0,0,0,0,0,0,0,0,0,0,0,0,0,0,0,0,0,0,0,0,0,0,0,0,0,0,0,0,0,0,0,0
0,0,0,0,0,0,0,0,0,0,0,0,0,0,0,0,0,0,0,0,0,0,0,0,0,0,0,0,0,0,0,0,0,0,0,0
0,0,0,0,0,0,0,0,0,0,0,0,0,0,0,0,0,0,0,0,0,0,0,0,0,0,0,0,0,0,0,0,0,0,0,0
0,0,0,0,0,0,0,0,0,0,0,0,0,0,0,0,0,0,0,0,0,0,0,0,0,0,0,0,0,0,0,0,0,0,0,0
endlayer

layer
0,0,0,0,0,0,0,0,0,0,0,0,0,0,0,0,0,0,0,0,0,0,0,0,0,0,0,0,0,0,0,0,0,0,0,0
0,0,0,0,14,14,14,0,0,0,0,0,0,0,0,0,0,0,0,0,0,0,0,0,0,0,0,0,0,0,0,0,0,0,0,0
0,0,14,31,31,31,31,31,31,31,31,31,31,31,31,31,31,31,31,31,31,31,31,31,31,31,31,31,31,31,31,31,31,31,0,0
0,0,0,31,0,0,0,0,0,31,31,31,31,0,0,0,0,0,0,0,0,0,0,0,31,31,31,31,0,0,0,0,0,31,14,0
0,0,0,31,0,0,0,0,0,0,0,0,0,0,0,0,0,0,0,0,0,0,0,0,0,0,0,0,0,0,0,0,0,31,14,0
0,0,0,31,0,0,14,0,0,0,0,0,0,0,0,0,0,20,0,0,0,0,0,20,0,0,0,20,0,0,0,0,0,31,14,0
0,0,0,31,0,0,16,16,0,0,0,0,0,0,0,0,0,0,0,0,0,0,20,0,0,0,0,0,0,0,0,0,0,31,0,0
0,0,0,31,0,0,0,0,0,0,0,0,0,0,20,0,0,0,0,0,0,0,0,20,0,0,0,20,0,0,0,0,0,31,0,0
0,0,0,31,31,0,0,0,0,0,0,0,0,0,0,0,0,0,0,0,0,0,0,0,0,20,14,0,0,0,0,0,31,31,0,0
0,0,0,31,31,0,0,0,20,0,0,20,0,0,0,0,0,0,0,0,0,0,0,0,0,0,0,0,0,0,0,0,31,31,0,0
0,0,0,31,31,0,0,0,0,0,0,0,0,0,0,0,0,0,0,0,0,0,0,0,0,0,0,0,0,20,0,0,31,31,0,0
0,0,0,31,31,0,0,0,0,0,0,0,0,20,0,20,0,0,20,0,0,0,0,0,0,0,0,0,0,0,0,0,31,31,0,0
0,0,0,31,0,0,0,0,0,0,0,0,0,0,0,0,0,0,0,0,0,0,0,0,0,0,0,0,0,0,0,0,0,31,0,0
0,0,0,31,0,0,0,0,0,0,0,0,0,0,0,0,0,0,0,0,0,0,0,0,0,0,0,0,0,0,0,0,0,31,0,0
0,0,0,31,0,0,0,0,0,20,0,0,0,0,0,0,0,0,0,0,20,0,0,0,0,0,0,0,0,0,0,0,0,31,0,0
0,0,0,31,0,0,0,0,0,0,0,0,0,0,0,0,0,0,0,0,0,0,0,0,0,0,0,0,0,0,20,0,0,31,0,0
0,0,0,31,0,0,0,0,0,20,0,0,0,0,0,0,0,0,0,0,0,0,0,0,20,0,0,0,0,0,0,0,0,31,0,0
0,0,0,31,0,0,0,0,0,0,0,0,0,0,0,0,0,0,0,0,0,0,0,0,0,0,0,0,0,0,20,0,0,31,0,0
0,0,0,31,0,0,0,0,0,0,0,0,0,0,0,0,0,0,0,0,0,0,0,0,0,0,0,0,0,0,0,0,0,31,0,0
0,0,0,31,0,20,0,0,0,0,0,0,0,0,0,0,0,0,0,20,0,0,0,0,20,0,0,0,0,0,0,0,0,31,0,0
0,0,0,31,0,0,0,0,0,0,0,0,0,0,0,0,0,0,0,0,0,0,0,0,0,0,0,0,0,0,0,0,0,31,0,0
0,0,0,0,31,0,0,0,0,0,0,0,0,0,0,0,0,0,20,0,0,0,0,0,0,0,0,0,0,0,0,0,31,0,0,0
0,0,0,0,31,0,0,0,20,0,20,0,0,0,0,0,0,0,20,0,0,0,0,0,0,0,0,0,0,0,0,0,31,0,0,0
0,0,0,0,31,0,0,0,0,0,0,0,0,0,20,0,0,0,0,0,0,0,0,0,0,0,0,0,0,0,0,0,31,0,0,0
0,0,0,0,0,31,0,0,0,0,0,0,0,0,20,0,0,0,0,0,0,0,0,0,20,0,0,0,0,20,20,31,0,0,0,0
0,0,0,0,0,31,0,0,0,0,0,0,0,0,0,0,0,0,0,0,0,0,0,0,0,0,14,0,0,0,0,31,14,0,0,0
0,0,0,0,0,0,31,0,0,0,0,0,0,0,0,20,0,0,0,0,0,0,0,0,0,0,0,0,0,0,31,0,0,0,0,0
0,0,0,0,0,0,0,31,0,0,0,0,0,0,0,0,0,20,0,0,0,0,0,0,0,0,0,0,0,31,0,0,0,0,0,0
0,0,0,0,0,0,0,14,31,0,0,20,0,0,0,0,0,0,0,0,0,20,20,0,0,0,0,20,31,0,0,0,0,0,0,0
0,0,0,0,0,0,0,14,14,31,0,0,0,0,0,0,0,0,0,0,0,0,20,0,0,0,0,31,0,0,0,0,0,0,0,0
0,0,0,0,0,0,0,0,0,0,31,31,0,0,0,0,0,0,0,0,0,0,0,0,0,31,31,0,0,0,0,0,0,0,0,0
0,0,0,0,0,0,0,0,0,0,0,0,31,31,31,0,0,0,0,0,0,0,31,31,31,0,0,0,0,0,0,0,0,0,0,0
0,0,0,0,0,0,0,0,0,0,0,0,0,0,0,31,31,31,31,31,31,31,0,0,0,0,0,0,0,0,0,0,0,0,0,0
0,0,0,0,0,0,0,0,0,0,0,0,0,0,0,0,0,0,0,0,0,0,0,0,0,0,0,0,0,0,0,0,0,0,0,0
0,0,0,0,0,0,0,0,0,0,0,0,0,0,0,0,0,0,0,0,0,0,0,0,0,0,0,0,0,0,0,0,0,0,0,0
0,0,0,0,0,0,0,0,0,0,0,0,0,0,0,0,0,0,0,0,0,0,0,0,0,0,0,0,0,0,0,0,0,0,0,0
0,0,0,0,0,0,0,0,0,0,0,0,0,0,0,0,0,0,0,0,0,0,0,0,0,0,0,0,0,0,0,0,0,0,0,0
0,0,0,0,0,0,0,0,0,0,0,0,0,0,0,0,0,0,0,0,0,0,0,0,0,0,0,0,0,0,0,0,0,0,0,0
endlayer

layer
0,0,0,0,0,0,0,0,0,0,0,0,0,0,0,0,0,0,0,0,0,0,0,0,0,0,0,0,0,0,0,0,0,0,0,0
0,0,0,0,14,0,0,0,0,0,0,0,0,0,0,0,0,0,0,0,0,0,0,0,0,0,0,0,0,0,0,0,0,0,0,0
0,0,0,0,14,14,14,0,0,0,0,0,0,31,31,31,31,31,31,31,31,31,31,31,18,18,0,0,0,0,0,0,0,0,0,0
0,0,0,0,31,31,31,31,31,31,31,31,31,0,0,0,0,0,0,0,0,0,0,0,31,31,31,31,31,31,31,31,31,0,0,0
0,0,0,0,31,0,0,0,0,0,0,0,0,0,0,0,0,0,0,0,0,0,20,0,0,0,0,0,0,0,0,0,31,14,0,0
0,0,0,0,31,0,14,20,0,0,0,0,0,0,0,0,0,0,0,20,0,0,0,0,0,0,0,0,0,0,0,0,31,14,0,0
0,0,0,0,31,0,16,0,0,0,0,0,0,0,0,0,0,20,0,0,0,0,0,0,0,0,0,0,0,0,0,0,31,0,0,0
0,0,0,0,31,0,0,0,0,0,0,0,20,0,0,0,0,0,0,0,0,0,0,0,0,0,20,0,0,0,0,0,31,0,0,0
0,0,0,0,31,0,0,0,0,0,0,0,0,0,0,0,0,0,0,0,0,0,0,0,0,0,14,0,0,0,0,0,31,0,0,0
0,0,0,0,31,0,0,0,0,0,20,0,0,0,0,0,0,0,0,0,20,0,0,0,0,0,0,0,20,0,0,0,31,0,0,0
0,0,0,0,31,0,0,0,0,0,0,0,0,0,0,0,0,0,0,0,0,0,0,0,0,0,0,0,20,0,0,0,31,0,0,0
0,0,0,0,31,0,0,0,0,0,20,0,0,0,0,0,0,0,0,0,0,0,0,0,0,0,0,0,0,0,0,0,31,0,0,0
0,0,0,31,0,0,0,0,0,0,0,0,0,0,0,0,0,0,0,0,0,20,0,0,0,0,0,0,0,0,0,0,0,31,0,0
0,0,0,31,0,0,0,0,0,0,0,0,0,0,0,0,0,0,0,0,0,0,0,0,0,0,0,0,0,0,0,0,0,31,0,0
0,0,0,31,0,0,0,0,0,0,0,0,0,0,0,0,0,0,0,20,0,0,0,0,0,0,0,0,0,0,0,0,0,31,0,0
0,0,0,31,0,0,0,0,0,0,0,0,0,0,0,0,0,0,0,0,0,0,0,0,20,0,0,0,0,0,0,0,0,31,0,0
0,0,0,31,0,0,0,0,0,0,0,0,0,0,0,20,0,0,0,0,0,0,0,0,0,0,0,0,0,0,0,0,0,31,0,0
0,0,0,31,0,0,0,0,0,0,0,0,0,20,0,0,0,0,0,0,0,0,0,0,0,0,0,0,0,0,0,0,0,31,0,0
0,0,0,31,0,0,0,0,20,0,0,0,0,0,0,0,0,0,0,0,0,0,0,0,0,0,0,0,0,0,0,0,0,31,0,0
0,0,0,31,0,0,0,0,0,0,0,0,0,0,0,0,0,0,0,0,0,0,0,0,0,0,0,0,0,0,0,0,0,31,0,0
0,0,0,31,0,0,0,0,0,0,0,0,0,0,0,0,0,0,0,0,0,0,0,0,0,0,20,0,0,0,0,0,0,31,0,0
0,0,0,0,31,20,0,0,0,0,0,0,0,0,0,0,0,0,0,0,20,0,0,0,0,0,0,0,0,0,0,0,31,0,0,0
0,0,0,0,31,0,0,0,0,0,0,0,0,0,0,0,0,0,20,0,0,0,0,0,20,0,0,0,0,0,0,0,31,0,0,0
0,0,0,0,31,0,0,0,0,0,0,0,0,0,0,0,20,0,0,0,0,0,0,0,0,0,0,0,20,0,0,0,31,0,0,0
0,0,0,0,0,31,0,0,0,0,0,0,0,0,0,0,0,0,0,0,20,0,0,0,0,20,0,0,0,0,0,31,14,0,0,0
0,0,0,0,0,31,0,0,0,0,0,0,0,0,0,0,0,0,0,0,0,0,0,0,0,0,14,20,0,0,0,31,14,0,0,0
0,0,0,0,0,0,31,0,0,0,0,0,0,0,0,0,0,0,0,20,0,0,0,0,0,0,0,0,0,0,31,0,14,0,0,0
0,0,0,0,0,0,0,31,0,0,0,0,0,0,20,0,0,0,0,20,0,0,0,0,0,0,0,0,0,31,0,0,0,0,0,0
0,0,0,0,0,0,0,16,31,0,0,0,0,14,0,0,0,0,0,0,0,0,0,0,0,0,0,0,31,0,0,0,0,0,0,0
0,0,0,0,0,0,0,14,14,31,0,0,0,0,0,0,0,0,0,0,0,0,0,0,0,0,0,31,0,0,0,0,0,0,0,0
0,0,0,0,0,0,0,0,0,0,31,31,0,0,0,20,0,0,0,0,0,0,0,0,0,31,31,0,0,0,0,0,0,0,0,0
0,0,0,0,0,0,0,0,0,0,0,0,31,31,31,0,0,0,0,0,0,0,31,31,31,0,0,0,0,0,0,0,0,0,0,0
0,0,0,0,0,0,0,0,0,0,0,0,0,0,0,31,31,31,31,31,31,31,0,0,0,0,0,0,0,0,0,0,0,0,0,0
0,0,0,0,0,0,0,0,0,0,0,0,0,0,0,0,0,0,0,0,0,0,0,0,0,0,0,0,0,0,0,0,0,0,0,0
0,0,0,0,0,0,0,0,0,0,0,0,0,0,0,0,0,0,0,0,0,0,0,0,0,0,0,0,0,0,0,0,0,0,0,0
0,0,0,0,0,0,0,0,0,0,0,0,0,0,0,0,0,0,0,0,0,0,0,0,0,0,0,0,0,0,0,0,0,0,0,0
0,0,0,0,0,0,0,0,0,0,0,0,0,0,0,0,0,0,0,0,0,0,0,0,0,0,0,0,0,0,0,0,0,0,0,0
0,0,0,0,0,0,0,0,0,0,0,0,0,0,0,0,0,0,0,0,0,0,0,0,0,0,0,0,0,0,0,0,0,0,0,0
endlayer

layer
0,0,0,0,0,0,0,0,0,0,0,0,0,0,0,0,0,0,0,0,0,0,0,0,0,0,0,0,0,0,0,0,0,0,0,0
0,0,0,0,0,0,0,0,0,0,0,0,0,0,0,0,0,0,0,0,0,0,0,0,0,0,0,0,0,0,0,0,0,0,0,0
0,0,0,0,0,0,0,0,0,0,0,0,0,0,0,0,31,31,31,31,31,0,18,18,0,0,0,0,0,0,0,0,0,0,0,0
0,0,0,0,16,16,16,0,0,0,0,0,0,31,31,31,0,0,0,20,0,31,31,31,1,1,1,1,0,0,0,0,0,0,0,0
0,0,0,0,0,31,31,31,31,31,31,31,31,0,0,0,0,0,0,0,0,0,0,0,31,31,31,31,31,31,31,31,0,14,0,0
0,0,0,0,0,31,14,0,0,0,0,0,0,0,0,0,0,0,0,0,0,0,0,0,0,0,0,0,0,0,0,31,14,14,0,0
0,0,0,0,0,31,14,14,0,0,0,0,0,0,0,0,0,0,0,0,0,0,0,0,0,0,0,0,0,0,0,31,14,0,0,0
0,0,0,0,0,31,0,0,20,0,0,0,0,0,0,0,0,0,0,20,0,0,0,0,0,20,0,0,0,0,0,31,0,0,0,0
0,0,0,0,0,31,0,0,0,0,0,0,0,0,0,0,0,0,0,0,0,0,0,0,0,0,14,0,0,0,0,31,0,0,0,0
0,0,0,0,0,31,0,0,0,0,0,0,0,0,0,0,0,0,0,0,0,0,0,0,0,0,0,0,0,0,0,31,0,0,0,0
0,0,0,0,0,31,20,0,0,0,0,0,0,0,0,0,0,0,0,0,0,0,0,0,0,0,0,0,0,0,0,31,0,0,0,0
0,0,0,0,0,31,0,0,0,0,0,0,0,0,0,0,0,0,0,0,0,0,0,0,0,0,0,14,0,0,0,31,0,0,0,0
0,0,0,0,31,0,0,0,0,0,0,0,0,0,0,0,0,0,0,0,0,0,0,0,0,0,0,0,20,0,0,0,31,0,0,0
0,0,0,0,31,0,0,0,0,0,0,20,0,0,0,0,0,0,0,0,0,0,0,0,0,0,0,0,0,0,0,0,31,0,0,0
0,0,0,0,31,0,0,0,0,0,0,0,0,0,0,0,0,0,0,0,0,0,0,0,20,0,0,0,0,0,0,0,31,0,0,0
0,0,0,31,0,0,20,0,0,0,0,0,0,0,0,0,0,0,0,0,0,0,0,0,0,0,0,0,0,0,0,0,0,31,0,0
0,0,0,31,0,0,0,0,0,0,0,0,0,0,0,0,0,20,0,0,0,0,0,0,0,0,0,0,0,0,0,0,0,31,0,0
0,0,0,31,0,0,0,0,0,0,0,0,0,0,0,0,0,0,0,0,0,0,0,0,0,0,0,0,0,0,0,0,0,31,0,0
0,0,0,31,0,0,0,0,0,0,0,0,0,0,0,0,0,0,0,0,0,0,0,0,0,0,0,0,0,0,0,0,0,31,0,0
0,0,0,31,0,0,0,0,0,0,0,0,0,20,0,0,0,0,0,0,0,0,0,0,0,0,0,0,0,0,0,0,0,31,0,0
0,0,0,0,31,0,0,0,0,20,0,0,0,0,0,0,0,0,0,0,0,0,0,0,0,0,0,0,0,0,0,0,31,0,0,0
0,0,0,0,31,0,0,0,0,0,0,0,0,0,0,0,0,0,0,0,0,0,0,0,0,0,0,0,0,0,0,0,31,0,0,0
0,0,0,0,31,0,0,0,0,0,0,20,0,0,0,20,0,0,20,0,0,0,0,0,0,0,0,0,0,0,0,0,31,0,0,0
0,0,0,0,0,31,0,0,0,0,20,0,0,0,0,0,0,0,0,0,0,0,0,0,0,0,0,0,0,0,0,31,0,0,0,0
0,0,0,0,0,31,0,0,0,0,0,0,0,0,0,0,0,0,0,20,0,0,0,0,0,0,0,0,0,0,0,31,14,0,0,0
0,0,0,0,0,0,31,0,0,0,0,0,0,0,0,0,0,0,0,0,0,20,0,0,0,0,14,0,0,0,31,14,0,0,0,0
0,0,0,0,0,0,31,0,0,20,0,0,0,0,0,0,0,0,0,0,0,0,0,0,0,0,0,0,0,0,31,0,0,0,0,0
0,0,0,0,0,0,0,31,0,0,0,0,0,0,0,0,0,0,0,0,0,0,0,0,0,0,0,0,0,31,0,0,0,0,0,0
0,0,0,0,0,0,0,14,31,0,0,20,0,14,0,0,0,0,0,0,0,0,0,0,0,0,0,0,31,0,0,0,0,0,0,0
0,0,0,0,0,0,0,14,14,31,31,0,0,0,0,0,0,0,0,0,0,0,0,20,0,0,31,31,0,0,0,0,0,0,0,0
0,0,0,0,0,0,0,0,0,0,0,31,31,0,0,0,20,0,0,0,0,0,0,0,31,31,0,0,0,0,0,0,0,0,0,0
0,0,0,0,0,0,0,0,0,0,0,0,0,31,31,31,0,0,0,0,0,31,31,31,0,0,0,0,0,0,0,0,0,0,0,0
0,0,0,0,0,0,0,0,0,0,0,0,0,0,0,0,31,31,31,31,31,0,0,0,0,0,0,0,0,0,0,0,0,0,0,0
0,0,0,0,0,0,0,0,0,0,0,0,0,0,0,0,0,0,0,0,0,0,0,0,0,0,0,0,0,0,0,0,0,0,0,0
0,0,0,0,0,0,0,0,0,0,0,0,0,0,0,0,0,0,0,0,0,0,0,0,0,0,0,0,0,0,0,0,0,0,0,0
0,0,0,0,0,0,0,0,0,0,0,0,0,0,0,0,0,0,0,0,0,0,0,0,0,0,0,0,0,0,0,0,0,0,0,0
0,0,0,0,0,0,0,0,0,0,0,0,0,0,0,0,0,0,0,0,0,0,0,0,0,0,0,0,0,0,0,0,0,0,0,0
0,0,0,0,0,0,0,0,0,0,0,0,0,0,0,0,0,0,0,0,0,0,0,0,0,0,0,0,0,0,0,0,0,0,0,0
endlayer

layer
0,0,0,0,0,0,0,0,0,0,0,0,0,0,0,0,0,0,0,0,0,0,0,0,0,0,0,0,0,0,0,0,0,0,0,0
0,0,0,0,0,0,0,0,0,0,0,0,0,0,0,0,0,0,0,0,0,0,0,0,0,0,0,0,0,0,0,0,0,0,0,0
0,0,0,0,0,0,0,0,0,0,0,0,0,0,0,0,0,0,0,0,0,0,0,0,0,0,0,0,0,0,0,0,0,0,0,0
0,0,0,0,0,16,0,14,0,0,0,0,0,31,31,31,31,31,31,31,31,31,31,31,0,0,0,0,0,0,0,0,0,0,0,0
0,0,0,0,0,16,0,16,0,0,0,31,31,0,0,0,0,0,0,0,0,0,0,0,31,31,5,1,1,0,0,0,0,0,0,0
0,0,0,0,0,0,0,31,31,31,31,0,0,0,0,0,0,0,0,0,0,0,0,0,0,0,31,31,31,31,31,14,0,0,0,0
0,0,0,0,0,0,14,0,0,0,0,0,0,0,0,0,0,0,0,0,0,0,0,0,0,0,0,0,0,0,31,14,14,0,0,0
0,0,0,0,0,0,31,0,0,0,0,0,0,0,0,0,0,0,0,0,0,0,0,0,0,0,16,0,0,0,31,14,0,0,0,0
0,0,0,0,0,0,31,0,0,0,0,0,0,0,0,0,0,0,0,0,0,0,0,0,0,0,16,0,0,0,31,0,0,0,0,0
0,0,0,0,0,0,31,0,0,0,0,0,0,0,0,0,0,0,0,0,0,0,0,0,0,0,0,0,0,0,31,0,0,0,0,0
0,0,0,0,0,31,0,0,0,0,0,0,0,0,0,0,0,0,0,0,0,0,0,0,0,0,0,0,0,0,0,31,0,0,0,0
0,0,0,0,0,31,0,0,0,0,0,0,0,0,0,0,0,0,0,0,0,0,0,0,0,0,0,14,0,0,0,31,0,0,0,0
0,0,0,0,31,0,0,0,0,0,0,0,0,0,0,0,0,0,0,0,0,0,0,0,0,0,0,0,0,0,0,0,31,0,0,0
0,0,0,0,31,0,0,0,0,0,0,0,0,0,0,0,0,0,0,0,0,0,0,0,0,0,0,0,0,0,0,0,31,0,0,0
0,0,0,0,31,0,0,0,0,0,0,0,0,0,0,0,0,0,0,0,0,0,0,0,0,0,0,0,0,0,0,0,31,0,0,0
0,0,0,0,31,0,0,0,0,0,0,0,0,0,0,0,0,0,0,0,0,0,0,0,0,0,0,0,0,0,0,0,31,0,0,0
0,0,0,0,31,0,0,0,0,0,0,0,0,0,0,0,0,0,0,0,0,0,0,0,0,0,0,0,0,0,0,0,31,0,0,0
0,0,0,0,31,0,0,0,0,0,0,0,0,0,0,0,0,0,0,0,0,0,0,0,0,0,0,0,0,0,0,0,31,0,0,0
0,0,0,0,31,0,0,0,0,0,0,0,0,0,0,0,0,0,0,0,0,0,0,0,0,0,0,0,0,0,0,0,31,0,0,0
0,0,0,0,31,0,0,0,0,0,0,0,0,0,0,0,0,0,0,0,0,0,0,0,0,0,0,0,0,0,0,0,31,0,0,0
0,0,0,0,31,0,0,0,0,0,0,0,0,0,0,0,0,0,0,0,0,0,0,0,0,0,0,0,0,0,0,0,31,0,0,0
0,0,0,0,31,0,0,0,0,0,0,0,0,0,0,0,0,0,0,0,0,0,0,0,0,0,0,0,0,0,0,0,31,0,0,0
0,0,0,0,31,0,0,0,0,0,0,0,0,0,0,0,0,0,0,0,0,0,0,0,0,0,0,0,0,0,0,0,31,0,0,0
0,0,0,0,0,31,0,0,0,0,0,0,0,0,0,0,0,0,0,0,0,0,0,0,0,0,0,0,16,0,0,31,0,0,0,0
0,0,0,0,0,31,0,0,0,0,0,0,0,0,0,0,0,0,0,0,0,0,0,0,0,0,0,0,0,0,0,31,14,0,0,0
0,0,0,0,0,0,31,0,0,0,0,0,0,0,0,0,0,0,0,0,0,0,0,0,0,0,14,0,0,0,31,14,0,0,0,0
0,0,0,0,0,0,0,31,0,0,0,0,0,0,0,0,0,0,0,0,0,0,0,0,0,0,0,0,0,31,0,0,0,0,0,0
0,0,0,0,0,0,0,31,0,0,0,0,0,0,0,0,0,0,0,0,0,0,0,0,0,0,0,0,0,31,0,0,0,0,0,0
0,0,0,0,0,0,0,14,31,31,0,0,0,14,0,0,0,0,0,0,0,0,0,0,0,0,0,31,31,0,0,0,0,0,0,0
0,0,0,0,0,0,0,0,14,0,31,0,0,0,0,0,0,0,0,0,0,0,0,0,0,0,31,0,0,0,0,0,0,0,0,0
0,0,0,0,0,0,0,0,14,0,0,31,31,0,0,0,0,0,0,0,0,0,0,0,31,31,0,0,0,0,0,0,0,0,0,0
0,0,0,0,0,0,0,0,0,0,0,0,0,31,31,31,31,31,31,31,31,31,31,31,0,0,0,0,0,0,0,0,0,0,0,0
0,0,0,0,0,0,0,0,0,0,0,0,0,0,0,0,0,0,0,0,0,0,0,0,0,0,0,0,0,0,0,0,0,0,0,0
0,0,0,0,0,0,0,0,0,0,0,0,0,0,0,0,0,0,0,0,0,0,0,0,0,0,0,0,0,0,0,0,0,0,0,0
0,0,0,0,0,0,0,0,0,0,0,0,0,0,0,0,0,0,0,0,0,0,0,0,0,0,0,0,0,0,0,0,0,0,0,0
0,0,0,0,0,0,0,0,0,0,0,0,0,0,0,0,0,0,0,0,0,0,0,0,0,0,0,0,0,0,0,0,0,0,0,0
0,0,0,0,0,0,0,0,0,0,0,0,0,0,0,0,0,0,0,0,0,0,0,0,0,0,0,0,0,0,0,0,0,0,0,0
0,0,0,0,0,0,0,0,0,0,0,0,0,0,0,0,0,0,0,0,0,0,0,0,0,0,0,0,0,0,0,0,0,0,0,0
endlayer

layer
0,0,0,0,0,0,0,0,0,0,0,0,0,0,0,0,0,0,0,0,0,0,0,0,0,0,0,0,0,0,0,0,0,0,0,0
0,0,0,0,0,0,0,0,0,0,0,0,0,0,0,0,0,0,0,0,0,0,0,0,0,0,0,0,0,0,0,0,0,0,0,0
0,0,0,0,0,0,0,0,0,0,0,0,0,0,0,0,0,0,0,0,0,0,0,0,0,0,0,0,0,0,0,0,0,0,0,0
0,0,0,0,0,0,0,0,0,0,0,0,0,0,31,31,31,31,31,31,31,31,31,1,0,0,0,0,0,0,0,0,0,0,0,0
0,0,0,0,0,0,0,0,0,0,0,0,31,31,0,0,0,0,0,0,0,0,0,31,31,1,1,0,0,0,0,0,0,0,0,0
0,0,0,0,0,0,0,16,14,0,31,31,0,0,0,0,0,0,0,0,0,0,0,0,0,31,31,1,1,1,14,0,0,0,0,0
0,0,0,0,0,0,16,31,31,31,0,0,0,0,0,0,0,0,0,0,0,0,0,0,0,0,0,31,31,31,14,0,14,0,0,0
0,0,0,0,0,0,14,31,31,0,0,0,0,0,0,0,0,0,0,0,0,0,0,0,0,0,14,0,31,31,14,14,0,0,0,0
0,0,0,0,0,0,0,31,0,0,0,0,0,0,0,0,0,0,0,0,0,16,0,0,0,0,14,0,0,31,0,0,0,0,0,0
0,0,0,0,0,0,31,0,0,0,0,0,0,0,0,0,0,0,0,0,0,0,0,0,0,0,0,0,0,0,31,0,0,0,0,0
0,0,0,0,0,0,31,0,0,0,0,0,0,0,0,0,0,0,0,0,0,0,0,0,0,0,0,0,0,0,31,0,0,0,0,0
0,0,0,0,0,31,0,0,0,0,0,0,0,0,0,0,0,0,0,0,0,0,0,0,0,0,0,14,0,0,0,31,0,0,0,0
0,0,0,0,0,31,0,0,0,0,0,0,0,0,0,0,0,0,0,0,0,0,0,0,0,0,0,0,0,0,0,31,0,0,0,0
0,0,0,0,31,0,0,0,0,0,0,0,0,0,0,0,0,0,0,0,0,0,0,0,0,0,0,0,0,0,0,0,31,0,0,0
0,0,0,0,31,0,0,0,0,0,0,0,0,0,0,0,0,0,0,0,0,0,0,0,0,0,0,0,0,0,0,0,31,0,0,0
0,0,0,0,31,0,0,0,0,0,0,0,0,0,0,0,0,0,0,0,0,0,0,0,0,0,0,0,0,0,0,0,31,0,0,0
0,0,0,0,31,0,0,0,0,0,0,0,0,0,0,0,0,0,0,0,0,0,0,0,0,0,0,0,0,0,0,0,31,0,0,0
0,0,0,0,31,0,0,0,0,0,0,0,0,0,0,0,0,0,0,0,0,0,0,0,0,0,0,0,0,0,0,0,31,0,0,0
0,0,0,0,31,0,0,0,0,0,0,0,0,0,0,0,0,0,0,0,0,0,0,0,0,0,0,0,0,0,0,0,31,0,0,0
0,0,0,0,31,0,0,0,0,0,0,0,0,0,0,0,0,0,0,0,0,0,0,0,0,0,0,0,0,0,0,0,31,0,0,0
0,0,0,0,31,0,0,0,0,0,0,0,0,0,0,0,0,0,0,0,0,0,0,0,0,0,0,0,0,0,0,0,31,0,0,0
0,0,0,0,31,0,0,0,0,0,0,0,0,0,0,0,0,0,0,0,0,0,0,0,0,0,0,0,0,0,0,0,31,0,0,0
0,0,0,0,18,31,0,0,0,0,0,0,0,0,0,0,0,0,0,0,0,0,0,0,0,0,0,0,0,0,0,31,0,0,0,0
0,0,0,0,0,31,0,0,0,0,0,0,0,0,0,0,0,0,0,0,0,0,0,0,0,0,0,0,16,0,0,31,0,0,0,0
0,0,0,0,0,0,31,0,0,0,0,0,0,0,0,0,0,0,0,0,0,0,0,0,0,0,0,0,0,0,31,14,0,0,0,0
0,0,0,0,0,0,31,0,0,0,0,0,0,0,0,0,0,0,0,0,0,0,0,0,0,0,14,0,0,0,31,14,0,0,0,0
0,0,0,0,0,0,0,31,0,0,0,0,0,0,0,0,0,0,0,0,0,0,0,0,0,0,0,0,0,31,0,14,0,0,0,0
0,0,0,0,0,0,0,0,31,0,0,0,0,0,0,0,0,0,0,0,0,0,0,0,0,0,0,0,31,0,0,0,0,0,0,0
0,0,0,0,0,0,0,14,0,31,0,0,0,14,0,0,0,0,0,0,0,0,0,0,0,0,0,31,0,0,0,0,0,0,0,0
0,0,0,0,0,0,0,0,16,16,31,31,0,0,0,0,0,0,0,0,0,0,0,0,0,31,31,0,0,0,0,0,0,0,0,0
0,0,0,0,0,0,0,0,0,0,0,0,31,31,0,0,0,0,0,0,0,0,0,31,31,0,0,0,0,0,0,0,0,0,0,0
0,0,0,0,0,0,0,0,0,0,0,0,0,0,31,31,31,31,31,31,31,31,31,0,0,0,0,0,0,0,0,0,0,0,0,0
0,0,0,0,0,0,0,0,0,0,0,0,0,0,0,0,0,0,0,0,0,0,0,0,0,0,0,0,0,0,0,0,0,0,0,0
0,0,0,0,0,0,0,0,0,0,0,0,0,0,0,0,0,0,0,0,0,0,0,0,0,0,0,0,0,0,0,0,0,0,0,0
0,0,0,0,0,0,0,0,0,0,0,0,0,0,0,0,0,0,0,0,0,0,0,0,0,0,0,0,0,0,0,0,0,0,0,0
0,0,0,0,0,0,0,0,0,0,0,0,0,0,0,0,0,0,0,0,0,0,0,0,0,0,0,0,0,0,0,0,0,0,0,0
0,0,0,0,0,0,0,0,0,0,0,0,0,0,0,0,0,0,0,0,0,0,0,0,0,0,0,0,0,0,0,0,0,0,0,0
0,0,0,0,0,0,0,0,0,0,0,0,0,0,0,0,0,0,0,0,0,0,0,0,0,0,0,0,0,0,0,0,0,0,0,0
endlayer

layer
0,0,0,0,0,0,0,0,0,0,0,0,0,0,0,0,0,0,0,0,0,0,0,0,0,0,0,0,0,0,0,0,0,0,0,0
0,0,0,0,0,0,0,0,0,0,0,0,0,0,0,0,0,0,0,0,0,0,0,0,0,0,0,0,0,0,0,0,0,0,0,0
0,0,0,0,0,0,0,0,0,0,0,0,0,0,0,0,0,0,0,0,0,0,0,0,0,0,0,0,0,0,0,0,0,0,0,0
0,0,0,0,0,0,0,0,0,0,0,0,0,0,0,0,31,31,31,31,31,18,18,0,0,0,0,0,0,0,0,0,0,0,0,0
0,0,0,0,0,0,0,0,0,0,0,0,0,31,31,31,0,0,0,0,0,31,31,31,1,0,0,0,0,0,0,0,0,0,0,0
0,0,0,0,0,0,0,0,0,0,0,31,31,0,0,0,0,0,0,0,0,0,0,0,31,31,0,0,14,0,0,0,0,0,0,0
0,0,0,0,0,0,0,0,0,31,31,0,0,0,0,0,0,0,0,0,0,0,0,0,0,0,31,31,14,14,14,0,0,0,0,0
0,0,0,0,0,0,0,14,31,0,0,0,0,0,0,0,0,0,0,0,0,0,0,0,0,14,14,14,31,14,0,0,0,0,0,0
0,0,0,0,0,0,0,31,0,0,0,0,0,0,0,0,0,0,0,0,0,16,0,0,0,0,14,14,0,31,0,0,0,0,0,0
0,0,0,0,0,0,0,31,0,0,0,0,0,0,0,0,0,0,0,0,0,0,0,0,0,0,0,0,0,31,0,0,0,0,0,0
0,0,0,0,0,0,31,0,0,0,0,0,0,0,0,0,0,0,0,0,0,0,0,0,0,0,0,0,0,0,31,0,0,0,0,0
0,0,0,0,0,0,31,0,0,0,0,0,0,0,0,0,0,0,0,0,0,0,0,0,0,0,0,14,0,0,31,0,0,0,0,0
0,0,0,0,0,31,0,0,0,0,0,0,0,0,0,0,0,0,0,0,0,0,0,0,0,0,0,0,0,0,0,31,0,0,0,0
0,0,0,0,0,31,0,0,0,0,0,0,0,0,0,0,0,0,0,0,0,0,0,0,0,0,0,0,0,0,0,31,0,0,0,0
0,0,0,0,0,31,0,0,0,0,0,0,0,0,0,0,0,0,0,0,0,0,0,0,0,0,0,0,0,0,0,31,0,0,0,0
0,0,0,0,31,0,0,0,0,0,0,0,0,0,0,0,0,0,0,0,0,0,0,0,0,0,0,0,0,0,0,0,31,0,0,0
0,0,0,0,31,0,0,0,0,0,0,0,0,0,0,0,0,0,0,0,0,0,0,0,0,0,0,0,0,0,0,0,31,0,0,0
0,0,0,0,31,0,0,0,0,0,0,0,0,0,0,0,0,0,0,0,0,0,0,0,0,0,0,0,0,0,0,0,31,0,0,0
0,0,0,0,31,0,0,0,0,0,0,0,0,0,0,0,0,0,0,0,0,0,0,0,0,0,0,0,0,0,0,0,31,0,0,0
0,0,0,0,31,0,0,0,0,0,0,0,0,0,0,0,0,0,0,0,0,0,0,0,0,0,0,0,0,0,0,0,31,0,0,0
0,0,0,0,18,31,0,0,0,0,0,0,0,0,0,0,0,0,0,0,0,0,0,0,0,0,0,0,0,0,0,31,0,0,0,0
0,0,0,0,18,31,0,0,0,0,0,0,0,0,0,0,0,0,0,0,0,0,0,0,0,0,0,0,0,0,0,31,0,0,0,0
0,0,0,0,0,31,0,0,0,0,0,0,0,0,0,0,0,0,0,0,0,0,0,0,0,0,0,0,0,0,0,31,0,0,0,0
0,0,0,0,0,18,31,0,0,0,0,0,0,0,0,0,0,0,0,0,0,0,0,0,0,0,0,0,16,0,31,0,0,0,0,0
0,0,0,0,0,0,31,0,0,0,14,0,0,0,0,0,0,0,0,0,0,0,0,0,0,0,0,0,0,0,31,14,14,0,0,0
0,0,0,0,0,0,0,31,0,0,0,0,0,0,0,0,0,0,0,0,0,0,0,0,0,0,14,0,0,31,14,0,0,0,0,0
0,0,0,0,0,0,0,31,0,0,0,0,0,0,0,0,0,0,0,0,0,0,0,0,0,0,0,0,0,31,0,0,0,0,0,0
0,0,0,0,0,0,0,14,31,0,0,0,0,0,0,0,0,0,0,0,0,0,0,0,0,0,0,0,31,0,0,0,0,0,0,0
0,0,0,0,0,0,0,14,0,31,31,0,0,14,0,0,0,0,0,0,0,0,0,0,0,0,31,31,0,0,0,0,0,0,0,0
0,0,0,0,0,0,0,0,0,16,0,31,31,0,0,0,0,0,0,0,0,0,0,0,31,31,0,0,0,0,0,0,0,0,0,0
0,0,0,0,0,0,0,0,0,0,0,0,0,31,31,31,0,0,0,0,0,31,31,31,0,0,0,0,0,0,0,0,0,0,0,0
0,0,0,0,0,0,0,0,0,0,0,0,0,0,0,0,31,31,31,31,31,0,0,0,0,0,0,0,0,0,0,0,0,0,0,0
0,0,0,0,0,0,0,0,0,0,0,0,0,0,0,0,0,0,0,0,0,0,0,0,0,0,0,0,0,0,0,0,0,0,0,0
0,0,0,0,0,0,0,0,0,0,0,0,0,0,0,0,0,0,0,0,0,0,0,0,0,0,0,0,0,0,0,0,0,0,0,0
0,0,0,0,0,0,0,0,0,0,0,0,0,0,0,0,0,0,0,0,0,0,0,0,0,0,0,0,0,0,0,0,0,0,0,0
0,0,0,0,0,0,0,0,0,0,0,0,0,0,0,0,0,0,0,0,0,0,0,0,0,0,0,0,0,0,0,0,0,0,0,0
0,0,0,0,0,0,0,0,0,0,0,0,0,0,0,0,0,0,0,0,0,0,0,0,0,0,0,0,0,0,0,0,0,0,0,0
0,0,0,0,0,0,0,0,0,0,0,0,0,0,0,0,0,0,0,0,0,0,0,0,0,0,0,0,0,0,0,0,0,0,0,0
endlayer

layer
0,0,0,0,0,0,0,0,0,0,0,0,0,0,0,0,0,0,0,0,0,0,0,0,0,0,0,0,0,0,0,0,0,0,0,0
0,0,0,0,0,0,0,0,0,0,0,0,0,0,0,0,0,0,0,0,0,0,0,0,0,0,0,0,0,0,0,0,0,0,0,0
0,0,0,0,0,0,0,0,0,0,0,0,0,0,0,0,0,0,0,0,0,0,0,0,0,0,0,0,0,0,0,0,0,0,0,0
0,0,0,0,0,0,0,0,0,0,0,0,0,0,0,0,0,0,0,0,0,0,0,0,0,0,0,0,0,0,0,0,0,0,0,0
0,0,0,0,0,0,0,0,0,0,0,0,0,0,31,31,31,31,31,31,31,31,31,1,0,0,0,0,0,0,0,0,0,0,0,0
0,0,0,0,0,0,0,0,0,0,0,0,31,31,0,0,0,0,0,0,0,0,0,31,31,0,0,0,0,0,0,0,0,0,0,0
0,0,0,0,0,0,0,0,0,0,31,31,0,0,0,0,0,0,0,0,0,0,0,0,0,31,31,0,0,0,0,0,0,0,0,0
0,0,0,0,0,0,0,0,0,31,0,0,0,0,0,0,0,0,0,0,0,0,0,0,0,0,14,14,14,14,0,0,0,0,0,0
0,0,0,0,0,0,0,0,31,0,0,0,0,0,0,0,0,0,0,0,0,16,0,0,0,0,14,14,31,14,0,0,0,0,0,0
0,0,0,0,0,0,0,31,0,0,0,0,0,0,0,0,0,0,0,0,0,0,0,0,0,0,0,0,14,31,0,0,0,0,0,0
0,0,0,0,0,0,0,31,0,0,0,0,0,0,0,0,0,0,0,0,0,0,0,0,0,0,0,0,0,31,0,0,0,0,0,0
0,0,0,0,0,0,31,0,0,0,0,0,0,0,0,0,0,0,0,0,0,0,0,0,0,0,0,14,0,0,31,0,0,0,0,0
0,0,0,0,0,0,31,0,0,0,0,0,0,0,0,0,0,0,0,0,0,0,0,0,0,0,0,0,0,0,31,0,0,0,0,0
0,0,0,0,0,31,0,0,0,0,0,0,0,0,0,0,0,0,0,0,0,0,0,0,0,0,0,0,0,0,0,31,0,0,0,0
0,0,0,0,0,31,0,0,0,0,0,0,0,0,0,46,46,46,0,0,0,0,0,0,0,0,0,0,0,0,0,31,0,0,0,0
0,0,0,0,0,31,0,0,0,0,0,0,0,0,46,46,46,0,0,0,0,0,0,0,0,0,0,0,0,0,0,31,0,0,0,0
0,0,0,0,0,31,0,0,0,0,0,0,0,0,46,46,46,0,0,0,0,0,0,0,0,0,0,0,0,0,0,31,0,0,0,0
0,0,0,0,0,31,0,0,0,0,0,0,0,0,46,46,46,46,0,0,0,0,0,0,0,0,0,0,0,0,0,31,0,0,0,0
0,0,0,0,0,31,0,0,0,0,0,0,0,0,0,46,46,46,0,0,0,0,0,0,0,0,0,0,0,0,0,31,0,0,0,0
0,0,0,0,0,31,0,0,0,0,0,0,0,0,0,0,0,0,0,0,0,0,0,0,0,0,0,0,0,0,0,31,0,0,0,0
0,0,0,0,0,31,0,0,0,0,0,0,0,0,0,0,0,0,0,0,0,0,0,0,0,0,0,0,0,0,0,31,0,0,0,0
0,0,0,0,0,31,0,0,0,0,0,0,0,0,0,0,0,0,0,0,0,0,0,0,0,0,0,0,0,0,0,31,0,0,0,0
0,0,0,0,0,1,31,0,0,0,0,0,0,0,0,0,0,0,0,0,0,0,0,0,0,14,0,0,16,14,31,0,0,0,0,0
0,0,0,0,0,0,31,0,0,0,0,0,0,0,0,0,0,0,0,0,0,0,0,0,0,0,0,0,16,0,31,0,0,0,0,0
0,0,0,0,0,0,0,31,0,0,14,0,0,0,0,0,0,0,0,0,0,0,0,0,0,0,0,0,0,31,14,0,0,0,0,0
0,0,0,0,0,0,0,31,0,0,0,0,0,0,0,0,0,0,0,0,0,0,0,0,0,0,14,0,0,31,0,0,0,0,0,0
0,0,0,0,0,0,0,14,31,0,0,0,0,0,0,0,0,0,0,0,0,0,0,0,0,0,0,0,31,0,0,0,0,0,0,0
0,0,0,0,0,0,0,0,14,31,0,0,0,0,0,0,0,0,0,0,0,0,0,0,0,0,0,31,0,0,0,0,0,0,0,0
0,0,0,0,0,0,0,0,0,0,31,31,0,14,0,0,0,0,0,0,0,0,0,0,0,31,31,0,0,0,0,0,0,0,0,0
0,0,0,0,0,0,0,0,0,0,14,14,31,31,14,0,0,0,0,0,0,0,0,31,31,0,0,0,0,0,0,0,0,0,0,0
0,0,0,0,0,0,0,0,0,0,0,0,0,0,31,31,31,31,31,31,31,31,31,0,0,0,0,0,0,0,0,0,0,0,0,0
0,0,0,0,0,0,0,0,0,0,0,0,0,0,0,0,0,0,0,0,0,0,0,0,0,0,0,0,0,0,0,0,0,0,0,0
0,0,0,0,0,0,0,0,0,0,0,0,0,0,0,0,0,0,0,0,0,0,0,0,0,0,0,0,0,0,0,0,0,0,0,0
0,0,0,0,0,0,0,0,0,0,0,0,0,0,0,0,0,0,0,0,0,0,0,0,0,0,0,0,0,0,0,0,0,0,0,0
0,0,0,0,0,0,0,0,0,0,0,0,0,0,0,0,0,0,0,0,0,0,0,0,0,0,0,0,0,0,0,0,0,0,0,0
0,0,0,0,0,0,0,0,0,0,0,0,0,0,0,0,0,0,0,0,0,0,0,0,0,0,0,0,0,0,0,0,0,0,0,0
0,0,0,0,0,0,0,0,0,0,0,0,0,0,0,0,0,0,0,0,0,0,0,0,0,0,0,0,0,0,0,0,0,0,0,0
0,0,0,0,0,0,0,0,0,0,0,0,0,0,0,0,0,0,0,0,0,0,0,0,0,0,0,0,0,0,0,0,0,0,0,0
endlayer

layer
0,0,0,0,0,0,0,0,0,0,0,0,0,0,0,0,0,0,0,0,0,0,0,0,0,0,0,0,0,0,0,0,0,0,0,0
0,0,0,0,0,0,0,0,0,0,0,0,0,0,0,0,0,0,0,0,0,0,0,0,0,0,0,0,0,0,0,0,0,0,0,0
0,0,0,0,0,0,0,0,0,0,0,0,0,0,0,0,0,0,0,0,0,0,0,0,0,0,0,0,0,0,0,0,0,0,0,0
0,0,0,0,0,0,0,0,0,0,0,0,0,0,0,0,0,0,0,0,0,0,0,0,0,0,0,0,0,0,0,0,0,0,0,0
0,0,0,0,0,0,0,0,0,0,0,0,0,0,0,0,31,31,31,31,31,0,0,0,0,0,0,0,0,0,0,0,0,0,0,0
0,0,0,0,0,0,0,0,0,0,0,0,0,31,31,31,0,0,0,0,0,31,31,31,14,0,0,0,0,0,0,0,0,0,0,0
0,0,0,0,0,0,0,0,0,0,0,31,31,0,0,0,0,0,0,0,0,0,14,0,0,14,14,14,0,0,0,0,0,0,0,0
0,0,0,0,0,0,0,0,0,0,31,0,0,0,0,0,0,0,0,0,0,0,0,0,0,0,14,14,14,14,0,0,0,0,0,0
0,0,0,0,0,0,0,0,0,31,0,0,0,0,0,0,0,0,0,0,0,16,0,0,0,0,0,14,14,14,0,0,0,0,0,0
0,0,0,0,0,0,0,0,31,0,0,0,0,0,0,0,0,0,0,0,0,0,0,0,0,0,0,0,31,0,0,0,0,0,0,0
0,0,0,0,0,0,0,31,0,0,0,0,0,0,0,0,0,0,0,0,0,0,0,0,0,0,0,0,14,31,0,0,0,0,0,0
0,0,0,0,0,0,0,31,0,0,0,0,0,0,0,0,0,0,0,0,0,0,0,0,0,0,0,16,0,31,0,0,0,0,0,0
0,0,0,0,0,0,31,0,0,0,0,0,0,0,0,46,46,46,0,0,0,0,0,0,0,0,0,0,0,0,31,0,0,0,0,0
0,0,0,0,0,0,31,0,0,0,0,0,0,0,46,46,46,46,46,0,0,0,0,0,0,0,0,0,0,0,31,0,0,0,0,0
0,0,0,0,0,0,31,0,0,0,0,0,0,46,46,48,48,47,0,0,0,0,0,0,0,0,0,0,0,0,31,0,0,0,0,0
0,0,0,0,0,31,0,0,0,0,0,0,46,46,47,47,47,47,48,0,0,0,0,0,0,0,0,0,0,0,0,31,0,0,0,0
0,0,0,0,0,31,0,0,0,0,0,0,46,46,48,48,47,48,47,0,0,0,0,0,0,0,0,0,0,0,0,31,0,0,0,0
0,0,0,0,0,31,0,0,0,0,0,0,46,46,47,48,47,48,48,46,46,0,0,0,0,0,0,0,0,0,0,31,0,0,0,0
0,0,0,0,0,31,0,0,0,0,0,0,0,46,46,47,48,47,46,46,0,0,0,0,0,0,0,0,0,0,0,31,0,0,0,0
0,0,0,0,0,31,0,0,0,0,0,0,0,0,46,46,46,46,46,0,0,0,0,0,0,0,0,0,0,0,0,31,0,0,0,0
0,0,0,0,0,1,31,0,0,0,0,0,0,0,0,46,46,46,0,0,0,0,0,0,0,0,0,0,0,0,31,0,0,0,0,0
0,0,0,0,0,1,31,0,0,0,0,0,0,0,0,0,0,0,0,0,0,0,0,0,0,0,0,0,0,0,31,0,0,0,0,0
0,0,0,0,0,0,31,0,0,0,0,0,0,0,0,0,0,0,0,0,0,0,0,0,0,14,0,0,0,14,31,0,0,0,0,0
0,0,0,0,0,0,1,31,0,0,0,0,0,0,0,0,0,0,0,0,0,0,0,0,0,0,0,0,14,31,14,0,0,0,0,0
0,0,0,0,0,0,0,31,0,0,14,0,0,0,0,0,0,0,0,0,0,0,0,0,0,0,0,0,0,31,0,0,0,0,0,0
0,0,0,0,0,0,0,0,31,0,0,0,0,0,0,0,0,0,0,0,0,0,0,0,0,16,16,0,31,14,0,0,0,0,0,0
0,0,0,0,0,0,0,0,14,31,0,0,0,0,0,0,0,0,0,0,0,0,0,0,0,0,0,31,0,0,0,0,0,0,0,0
0,0,0,0,0,0,0,0,0,0,31,0,0,0,0,0,0,0,0,0,0,0,0,0,0,0,31,0,0,0,0,0,0,0,0,0
0,0,0,0,0,0,0,0,0,0,14,31,31,14,14,0,0,0,0,0,0,0,0,0,31,31,0,0,0,0,0,0,0,0,0,0
0,0,0,0,0,0,0,0,0,0,14,0,16,31,31,31,0,0,0,0,0,31,31,31,0,0,0,0,0,0,0,0,0,0,0,0
0,0,0,0,0,0,0,0,0,0,0,0,0,0,0,0,31,31,31,31,31,0,0,0,0,0,0,0,0,0,0,0,0,0,0,0
0,0,0,0,0,0,0,0,0,0,0,0,0,0,0,0,0,0,0,0,0,0,0,0,0,0,0,0,0,0,0,0,0,0,0,0
0,0,0,0,0,0,0,0,0,0,0,0,0,0,0,0,0,0,0,0,0,0,0,0,0,0,0,0,0,0,0,0,0,0,0,0
0,0,0,0,0,0,0,0,0,0,0,0,0,0,0,0,0,0,0,0,0,0,0,0,0,0,0,0,0,0,0,0,0,0,0,0
0,0,0,0,0,0,0,0,0,0,0,0,0,0,0,0,0,0,0,0,0,0,0,0,0,0,0,0,0,0,0,0,0,0,0,0
0,0,0,0,0,0,0,0,0,0,0,0,0,0,0,0,0,0,0,0,0,0,0,0,0,0,0,0,0,0,0,0,0,0,0,0
0,0,0,0,0,0,0,0,0,0,0,0,0,0,0,0,0,0,0,0,0,0,0,0,0,0,0,0,0,0,0,0,0,0,0,0
0,0,0,0,0,0,0,0,0,0,0,0,0,0,0,0,0,0,0,0,0,0,0,0,0,0,0,0,0,0,0,0,0,0,0,0
endlayer

layer
0,0,0,0,0,0,0,0,0,0,0,0,0,0,0,0,0,0,0,0,0,0,0,0,0,0,0,0,0,0,0,0,0,0,0,0
0,0,0,0,0,0,0,0,0,0,0,0,0,0,0,0,0,0,0,0,0,0,0,0,0,0,0,0,0,0,0,0,0,0,0,0
0,0,0,0,0,0,0,0,0,0,0,0,0,0,0,0,0,0,0,0,0,0,0,0,0,0,0,0,0,0,0,0,0,0,0,0
0,0,0,0,0,0,0,0,0,0,0,0,0,0,0,0,0,0,0,0,0,0,0,0,0,0,0,0,0,0,0,0,0,0,0,0
0,0,0,0,0,0,0,0,0,0,0,0,0,0,0,0,0,0,0,0,0,0,0,0,0,0,0,0,0,0,0,0,0,0,0,0
0,0,0,0,0,0,0,0,0,0,0,0,0,0,0,31,31,31,31,31,31,31,0,14,14,0,0,0,0,0,0,0,0,0,0,0
0,0,0,0,0,0,0,0,0,0,0,0,31,31,31,0,0,0,0,0,0,0,31,0,0,14,0,0,0,0,0,0,0,0,0,0
0,0,0,0,0,0,0,0,0,0,0,31,0,0,0,0,0,0,0,0,0,0,14,0,0,0,0,0,0,0,0,0,0,0,0,0
0,0,0,0,0,0,0,0,0,0,31,0,0,0,0,0,0,0,0,0,0,16,0,0,0,0,0,14,0,0,0,0,0,0,0,0
0,0,0,0,0,0,0,0,0,31,0,0,0,0,0,0,0,0,0,0,0,0,0,0,0,0,0,0,14,0,0,0,0,0,0,0
0,0,0,0,0,0,0,0,31,0,0,0,0,0,0,0,0,0,0,0,0,0,0,0,0,0,0,16,31,0,0,0,0,0,0,0
0,0,0,0,0,0,0,31,0,0,0,0,0,0,0,46,46,46,0,0,0,0,0,0,0,0,0,16,0,31,0,0,0,0,0,0
0,0,0,0,0,0,0,31,0,0,0,0,0,46,46,0,0,0,46,46,0,0,0,0,0,0,0,0,0,31,0,0,0,0,0,0
0,0,0,0,0,0,0,31,0,0,0,0,46,46,47,48,48,47,48,46,46,0,0,0,0,0,0,0,0,31,0,0,0,0,0,0
0,0,0,0,0,0,31,0,0,0,0,0,46,48,48,47,47,47,48,47,46,0,0,0,0,0,0,0,0,0,31,0,0,0,0,0
0,0,0,0,0,0,31,0,0,0,0,46,0,48,48,47,48,48,48,48,0,46,0,0,0,0,0,0,0,0,31,0,0,0,0,0
0,0,0,0,0,0,31,0,0,0,0,46,0,48,48,48,48,48,47,48,0,46,0,0,0,0,0,0,0,0,31,0,0,0,0,0
0,0,0,0,0,0,31,0,0,0,0,46,0,48,48,47,48,48,48,47,0,46,0,0,0,0,0,0,0,0,31,0,0,0,0,0
0,0,0,0,0,0,31,0,0,0,0,0,46,48,47,48,48,48,48,48,46,0,0,0,0,0,0,0,0,0,31,0,0,0,0,0
0,0,0,0,0,0,31,0,0,0,0,0,46,46,48,48,48,47,47,46,46,0,0,0,0,0,0,0,0,0,31,0,0,0,0,0
0,0,0,0,0,0,31,0,0,0,0,0,0,46,46,0,0,0,46,46,0,0,0,0,0,0,0,0,0,0,31,0,0,0,0,0
0,0,0,0,0,0,1,31,0,0,0,0,0,0,0,46,46,46,0,0,0,0,0,0,0,0,0,0,0,31,0,0,0,0,0,0
0,0,0,0,0,0,1,31,0,0,0,0,0,0,0,0,0,0,0,0,0,0,0,0,0,14,0,0,14,31,0,0,0,0,0,0
0,0,0,0,0,0,0,31,0,0,0,0,0,0,0,0,0,0,0,0,0,0,0,0,0,0,14,0,14,31,14,0,0,0,0,0
0,0,0,0,0,0,0,1,31,14,14,0,0,0,0,0,0,0,0,0,0,0,0,0,0,0,0,14,31,14,14,0,0,0,0,0
0,0,0,0,0,0,0,14,14,31,0,0,0,0,0,0,0,0,0,0,0,0,0,0,0,0,14,31,0,0,0,0,0,0,0,0
0,0,0,0,0,0,0,0,0,0,31,0,0,0,0,0,0,0,0,0,0,0,0,0,0,0,31,0,0,0,0,0,0,0,0,0
0,0,0,0,0,0,0,0,0,0,0,31,14,0,0,0,0,0,0,0,0,0,0,0,0,31,0,0,0,0,0,0,0,0,0,0
0,0,0,0,0,0,0,0,0,0,0,0,14,0,0,0,0,0,0,0,0,0,31,31,31,0,0,0,0,0,0,0,0,0,0,0
0,0,0,0,0,0,0,0,0,0,0,0,16,0,14,31,31,31,31,31,31,31,0,0,0,0,0,0,0,0,0,0,0,0,0,0
0,0,0,0,0,0,0,0,0,0,0,0,0,0,0,0,0,0,0,0,0,0,0,0,0,0,0,0,0,0,0,0,0,0,0,0
0,0,0,0,0,0,0,0,0,0,0,0,0,0,0,0,0,0,0,0,0,0,0,0,0,0,0,0,0,0,0,0,0,0,0,0
0,0,0,0,0,0,0,0,0,0,0,0,0,0,0,0,0,0,0,0,0,0,0,0,0,0,0,0,0,0,0,0,0,0,0,0
0,0,0,0,0,0,0,0,0,0,0,0,0,0,0,0,0,0,0,0,0,0,0,0,0,0,0,0,0,0,0,0,0,0,0,0
0,0,0,0,0,0,0,0,0,0,0,0,0,0,0,0,0,0,0,0,0,0,0,0,0,0,0,0,0,0,0,0,0,0,0,0
0,0,0,0,0,0,0,0,0,0,0,0,0,0,0,0,0,0,0,0,0,0,0,0,0,0,0,0,0,0,0,0,0,0,0,0
0,0,0,0,0,0,0,0,0,0,0,0,0,0,0,0,0,0,0,0,0,0,0,0,0,0,0,0,0,0,0,0,0,0,0,0
0,0,0,0,0,0,0,0,0,0,0,0,0,0,0,0,0,0,0,0,0,0,0,0,0,0,0,0,0,0,0,0,0,0,0,0
endlayer

layer
0,0,0,0,0,0,0,0,0,0,0,0,0,0,0,0,0,0,0,0,0,0,0,0,0,0,0,0,0,0,0,0,0,0,0,0
0,0,0,0,0,0,0,0,0,0,0,0,0,0,0,0,0,0,0,0,0,0,0,0,0,0,0,0,0,0,0,0,0,0,0,0
0,0,0,0,0,0,0,0,0,0,0,0,0,0,0,0,0,0,0,0,0,0,0,0,0,0,0,0,0,0,0,0,0,0,0,0
0,0,0,0,0,0,0,0,0,0,0,0,0,0,0,0,0,0,0,0,0,0,0,0,0,0,0,0,0,0,0,0,0,0,0,0
0,0,0,0,0,0,0,0,0,0,0,0,0,0,0,0,0,0,0,0,0,0,0,0,0,0,0,0,0,0,0,0,0,0,0,0
0,0,0,0,0,0,0,0,0,0,0,0,0,0,0,0,0,0,0,0,0,0,0,0,0,0,0,0,0,0,0,0,0,0,0,0
0,0,0,0,0,0,0,0,0,0,0,0,0,0,31,31,31,31,31,31,31,31,31,14,14,0,0,0,0,0,0,0,0,0,0,0
0,0,0,0,0,0,0,0,0,0,0,0,31,31,0,0,0,0,0,0,0,0,14,0,0,0,0,0,0,0,0,0,0,0,0,0
0,0,0,0,0,0,0,0,0,0,0,31,0,0,0,0,0,0,0,0,0,16,0,0,0,0,0,0,0,0,0,0,0,0,0,0
0,0,0,0,0,0,0,0,0,0,31,0,0,0,0,0,0,0,0,0,0,0,0,0,0,0,0,0,0,0,0,0,0,0,0,0
0,0,0,0,0,0,0,0,0,31,0,0,0,0,0,0,0,0,0,0,0,0,0,0,0,0,0,16,14,0,0,0,0,0,0,0
0,0,0,0,0,0,0,0,31,0,0,0,0,0,46,46,46,46,46,0,0,0,0,0,0,0,0,16,31,0,0,0,0,0,0,0
0,0,0,0,0,0,0,0,31,0,0,0,46,46,48,48,48,48,48,46,46,0,0,0,0,0,0,0,31,0,0,0,0,0,0,0
0,0,0,0,0,0,0,31,0,0,0,0,46,47,47,48,48,47,47,48,46,0,0,0,0,0,0,0,0,31,0,0,0,0,0,0
0,0,0,0,0,0,0,31,0,0,0,46,48,48,47,47,48,48,48,47,48,46,0,0,0,0,0,0,0,31,0,0,0,0,0,0
0,0,0,0,0,0,0,31,0,0,0,46,48,48,48,47,47,48,48,48,48,46,0,0,0,0,0,0,0,31,0,0,0,0,0,0
0,0,0,0,0,0,0,31,0,0,0,46,48,47,47,48,48,48,48,48,48,46,0,0,0,0,0,0,0,31,0,0,0,0,0,0
0,0,0,0,0,0,0,31,0,0,0,46,47,48,48,48,47,48,48,48,47,46,0,0,0,0,0,0,0,31,0,0,0,0,0,0
0,0,0,0,0,0,0,31,0,0,0,46,48,48,48,48,48,47,48,47,48,46,0,0,0,0,0,0,0,31,0,0,0,0,0,0
0,0,0,0,0,0,0,31,0,0,0,0,46,47,48,47,47,47,48,48,46,0,0,0,0,0,0,0,0,31,0,0,0,0,0,0
0,0,0,0,0,0,0,31,0,0,0,0,46,46,48,48,48,48,47,46,46,0,0,0,0,0,0,0,0,31,0,0,0,0,0,0
0,0,0,0,0,0,0,31,0,0,0,0,0,0,46,46,46,46,46,0,0,0,0,0,0,0,0,0,14,31,0,0,0,0,0,0
0,0,0,0,0,0,0,1,31,0,0,0,0,0,0,0,0,0,0,0,0,0,0,0,0,14,14,14,31,0,0,0,0,0,0,0
0,0,0,0,0,0,0,1,31,14,14,0,0,0,0,0,0,0,0,0,0,0,0,0,0,0,14,14,31,14,14,0,0,0,0,0
0,0,0,0,0,0,0,0,0,14,14,0,0,0,0,0,0,0,0,0,0,0,0,0,0,14,14,31,14,0,0,0,0,0,0,0
0,0,0,0,0,0,0,0,0,14,31,0,0,0,0,0,0,0,0,0,0,0,0,0,0,0,31,0,0,0,0,0,0,0,0,0
0,0,0,0,0,0,0,0,0,0,0,31,14,0,0,0,0,0,0,0,0,0,0,0,0,31,0,0,0,0,0,0,0,0,0,0
0,0,0,0,0,0,0,0,0,0,0,0,0,0,0,0,0,0,0,0,0,0,0,31,31,0,0,0,0,0,0,0,0,0,0,0
0,0,0,0,0,0,0,0,0,0,0,0,14,0,0,0,0,31,31,31,31,31,31,0,0,0,0,0,0,0,0,0,0,0,0,0
0,0,0,0,0,0,0,0,0,0,0,0,0,0,0,14,14,14,0,0,0,0,0,0,0,0,0,0,0,0,0,0,0,0,0,0
0,0,0,0,0,0,0,0,0,0,0,0,0,0,0,0,0,0,0,0,0,0,0,0,0,0,0,0,0,0,0,0,0,0,0,0
0,0,0,0,0,0,0,0,0,0,0,0,0,0,0,0,0,0,0,0,0,0,0,0,0,0,0,0,0,0,0,0,0,0,0,0
0,0,0,0,0,0,0,0,0,0,0,0,0,0,0,0,0,0,0,0,0,0,0,0,0,0,0,0,0,0,0,0,0,0,0,0
0,0,0,0,0,0,0,0,0,0,0,0,0,0,0,0,0,0,0,0,0,0,0,0,0,0,0,0,0,0,0,0,0,0,0,0
0,0,0,0,0,0,0,0,0,0,0,0,0,0,0,0,0,0,0,0,0,0,0,0,0,0,0,0,0,0,0,0,0,0,0,0
0,0,0,0,0,0,0,0,0,0,0,0,0,0,0,0,0,0,0,0,0,0,0,0,0,0,0,0,0,0,0,0,0,0,0,0
0,0,0,0,0,0,0,0,0,0,0,0,0,0,0,0,0,0,0,0,0,0,0,0,0,0,0,0,0,0,0,0,0,0,0,0
0,0,0,0,0,0,0,0,0,0,0,0,0,0,0,0,0,0,0,0,0,0,0,0,0,0,0,0,0,0,0,0,0,0,0,0
endlayer

layer
0,0,0,0,0,0,0,0,0,0,0,0,0,0,0,0,0,0,0,0,0,0,0,0,0,0,0,0,0,0,0,0,0,0,0,0
0,0,0,0,0,0,0,0,0,0,0,0,0,0,0,0,0,0,0,0,0,0,0,0,0,0,0,0,0,0,0,0,0,0,0,0
0,0,0,0,0,0,0,0,0,0,0,0,0,0,0,0,0,0,0,0,0,0,0,0,0,0,0,0,0,0,0,0,0,0,0,0
0,0,0,0,0,0,0,0,0,0,0,0,0,0,0,0,0,0,0,0,0,0,0,0,0,0,0,0,0,0,0,0,0,0,0,0
0,0,0,0,0,0,0,0,0,0,0,0,0,0,0,0,0,0,0,0,0,0,0,0,0,0,0,0,0,0,0,0,0,0,0,0
0,0,0,0,0,0,0,0,0,0,0,0,0,0,0,0,0,0,0,0,0,0,0,0,0,0,0,0,0,0,0,0,0,0,0,0
0,0,0,0,0,0,0,0,0,0,0,0,0,0,0,0,0,0,0,0,0,0,0,0,0,0,0,0,0,0,0,0,0,0,0,0
0,0,0,0,0,0,0,0,0,0,0,0,0,0,31,31,31,31,31,31,31,31,14,0,0,0,0,0,0,0,0,0,0,0,0,0
0,0,0,0,0,0,0,0,0,0,0,0,31,31,31,0,0,0,0,0,14,14,14,0,0,0,0,0,0,0,0,0,0,0,0,0
0,0,0,0,0,0,0,0,0,0,18,31,31,0,0,0,0,0,0,0,0,0,0,0,0,0,0,0,0,0,0,0,0,0,0,0
0,0,0,0,0,0,0,0,0,18,31,31,0,0,0,46,46,46,0,0,0,0,0,0,0,0,0,0,0,0,0,0,0,0,0,0
0,0,0,0,0,0,0,0,18,31,31,0,0,46,46,48,48,47,46,46,0,0,0,0,0,0,0,0,0,0,0,0,0,0,0,0
0,0,0,0,0,0,0,0,18,31,0,0,46,47,48,48,47,48,48,48,46,0,0,0,0,0,0,31,0,0,0,0,0,0,0,0
0,0,0,0,0,0,0,0,31,31,0,46,48,48,48,48,48,48,48,47,47,46,0,0,0,0,0,31,31,0,0,0,0,0,0,0
0,0,0,0,0,0,0,0,31,0,0,46,48,48,47,48,48,47,47,48,47,46,0,0,0,0,0,0,31,0,0,0,0,0,0,0
0,0,0,0,0,0,0,0,31,0,46,48,47,47,48,48,47,47,48,48,48,47,46,0,0,0,0,0,31,0,0,0,0,0,0,0
0,0,0,0,0,0,0,0,31,0,46,48,47,48,48,48,48,48,48,48,48,48,46,0,0,0,0,0,31,0,0,0,0,0,0,0
0,0,0,0,0,0,0,0,31,0,46,48,48,48,48,47,47,48,47,48,48,48,46,0,0,0,0,0,31,0,0,0,0,0,0,0
0,0,0,0,0,0,0,0,31,0,0,46,47,48,48,48,48,47,48,48,48,46,0,0,0,0,0,0,31,0,0,0,0,0,0,0
0,0,0,0,0,0,0,0,31,0,0,46,47,48,48,47,48,48,48,47,48,46,0,0,0,0,0,0,31,0,0,0,0,0,0,0
0,0,0,0,0,0,0,0,31,0,0,0,46,48,48,48,48,47,48,47,46,0,0,0,0,0,0,0,31,0,0,0,0,0,0,0
0,0,0,0,0,0,0,0,31,0,0,0,0,46,46,48,47,48,46,46,0,0,0,0,0,14,0,31,31,0,0,0,0,0,0,0
0,0,0,0,0,0,0,0,0,0,0,0,0,0,0,46,46,46,0,0,0,0,0,0,0,14,14,31,14,0,0,0,0,0,0,0
0,0,0,0,0,0,0,0,0,14,0,0,0,0,0,0,0,0,0,0,0,0,0,0,0,14,31,31,14,14,0,0,0,0,0,0
0,0,0,0,0,0,0,0,0,0,0,0,0,0,0,0,0,0,0,0,0,0,0,0,0,31,31,0,14,0,0,0,0,0,0,0
0,0,0,0,0,0,0,0,0,0,14,0,0,0,0,0,0,0,0,0,0,0,0,0,31,31,0,0,0,0,0,0,0,0,0,0
0,0,0,0,0,0,0,0,0,0,0,14,0,0,0,0,0,0,0,0,0,0,31,31,31,0,0,0,0,0,0,0,0,0,0,0
0,0,0,0,0,0,0,0,0,0,0,0,0,0,0,0,0,0,31,31,31,31,31,0,0,0,0,0,0,0,0,0,0,0,0,0
0,0,0,0,0,0,0,0,0,0,0,0,0,0,0,0,0,0,0,0,0,0,0,0,0,0,0,0,0,0,0,0,0,0,0,0
0,0,0,0,0,0,0,0,0,0,0,0,0,0,0,0,0,0,0,0,0,0,0,0,0,0,0,0,0,0,0,0,0,0,0,0
0,0,0,0,0,0,0,0,0,0,0,0,0,0,0,0,0,0,0,0,0,0,0,0,0,0,0,0,0,0,0,0,0,0,0,0
0,0,0,0,0,0,0,0,0,0,0,0,0,0,0,0,0,0,0,0,0,0,0,0,0,0,0,0,0,0,0,0,0,0,0,0
0,0,0,0,0,0,0,0,0,0,0,0,0,0,0,0,0,0,0,0,0,0,0,0,0,0,0,0,0,0,0,0,0,0,0,0
0,0,0,0,0,0,0,0,0,0,0,0,0,0,0,0,0,0,0,0,0,0,0,0,0,0,0,0,0,0,0,0,0,0,0,0
0,0,0,0,0,0,0,0,0,0,0,0,0,0,0,0,0,0,0,0,0,0,0,0,0,0,0,0,0,0,0,0,0,0,0,0
0,0,0,0,0,0,0,0,0,0,0,0,0,0,0,0,0,0,0,0,0,0,0,0,0,0,0,0,0,0,0,0,0,0,0,0
0,0,0,0,0,0,0,0,0,0,0,0,0,0,0,0,0,0,0,0,0,0,0,0,0,0,0,0,0,0,0,0,0,0,0,0
0,0,0,0,0,0,0,0,0,0,0,0,0,0,0,0,0,0,0,0,0,0,0,0,0,0,0,0,0,0,0,0,0,0,0,0
endlayer

layer
0,0,0,0,0,0,0,0,0,0,0,0,0,0,0,0,0,0,0,0,0,0,0,0,0,0,0,0,0,0,0,0,0,0,0,0
0,0,0,0,0,0,0,0,0,0,0,0,0,0,0,0,0,0,0,0,0,0,0,0,0,0,0,0,0,0,0,0,0,0,0,0
0,0,0,0,0,0,0,0,0,0,0,0,0,0,0,0,0,0,0,0,0,0,0,0,0,0,0,0,0,0,0,0,0,0,0,0
0,0,0,0,0,0,0,0,0,0,0,0,0,0,0,0,0,0,0,0,0,0,0,0,0,0,0,0,0,0,0,0,0,0,0,0
0,0,0,0,0,0,0,0,0,0,0,0,0,0,0,0,0,0,0,0,0,0,0,0,0,0,0,0,0,0,0,0,0,0,0,0
0,0,0,0,0,0,0,0,0,0,0,0,0,0,0,0,0,0,0,0,0,0,0,0,0,0,0,0,0,0,0,0,0,0,0,0
0,0,0,0,0,0,0,0,0,0,0,0,0,0,0,0,0,0,0,0,0,0,0,0,0,0,0,0,0,0,0,0,0,0,0,0
0,0,0,0,0,0,0,0,0,0,0,0,0,0,0,0,0,0,0,0,0,0,0,0,0,0,0,0,0,0,0,0,0,0,0,0
0,0,0,0,0,0,0,0,0,0,0,0,0,18,1,31,31,31,31,31,31,14,0,0,0,0,0,0,0,0,0,0,0,0,0,0
0,0,0,0,0,0,0,0,0,0,0,18,18,31,31,31,0,0,0,0,0,0,0,0,0,0,0,0,0,0,0,0,0,0,0,0
0,0,0,0,0,0,0,0,0,0,18,1,31,31,46,46,46,46,46,0,0,0,0,0,0,0,0,0,0,0,0,0,0,0,0,0
0,0,0,0,0,0,0,0,0,18,18,31,46,46,48,48,48,48,48,46,46,0,0,0,0,0,0,0,0,0,0,0,0,0,0,0
0,0,0,0,0,0,0,0,0,18,31,46,0,48,48,48,48,48,48,47,0,46,0,0,0,31,31,0,0,0,0,0,0,0,0,0
0,0,0,0,0,0,0,0,0,18,31,46,47,48,48,48,48,47,48,48,48,46,0,0,0,0,31,0,0,0,0,0,0,0,0,0
0,0,0,0,0,0,0,0,0,31,46,48,48,48,47,47,48,48,47,48,48,48,46,0,0,0,31,31,0,0,0,0,0,0,0,0
0,0,0,0,0,0,0,0,0,31,46,48,48,48,47,48,47,48,47,47,47,48,46,0,0,0,0,31,0,0,0,0,0,0,0,0
0,0,0,0,0,0,0,0,0,31,46,48,48,48,48,48,48,48,47,47,48,48,46,0,0,0,0,31,0,0,0,0,0,0,0,0
0,0,0,0,0,0,0,0,0,31,46,47,48,48,48,48,48,48,48,48,48,48,46,0,0,0,0,31,0,0,0,0,0,0,0,0
0,0,0,0,0,0,0,0,0,31,46,47,48,48,48,48,48,48,48,48,48,48,46,0,0,0,0,31,0,0,0,0,0,0,0,0
0,0,0,0,0,0,0,0,0,31,0,46,47,48,48,48,47,48,48,48,48,46,0,0,0,0,0,31,0,0,0,0,0,0,0,0
0,0,0,0,0,0,0,0,0,0,0,46,0,48,48,48,48,47,48,48,0,46,0,0,0,0,0,0,0,0,0,0,0,0,0,0
0,0,0,0,0,0,0,0,0,0,0,0,46,46,48,48,47,47,48,46,46,0,0,0,0,0,0,14,0,0,0,0,0,0,0,0
0,0,0,0,0,0,0,0,0,0,0,0,0,0,46,46,46,46,46,0,0,0,0,0,0,14,14,14,0,0,0,0,0,0,0,0
0,0,0,0,0,0,0,0,0,0,0,0,0,0,0,0,0,0,0,0,0,0,0,0,31,0,0,14,0,0,0,0,0,0,0,0
0,0,0,0,0,0,0,0,0,0,0,0,0,0,0,0,0,0,0,0,0,0,0,31,31,0,0,0,14,0,0,0,0,0,0,0
0,0,0,0,0,0,0,0,0,0,0,0,0,0,0,0,0,0,0,0,0,31,31,31,0,0,0,0,0,0,0,0,0,0,0,0
0,0,0,0,0,0,0,0,0,0,0,0,0,0,0,0,0,0,31,31,31,31,0,0,0,0,0,0,0,0,0,0,0,0,0,0
0,0,0,0,0,0,0,0,0,0,0,0,0,0,0,0,0,0,0,0,0,0,0,0,0,0,0,0,0,0,0,0,0,0,0,0
0,0,0,0,0,0,0,0,0,0,0,0,0,0,0,0,0,0,0,0,0,0,0,0,0,0,0,0,0,0,0,0,0,0,0,0
0,0,0,0,0,0,0,0,0,0,0,0,0,0,0,0,0,0,0,0,0,0,0,0,0,0,0,0,0,0,0,0,0,0,0,0
0,0,0,0,0,0,0,0,0,0,0,0,0,0,0,0,0,0,0,0,0,0,0,0,0,0,0,0,0,0,0,0,0,0,0,0
0,0,0,0,0,0,0,0,0,0,0,0,0,0,0,0,0,0,0,0,0,0,0,0,0,0,0,0,0,0,0,0,0,0,0,0
0,0,0,0,0,0,0,0,0,0,0,0,0,0,0,0,0,0,0,0,0,0,0,0,0,0,0,0,0,0,0,0,0,0,0,0
0,0,0,0,0,0,0,0,0,0,0,0,0,0,0,0,0,0,0,0,0,0,0,0,0,0,0,0,0,0,0,0,0,0,0,0
0,0,0,0,0,0,0,0,0,0,0,0,0,0,0,0,0,0,0,0,0,0,0,0,0,0,0,0,0,0,0,0,0,0,0,0
0,0,0,0,0,0,0,0,0,0,0,0,0,0,0,0,0,0,0,0,0,0,0,0,0,0,0,0,0,0,0,0,0,0,0,0
0,0,0,0,0,0,0,0,0,0,0,0,0,0,0,0,0,0,0,0,0,0,0,0,0,0,0,0,0,0,0,0,0,0,0,0
0,0,0,0,0,0,0,0,0,0,0,0,0,0,0,0,0,0,0,0,0,0,0,0,0,0,0,0,0,0,0,0,0,0,0,0
endlayer

layer
0,0,0,0,0,0,0,0,0,0,0,0,0,0,0,0,0,0,0,0,0,0,0,0,0,0,0,0,0,0,0,0,0,0,0,0
0,0,0,0,0,0,0,0,0,0,0,0,0,0,0,0,0,0,0,0,0,0,0,0,0,0,0,0,0,0,0,0,0,0,0,0
0,0,0,0,0,0,0,0,0,0,0,0,0,0,0,0,0,0,0,0,0,0,0,0,0,0,0,0,0,0,0,0,0,0,0,0
0,0,0,0,0,0,0,0,0,0,0,0,0,0,0,0,0,0,0,0,0,0,0,0,0,0,0,0,0,0,0,0,0,0,0,0
0,0,0,0,0,0,0,0,0,0,0,0,0,0,0,0,0,0,0,0,0,0,0,0,0,0,0,0,0,0,0,0,0,0,0,0
0,0,0,0,0,0,0,0,0,0,0,0,0,0,0,0,0,0,0,0,0,0,0,0,0,0,0,0,0,0,0,0,0,0,0,0
0,0,0,0,0,0,0,0,0,0,0,0,0,0,0,0,0,0,0,0,0,0,0,0,0,0,0,0,0,0,0,0,0,0,0,0
0,0,0,0,0,0,0,0,0,0,0,0,0,0,0,0,0,0,0,0,0,0,0,0,0,0,0,0,0,0,0,0,0,0,0,0
0,0,0,0,0,0,0,0,0,0,0,0,0,0,0,1,1,0,0,0,0,0,0,0,0,0,0,0,0,0,0,0,0,0,0,0
0,0,0,0,0,0,0,0,0,0,0,0,0,1,1,1,31,31,31,31,0,0,0,0,0,0,0,0,0,0,0,0,0,0,0,0
0,0,0,0,0,0,0,0,0,0,0,0,1,1,46,46,46,46,46,31,0,0,0,0,0,0,0,0,0,0,0,0,0,0,0,0
0,0,0,0,0,0,0,0,0,0,0,1,46,46,48,48,47,48,48,46,46,0,0,0,0,0,0,0,0,0,0,0,0,0,0,0
0,0,0,0,0,0,0,0,0,0,18,46,31,47,48,48,48,47,48,48,0,46,0,0,0,0,0,0,0,0,0,0,0,0,0,0
0,0,0,0,0,0,0,0,0,0,18,46,48,48,47,48,47,47,48,48,48,46,0,0,0,31,0,0,0,0,0,0,0,0,0,0
0,0,0,0,0,0,0,0,0,0,46,48,47,48,48,48,48,48,48,48,47,48,46,0,0,31,0,0,0,0,0,0,0,0,0,0
0,0,0,0,0,0,0,0,0,0,46,48,47,48,48,48,48,48,47,48,48,47,46,0,0,31,31,0,0,0,0,0,0,0,0,0
0,0,0,0,0,0,0,0,0,0,46,48,48,48,48,47,47,48,48,47,48,47,46,0,0,31,31,0,0,0,0,0,0,0,0,0
0,0,0,0,0,0,0,0,0,0,46,48,48,48,47,48,47,48,47,48,48,48,46,0,0,0,31,0,0,0,0,0,0,0,0,0
0,0,0,0,0,0,0,0,0,0,46,48,48,47,47,48,48,47,48,47,48,48,46,0,0,0,0,0,0,0,0,0,0,0,0,0
0,0,0,0,0,0,0,0,0,0,31,46,48,48,48,48,48,47,48,47,48,46,0,0,0,0,0,0,0,0,0,0,0,0,0,0
0,0,0,0,0,0,0,0,0,0,31,46,0,48,47,48,48,48,48,48,0,46,0,0,0,0,0,0,0,0,0,0,0,0,0,0
0,0,0,0,0,0,0,0,0,0,0,0,46,46,48,48,48,48,48,46,46,0,0,0,0,0,0,0,0,0,0,0,0,0,0,0
0,0,0,0,0,0,0,0,0,0,0,0,0,0,46,46,46,46,46,0,0,0,0,0,0,0,0,0,0,0,0,0,0,0,0,0
0,0,0,0,0,0,0,0,0,0,0,0,0,0,0,0,0,0,0,0,0,0,0,0,0,0,0,0,0,0,0,0,0,0,0,0
0,0,0,0,0,0,0,0,0,0,0,0,0,0,0,0,0,31,31,31,31,31,31,0,0,0,0,0,0,0,0,0,0,0,0,0
0,0,0,0,0,0,0,0,0,0,0,0,0,0,0,0,0,0,31,31,31,0,0,0,0,0,0,0,0,0,0,0,0,0,0,0
0,0,0,0,0,0,0,0,0,0,0,0,0,0,0,0,0,0,0,0,0,0,0,0,0,0,0,0,0,0,0,0,0,0,0,0
0,0,0,0,0,0,0,0,0,0,0,0,0,0,0,0,0,0,0,0,0,0,0,0,0,0,0,0,0,0,0,0,0,0,0,0
0,0,0,0,0,0,0,0,0,0,0,0,0,0,0,0,0,0,0,0,0,0,0,0,0,0,0,0,0,0,0,0,0,0,0,0
0,0,0,0,0,0,0,0,0,0,0,0,0,0,0,0,0,0,0,0,0,0,0,0,0,0,0,0,0,0,0,0,0,0,0,0
0,0,0,0,0,0,0,0,0,0,0,0,0,0,0,0,0,0,0,0,0,0,0,0,0,0,0,0,0,0,0,0,0,0,0,0
0,0,0,0,0,0,0,0,0,0,0,0,0,0,0,0,0,0,0,0,0,0,0,0,0,0,0,0,0,0,0,0,0,0,0,0
0,0,0,0,0,0,0,0,0,0,0,0,0,0,0,0,0,0,0,0,0,0,0,0,0,0,0,0,0,0,0,0,0,0,0,0
0,0,0,0,0,0,0,0,0,0,0,0,0,0,0,0,0,0,0,0,0,0,0,0,0,0,0,0,0,0,0,0,0,0,0,0
0,0,0,0,0,0,0,0,0,0,0,0,0,0,0,0,0,0,0,0,0,0,0,0,0,0,0,0,0,0,0,0,0,0,0,0
0,0,0,0,0,0,0,0,0,0,0,0,0,0,0,0,0,0,0,0,0,0,0,0,0,0,0,0,0,0,0,0,0,0,0,0
0,0,0,0,0,0,0,0,0,0,0,0,0,0,0,0,0,0,0,0,0,0,0,0,0,0,0,0,0,0,0,0,0,0,0,0
0,0,0,0,0,0,0,0,0,0,0,0,0,0,0,0,0,0,0,0,0,0,0,0,0,0,0,0,0,0,0,0,0,0,0,0
endlayer

layer
0,0,0,0,0,0,0,0,0,0,0,0,0,0,0,0,0,0,0,0,0,0,0,0,0,0,0,0,0,0,0,0,0,0,0,0
0,0,0,0,0,0,0,0,0,0,0,0,0,0,0,0,0,0,0,0,0,0,0,0,0,0,0,0,0,0,0,0,0,0,0,0
0,0,0,0,0,0,0,0,0,0,0,0,0,0,0,0,0,0,0,0,0,0,0,0,0,0,0,0,0,0,0,0,0,0,0,0
0,0,0,0,0,0,0,0,0,0,0,0,0,0,0,0,0,0,0,0,0,0,0,0,0,0,0,0,0,0,0,0,0,0,0,0
0,0,0,0,0,0,0,0,0,0,0,0,0,0,0,0,0,0,0,0,0,0,0,0,0,0,0,0,0,0,0,0,0,0,0,0
0,0,0,0,0,0,0,0,0,0,0,0,0,0,0,0,0,0,0,0,0,0,0,0,0,0,0,0,0,0,0,0,0,0,0,0
0,0,0,0,0,0,0,0,0,0,0,0,0,0,0,0,0,0,0,0,0,0,0,0,0,0,0,0,0,0,0,0,0,0,0,0
0,0,0,0,0,0,0,0,0,0,0,0,0,0,0,0,0,0,0,0,0,0,0,0,0,0,0,0,0,0,0,0,0,0,0,0
0,0,0,0,0,0,0,0,0,0,0,0,0,0,0,0,0,0,0,0,0,0,0,0,0,0,0,0,0,0,0,0,0,0,0,0
0,0,0,0,0,0,0,0,0,0,0,0,0,0,0,0,0,0,0,0,0,0,0,0,0,0,0,0,0,0,0,0,0,0,0,0
0,0,0,0,0,0,0,0,0,0,0,0,0,0,46,46,46,46,46,0,0,0,0,0,0,0,0,0,0,0,0,0,0,0,0,0
0,0,0,0,0,0,0,0,0,0,0,0,46,46,48,48,48,48,48,46,46,0,0,0,0,0,0,0,0,0,0,0,0,0,0,0
0,0,0,0,0,0,0,0,0,0,0,46,0,48,48,48,48,47,48,47,0,46,0,0,0,0,0,0,0,0,0,0,0,0,0,0
0,0,0,0,0,0,0,0,0,0,0,46,48,47,48,47,48,48,48,48,48,46,0,0,0,0,0,0,0,0,0,0,0,0,0,0
0,0,0,0,0,0,0,0,0,0,46,48,48,48,48,47,48,47,48,47,48,48,46,31,31,0,0,0,0,0,0,0,0,0,0,0
0,0,0,0,0,0,0,0,0,0,46,47,47,48,47,48,48,47,48,48,47,47,46,31,31,0,0,0,0,0,0,0,0,0,0,0
0,0,0,0,0,0,0,0,0,0,46,48,48,48,48,48,48,48,48,48,48,47,46,31,31,0,0,0,0,0,0,0,0,0,0,0
0,0,0,0,0,0,0,0,0,0,46,47,48,48,48,48,47,48,47,48,48,48,46,31,31,0,0,0,0,0,0,0,0,0,0,0
0,0,0,0,0,0,0,0,0,0,46,48,47,48,48,48,48,47,47,48,48,47,46,0,0,0,0,0,0,0,0,0,0,0,0,0
0,0,0,0,0,0,0,0,0,0,0,46,48,47,48,48,48,48,48,48,47,46,0,0,0,0,0,0,0,0,0,0,0,0,0,0
0,0,0,0,0,0,0,0,0,0,0,46,0,48,48,48,48,48,48,48,0,46,0,0,0,0,0,0,0,0,0,0,0,0,0,0
0,0,0,0,0,0,0,0,0,0,0,0,46,46,47,48,47,48,47,46,46,0,0,0,0,0,0,0,0,0,0,0,0,0,0,0
0,0,0,0,0,0,0,0,0,0,0,0,0,0,46,46,46,46,46,31,31,31,0,0,0,0,0,0,0,0,0,0,0,0,0,0
0,0,0,0,0,0,0,0,0,0,0,0,0,0,0,0,0,0,31,31,31,31,0,0,0,0,0,0,0,0,0,0,0,0,0,0
0,0,0,0,0,0,0,0,0,0,0,0,0,0,0,0,0,0,0,0,0,0,0,0,0,0,0,0,0,0,0,0,0,0,0,0
0,0,0,0,0,0,0,0,0,0,0,0,0,0,0,0,0,0,0,0,0,0,0,0,0,0,0,0,0,0,0,0,0,0,0,0
0,0,0,0,0,0,0,0,0,0,0,0,0,0,0,0,0,0,0,0,0,0,0,0,0,0,0,0,0,0,0,0,0,0,0,0
0,0,0,0,0,0,0,0,0,0,0,0,0,0,0,0,0,0,0,0,0,0,0,0,0,0,0,0,0,0,0,0,0,0,0,0
0,0,0,0,0,0,0,0,0,0,0,0,0,0,0,0,0,0,0,0,0,0,0,0,0,0,0,0,0,0,0,0,0,0,0,0
0,0,0,0,0,0,0,0,0,0,0,0,0,0,0,0,0,0,0,0,0,0,0,0,0,0,0,0,0,0,0,0,0,0,0,0
0,0,0,0,0,0,0,0,0,0,0,0,0,0,0,0,0,0,0,0,0,0,0,0,0,0,0,0,0,0,0,0,0,0,0,0
0,0,0,0,0,0,0,0,0,0,0,0,0,0,0,0,0,0,0,0,0,0,0,0,0,0,0,0,0,0,0,0,0,0,0,0
0,0,0,0,0,0,0,0,0,0,0,0,0,0,0,0,0,0,0,0,0,0,0,0,0,0,0,0,0,0,0,0,0,0,0,0
0,0,0,0,0,0,0,0,0,0,0,0,0,0,0,0,0,0,0,0,0,0,0,0,0,0,0,0,0,0,0,0,0,0,0,0
0,0,0,0,0,0,0,0,0,0,0,0,0,0,0,0,0,0,0,0,0,0,0,0,0,0,0,0,0,0,0,0,0,0,0,0
0,0,0,0,0,0,0,0,0,0,0,0,0,0,0,0,0,0,0,0,0,0,0,0,0,0,0,0,0,0,0,0,0,0,0,0
0,0,0,0,0,0,0,0,0,0,0,0,0,0,0,0,0,0,0,0,0,0,0,0,0,0,0,0,0,0,0,0,0,0,0,0
0,0,0,0,0,0,0,0,0,0,0,0,0,0,0,0,0,0,0,0,0,0,0,0,0,0,0,0,0,0,0,0,0,0,0,0
endlayer

layer
0,0,0,0,0,0,0,0,0,0,0,0,0,0,0,0,0,0,0,0,0,0,0,0,0,0,0,0,0,0,0,0,0,0,0,0
0,0,0,0,0,0,0,0,0,0,0,0,0,0,0,0,0,0,0,0,0,0,0,0,0,0,0,0,0,0,0,0,0,0,0,0
0,0,0,0,0,0,0,0,0,0,0,0,0,0,0,0,0,0,0,0,0,0,0,0,0,0,0,0,0,0,0,0,0,0,0,0
0,0,0,0,0,0,0,0,0,0,0,0,0,0,0,0,0,0,0,0,0,0,0,0,0,0,0,0,0,0,0,0,0,0,0,0
0,0,0,0,0,0,0,0,0,0,0,0,0,0,0,0,0,0,0,0,0,0,0,0,0,0,0,0,0,0,0,0,0,0,0,0
0,0,0,0,0,0,0,0,0,0,0,0,0,0,0,0,0,0,0,0,0,0,0,0,0,0,0,0,0,0,0,0,0,0,0,0
0,0,0,0,0,0,0,0,0,0,0,0,0,0,0,0,0,0,0,0,0,0,0,0,0,0,0,0,0,0,0,0,0,0,0,0
0,0,0,0,0,0,0,0,0,0,0,0,0,0,0,0,0,0,0,0,0,0,0,0,0,0,0,0,0,0,0,0,0,0,0,0
0,0,0,0,0,0,0,0,0,0,0,0,0,0,0,0,0,0,0,0,0,0,0,0,0,0,0,0,0,0,0,0,0,0,0,0
0,0,0,0,0,0,0,0,0,0,0,0,0,0,0,0,0,0,0,0,0,0,0,0,0,0,0,0,0,0,0,0,0,0,0,0
0,0,0,0,0,0,0,0,0,0,0,0,0,0,0,46,46,46,0,0,0,0,0,0,0,0,0,0,0,0,0,0,0,0,0,0
0,0,0,0,0,0,0,0,0,0,0,0,0,46,46,48,47,48,46,46,0,0,0,0,0,0,0,0,0,0,0,0,0,0,0,0
0,0,0,0,0,0,0,0,0,0,0,0,46,47,47,48,48,48,48,48,46,0,0,0,0,0,0,0,0,0,0,0,0,0,0,0
0,0,0,0,0,0,0,0,0,0,0,46,47,48,47,48,48,48,48,48,48,46,0,0,0,0,0,0,0,0,0,0,0,0,0,0
0,0,0,0,0,0,0,0,0,0,0,46,47,47,47,47,48,47,48,48,47,46,0,0,0,0,0,0,0,0,0,0,0,0,0,0
0,0,0,0,0,0,0,0,0,0,46,47,48,47,48,48,48,48,48,48,48,48,46,0,0,0,0,0,0,0,0,0,0,0,0,0
0,0,0,0,0,0,0,0,0,0,46,48,48,48,47,48,48,47,48,47,48,48,46,0,0,0,0,0,0,0,0,0,0,0,0,0
0,0,0,0,0,0,0,0,0,0,46,48,47,48,47,47,48,48,48,47,48,48,46,0,0,0,0,0,0,0,0,0,0,0,0,0
0,0,0,0,0,0,0,0,0,0,0,46,48,48,47,47,48,48,48,48,48,46,0,0,0,0,0,0,0,0,0,0,0,0,0,0
0,0,0,0,0,0,0,0,0,0,0,46,48,47,47,48,47,48,48,48,48,46,0,0,0,0,0,0,0,0,0,0,0,0,0,0
0,0,0,0,0,0,0,0,0,0,0,0,46,48,48,48,48,47,47,48,46,0,0,0,0,0,0,0,0,0,0,0,0,0,0,0
0,0,0,0,0,0,0,0,0,0,0,0,0,46,46,47,48,48,46,46,0,0,0,0,0,0,0,0,0,0,0,0,0,0,0,0
0,0,0,0,0,0,0,0,0,0,0,0,0,0,0,46,46,46,0,0,0,0,0,0,0,0,0,0,0,0,0,0,0,0,0,0
0,0,0,0,0,0,0,0,0,0,0,0,0,0,0,0,0,0,0,0,0,0,0,0,0,0,0,0,0,0,0,0,0,0,0,0
0,0,0,0,0,0,0,0,0,0,0,0,0,0,0,0,0,0,0,0,0,0,0,0,0,0,0,0,0,0,0,0,0,0,0,0
0,0,0,0,0,0,0,0,0,0,0,0,0,0,0,0,0,0,0,0,0,0,0,0,0,0,0,0,0,0,0,0,0,0,0,0
0,0,0,0,0,0,0,0,0,0,0,0,0,0,0,0,0,0,0,0,0,0,0,0,0,0,0,0,0,0,0,0,0,0,0,0
0,0,0,0,0,0,0,0,0,0,0,0,0,0,0,0,0,0,0,0,0,0,0,0,0,0,0,0,0,0,0,0,0,0,0,0
0,0,0,0,0,0,0,0,0,0,0,0,0,0,0,0,0,0,0,0,0,0,0,0,0,0,0,0,0,0,0,0,0,0,0,0
0,0,0,0,0,0,0,0,0,0,0,0,0,0,0,0,0,0,0,0,0,0,0,0,0,0,0,0,0,0,0,0,0,0,0,0
0,0,0,0,0,0,0,0,0,0,0,0,0,0,0,0,0,0,0,0,0,0,0,0,0,0,0,0,0,0,0,0,0,0,0,0
0,0,0,0,0,0,0,0,0,0,0,0,0,0,0,0,0,0,0,0,0,0,0,0,0,0,0,0,0,0,0,0,0,0,0,0
0,0,0,0,0,0,0,0,0,0,0,0,0,0,0,0,0,0,0,0,0,0,0,0,0,0,0,0,0,0,0,0,0,0,0,0
0,0,0,0,0,0,0,0,0,0,0,0,0,0,0,0,0,0,0,0,0,0,0,0,0,0,0,0,0,0,0,0,0,0,0,0
0,0,0,0,0,0,0,0,0,0,0,0,0,0,0,0,0,0,0,0,0,0,0,0,0,0,0,0,0,0,0,0,0,0,0,0
0,0,0,0,0,0,0,0,0,0,0,0,0,0,0,0,0,0,0,0,0,0,0,0,0,0,0,0,0,0,0,0,0,0,0,0
0,0,0,0,0,0,0,0,0,0,0,0,0,0,0,0,0,0,0,0,0,0,0,0,0,0,0,0,0,0,0,0,0,0,0,0
0,0,0,0,0,0,0,0,0,0,0,0,0,0,0,0,0,0,0,0,0,0,0,0,0,0,0,0,0,0,0,0,0,0,0,0
endlayer

layer
0,0,0,0,0,0,0,0,0,0,0,0,0,0,0,0,0,0,0,0,0,0,0,0,0,0,0,0,0,0,0,0,0,0,0,0
0,0,0,0,0,0,0,0,0,0,0,0,0,0,0,0,0,0,0,0,0,0,0,0,0,0,0,0,0,0,0,0,0,0,0,0
0,0,0,0,0,0,0,0,0,0,0,0,0,0,0,0,0,0,0,0,0,0,0,0,0,0,0,0,0,0,0,0,0,0,0,0
0,0,0,0,0,0,0,0,0,0,0,0,0,0,0,0,0,0,0,0,0,0,0,0,0,0,0,0,0,0,0,0,0,0,0,0
0,0,0,0,0,0,0,0,0,0,0,0,0,0,0,0,0,0,0,0,0,0,0,0,0,0,0,0,0,0,0,0,0,0,0,0
0,0,0,0,0,0,0,0,0,0,0,0,0,0,0,0,0,0,0,0,0,0,0,0,0,0,0,0,0,0,0,0,0,0,0,0
0,0,0,0,0,0,0,0,0,0,0,0,0,0,0,0,0,0,0,0,0,0,0,0,0,0,0,0,0,0,0,0,0,0,0,0
0,0,0,0,0,0,0,0,0,0,0,0,0,0,0,0,0,0,0,0,0,0,0,0,0,0,0,0,0,0,0,0,0,0,0,0
0,0,0,0,0,0,0,0,0,0,0,0,0,0,0,0,0,0,0,0,0,0,0,0,0,0,0,0,0,0,0,0,0,0,0,0
0,0,0,0,0,0,0,0,0,0,0,0,0,0,0,0,0,0,0,0,0,0,0,0,0,0,0,0,0,0,0,0,0,0,0,0
0,0,0,0,0,0,0,0,0,0,0,0,0,0,0,0,0,0,0,0,0,0,0,0,0,0,0,0,0,0,0,0,0,0,0,0
0,0,0,0,0,0,0,0,0,0,0,0,0,0,46,46,46,46,46,0,0,0,0,0,0,0,0,0,0,0,0,0,0,0,0,0
0,0,0,0,0,0,0,0,0,0,0,0,46,46,48,48,47,48,48,46,46,0,0,0,0,0,0,0,0,0,0,0,0,0,0,0
0,0,0,0,0,0,0,0,0,0,0,0,46,47,48,48,48,48,48,48,46,0,0,0,0,0,0,0,0,0,0,0,0,0,0,0
0,0,0,0,0,0,0,0,0,0,0,46,48,48,48,48,47,48,47,48,47,46,0,0,0,0,0,0,0,0,0,0,0,0,0,0
0,0,0,0,0,0,0,0,0,0,0,46,47,48,47,48,48,48,48,48,48,46,0,0,0,0,0,0,0,0,0,0,0,0,0,0
0,0,0,0,0,0,0,0,0,0,0,46,48,48,47,48,48,48,47,48,48,46,0,0,0,0,0,0,0,0,0,0,0,0,0,0
0,0,0,0,0,0,0,0,0,0,0,46,48,48,48,48,48,48,48,47,48,46,0,0,0,0,0,0,0,0,0,0,0,0,0,0
0,0,0,0,0,0,0,0,0,0,0,46,48,47,48,48,47,48,48,47,48,46,0,0,0,0,0,0,0,0,0,0,0,0,0,0
0,0,0,0,0,0,0,0,0,0,0,0,46,48,48,48,48,48,48,47,46,0,0,0,0,0,0,0,0,0,0,0,0,0,0,0
0,0,0,0,0,0,0,0,0,0,0,0,46,46,48,47,48,48,47,46,46,0,0,0,0,0,0,0,0,0,0,0,0,0,0,0
0,0,0,0,0,0,0,0,0,0,0,0,0,0,46,46,46,46,46,0,0,0,0,0,0,0,0,0,0,0,0,0,0,0,0,0
0,0,0,0,0,0,0,0,0,0,0,0,0,0,0,0,0,0,0,0,0,0,0,0,0,0,0,0,0,0,0,0,0,0,0,0
0,0,0,0,0,0,0,0,0,0,0,0,0,0,0,0,0,0,0,0,0,0,0,0,0,0,0,0,0,0,0,0,0,0,0,0
0,0,0,0,0,0,0,0,0,0,0,0,0,0,0,0,0,0,0,0,0,0,0,0,0,0,0,0,0,0,0,0,0,0,0,0
0,0,0,0,0,0,0,0,0,0,0,0,0,0,0,0,0,0,0,0,0,0,0,0,0,0,0,0,0,0,0,0,0,0,0,0
0,0,0,0,0,0,0,0,0,0,0,0,0,0,0,0,0,0,0,0,0,0,0,0,0,0,0,0,0,0,0,0,0,0,0,0
0,0,0,0,0,0,0,0,0,0,0,0,0,0,0,0,0,0,0,0,0,0,0,0,0,0,0,0,0,0,0,0,0,0,0,0
0,0,0,0,0,0,0,0,0,0,0,0,0,0,0,0,0,0,0,0,0,0,0,0,0,0,0,0,0,0,0,0,0,0,0,0
0,0,0,0,0,0,0,0,0,0,0,0,0,0,0,0,0,0,0,0,0,0,0,0,0,0,0,0,0,0,0,0,0,0,0,0
0,0,0,0,0,0,0,0,0,0,0,0,0,0,0,0,0,0,0,0,0,0,0,0,0,0,0,0,0,0,0,0,0,0,0,0
0,0,0,0,0,0,0,0,0,0,0,0,0,0,0,0,0,0,0,0,0,0,0,0,0,0,0,0,0,0,0,0,0,0,0,0
0,0,0,0,0,0,0,0,0,0,0,0,0,0,0,0,0,0,0,0,0,0,0,0,0,0,0,0,0,0,0,0,0,0,0,0
0,0,0,0,0,0,0,0,0,0,0,0,0,0,0,0,0,0,0,0,0,0,0,0,0,0,0,0,0,0,0,0,0,0,0,0
0,0,0,0,0,0,0,0,0,0,0,0,0,0,0,0,0,0,0,0,0,0,0,0,0,0,0,0,0,0,0,0,0,0,0,0
0,0,0,0,0,0,0,0,0,0,0,0,0,0,0,0,0,0,0,0,0,0,0,0,0,0,0,0,0,0,0,0,0,0,0,0
0,0,0,0,0,0,0,0,0,0,0,0,0,0,0,0,0,0,0,0,0,0,0,0,0,0,0,0,0,0,0,0,0,0,0,0
0,0,0,0,0,0,0,0,0,0,0,0,0,0,0,0,0,0,0,0,0,0,0,0,0,0,0,0,0,0,0,0,0,0,0,0
endlayer

layer
0,0,0,0,0,0,0,0,0,0,0,0,0,0,0,0,0,0,0,0,0,0,0,0,0,0,0,0,0,0,0,0,0,0,0,0
0,0,0,0,0,0,0,0,0,0,0,0,0,0,0,0,0,0,0,0,0,0,0,0,0,0,0,0,0,0,0,0,0,0,0,0
0,0,0,0,0,0,0,0,0,0,0,0,0,0,0,0,0,0,0,0,0,0,0,0,0,0,0,0,0,0,0,0,0,0,0,0
0,0,0,0,0,0,0,0,0,0,0,0,0,0,0,0,0,0,0,0,0,0,0,0,0,0,0,0,0,0,0,0,0,0,0,0
0,0,0,0,0,0,0,0,0,0,0,0,0,0,0,0,0,0,0,0,0,0,0,0,0,0,0,0,0,0,0,0,0,0,0,0
0,0,0,0,0,0,0,0,0,0,0,0,0,0,0,0,0,0,0,0,0,0,0,0,0,0,0,0,0,0,0,0,0,0,0,0
0,0,0,0,0,0,0,0,0,0,0,0,0,0,0,0,0,0,0,0,0,0,0,0,0,0,0,0,0,0,0,0,0,0,0,0
0,0,0,0,0,0,0,0,0,0,0,0,0,0,0,0,0,0,0,0,0,0,0,0,0,0,0,0,0,0,0,0,0,0,0,0
0,0,0,0,0,0,0,0,0,0,0,0,0,0,0,0,0,0,0,0,0,0,0,0,0,0,0,0,0,0,0,0,0,0,0,0
0,0,0,0,0,0,0,0,0,0,0,0,0,0,0,0,0,0,0,0,0,0,0,0,0,0,0,0,0,0,0,0,0,0,0,0
0,0,0,0,0,0,0,0,0,0,0,0,0,0,0,0,0,0,0,0,0,0,0,0,0,0,0,0,0,0,0,0,0,0,0,0
0,0,0,0,0,0,0,0,0,0,0,0,0,0,0,46,46,46,0,0,0,0,0,0,0,0,0,0,0,0,0,0,0,0,0,0
0,0,0,0,0,0,0,0,0,0,0,0,0,46,46,0,0,0,46,46,0,0,0,0,0,0,0,0,0,0,0,0,0,0,0,0
0,0,0,0,0,0,0,0,0,0,0,0,46,46,48,48,48,48,48,46,46,0,0,0,0,0,0,0,0,0,0,0,0,0,0,0
0,0,0,0,0,0,0,0,0,0,0,0,46,48,48,47,48,48,48,47,46,0,0,0,0,0,0,0,0,0,0,0,0,0,0,0
0,0,0,0,0,0,0,0,0,0,0,46,0,47,47,48,48,48,47,48,0,46,0,0,0,0,0,0,0,0,0,0,0,0,0,0
0,0,0,0,0,0,0,0,0,0,0,46,0,48,48,48,48,48,48,47,0,46,0,0,0,0,0,0,0,0,0,0,0,0,0,0
0,0,0,0,0,0,0,0,0,0,0,46,0,48,48,48,47,47,47,48,0,46,0,0,0,0,0,0,0,0,0,0,0,0,0,0
0,0,0,0,0,0,0,0,0,0,0,0,46,47,47,47,48,47,48,47,46,0,0,0,0,0,0,0,0,0,0,0,0,0,0,0
0,0,0,0,0,0,0,0,0,0,0,0,46,46,48,48,47,47,48,46,46,0,0,0,0,0,0,0,0,0,0,0,0,0,0,0
0,0,0,0,0,0,0,0,0,0,0,0,0,46,46,0,0,0,46,46,0,0,0,0,0,0,0,0,0,0,0,0,0,0,0,0
0,0,0,0,0,0,0,0,0,0,0,0,0,0,0,46,46,46,0,0,0,0,0,0,0,0,0,0,0,0,0,0,0,0,0,0
0,0,0,0,0,0,0,0,0,0,0,0,0,0,0,0,0,0,0,0,0,0,0,0,0,0,0,0,0,0,0,0,0,0,0,0
0,0,0,0,0,0,0,0,0,0,0,0,0,0,0,0,0,0,0,0,0,0,0,0,0,0,0,0,0,0,0,0,0,0,0,0
0,0,0,0,0,0,0,0,0,0,0,0,0,0,0,0,0,0,0,0,0,0,0,0,0,0,0,0,0,0,0,0,0,0,0,0
0,0,0,0,0,0,0,0,0,0,0,0,0,0,0,0,0,0,0,0,0,0,0,0,0,0,0,0,0,0,0,0,0,0,0,0
0,0,0,0,0,0,0,0,0,0,0,0,0,0,0,0,0,0,0,0,0,0,0,0,0,0,0,0,0,0,0,0,0,0,0,0
0,0,0,0,0,0,0,0,0,0,0,0,0,0,0,0,0,0,0,0,0,0,0,0,0,0,0,0,0,0,0,0,0,0,0,0
0,0,0,0,0,0,0,0,0,0,0,0,0,0,0,0,0,0,0,0,0,0,0,0,0,0,0,0,0,0,0,0,0,0,0,0
0,0,0,0,0,0,0,0,0,0,0,0,0,0,0,0,0,0,0,0,0,0,0,0,0,0,0,0,0,0,0,0,0,0,0,0
0,0,0,0,0,0,0,0,0,0,0,0,0,0,0,0,0,0,0,0,0,0,0,0,0,0,0,0,0,0,0,0,0,0,0,0
0,0,0,0,0,0,0,0,0,0,0,0,0,0,0,0,0,0,0,0,0,0,0,0,0,0,0,0,0,0,0,0,0,0,0,0
0,0,0,0,0,0,0,0,0,0,0,0,0,0,0,0,0,0,0,0,0,0,0,0,0,0,0,0,0,0,0,0,0,0,0,0
0,0,0,0,0,0,0,0,0,0,0,0,0,0,0,0,0,0,0,0,0,0,0,0,0,0,0,0,0,0,0,0,0,0,0,0
0,0,0,0,0,0,0,0,0,0,0,0,0,0,0,0,0,0,0,0,0,0,0,0,0,0,0,0,0,0,0,0,0,0,0,0
0,0,0,0,0,0,0,0,0,0,0,0,0,0,0,0,0,0,0,0,0,0,0,0,0,0,0,0,0,0,0,0,0,0,0,0
0,0,0,0,0,0,0,0,0,0,0,0,0,0,0,0,0,0,0,0,0,0,0,0,0,0,0,0,0,0,0,0,0,0,0,0
0,0,0,0,0,0,0,0,0,0,0,0,0,0,0,0,0,0,0,0,0,0,0,0,0,0,0,0,0,0,0,0,0,0,0,0
endlayer

layer
0,0,0,0,0,0,0,0,0,0,0,0,0,0,0,0,0,0,0,0,0,0,0,0,0,0,0,0,0,0,0,0,0,0,0,0
0,0,0,0,0,0,0,0,0,0,0,0,0,0,0,0,0,0,0,0,0,0,0,0,0,0,0,0,0,0,0,0,0,0,0,0
0,0,0,0,0,0,0,0,0,0,0,0,0,0,0,0,0,0,0,0,0,0,0,0,0,0,0,0,0,0,0,0,0,0,0,0
0,0,0,0,0,0,0,0,0,0,0,0,0,0,0,0,0,0,0,0,0,0,0,0,0,0,0,0,0,0,0,0,0,0,0,0
0,0,0,0,0,0,0,0,0,0,0,0,0,0,0,0,0,0,0,0,0,0,0,0,0,0,0,0,0,0,0,0,0,0,0,0
0,0,0,0,0,0,0,0,0,0,0,0,0,0,0,0,0,0,0,0,0,0,0,0,0,0,0,0,0,0,0,0,0,0,0,0
0,0,0,0,0,0,0,0,0,0,0,0,0,0,0,0,0,0,0,0,0,0,0,0,0,0,0,0,0,0,0,0,0,0,0,0
0,0,0,0,0,0,0,0,0,0,0,0,0,0,0,0,0,0,0,0,0,0,0,0,0,0,0,0,0,0,0,0,0,0,0,0
0,0,0,0,0,0,0,0,0,0,0,0,0,0,0,0,0,0,0,0,0,0,0,0,0,0,0,0,0,0,0,0,0,0,0,0
0,0,0,0,0,0,0,0,0,0,0,0,0,0,0,0,0,0,0,0,0,0,0,0,0,0,0,0,0,0,0,0,0,0,0,0
0,0,0,0,0,0,0,0,0,0,0,0,0,0,0,0,0,0,0,0,0,0,0,0,0,0,0,0,0,0,0,0,0,0,0,0
0,0,0,0,0,0,0,0,0,0,0,0,0,0,0,0,0,0,0,0,0,0,0,0,0,0,0,0,0,0,0,0,0,0,0,0
0,0,0,0,0,0,0,0,0,0,0,0,0,0,0,46,46,46,0,0,0,0,0,0,0,0,0,0,0,0,0,0,0,0,0,0
0,0,0,0,0,0,0,0,0,0,0,0,0,0,46,46,46,46,46,0,0,0,0,0,0,0,0,0,0,0,0,0,0,0,0,0
0,0,0,0,0,0,0,0,0,0,0,0,0,46,46,48,48,48,46,46,0,0,0,0,0,0,0,0,0,0,0,0,0,0,0,0
0,0,0,0,0,0,0,0,0,0,0,0,46,46,48,48,48,47,48,46,46,0,0,0,0,0,0,0,0,0,0,0,0,0,0,0
0,0,0,0,0,0,0,0,0,0,0,0,46,46,47,48,48,47,48,46,46,0,0,0,0,0,0,0,0,0,0,0,0,0,0,0
0,0,0,0,0,0,0,0,0,0,0,0,46,46,48,48,47,48,47,46,46,0,0,0,0,0,0,0,0,0,0,0,0,0,0,0
0,0,0,0,0,0,0,0,0,0,0,0,0,46,46,48,48,48,46,46,0,0,0,0,0,0,0,0,0,0,0,0,0,0,0,0
0,0,0,0,0,0,0,0,0,0,0,0,0,0,46,46,46,46,46,0,0,0,0,0,0,0,0,0,0,0,0,0,0,0,0,0
0,0,0,0,0,0,0,0,0,0,0,0,0,0,0,46,46,46,0,0,0,0,0,0,0,0,0,0,0,0,0,0,0,0,0,0
0,0,0,0,0,0,0,0,0,0,0,0,0,0,0,0,0,0,0,0,0,0,0,0,0,0,0,0,0,0,0,0,0,0,0,0
0,0,0,0,0,0,0,0,0,0,0,0,0,0,0,0,0,0,0,0,0,0,0,0,0,0,0,0,0,0,0,0,0,0,0,0
0,0,0,0,0,0,0,0,0,0,0,0,0,0,0,0,0,0,0,0,0,0,0,0,0,0,0,0,0,0,0,0,0,0,0,0
0,0,0,0,0,0,0,0,0,0,0,0,0,0,0,0,0,0,0,0,0,0,0,0,0,0,0,0,0,0,0,0,0,0,0,0
0,0,0,0,0,0,0,0,0,0,0,0,0,0,0,0,0,0,0,0,0,0,0,0,0,0,0,0,0,0,0,0,0,0,0,0
0,0,0,0,0,0,0,0,0,0,0,0,0,0,0,0,0,0,0,0,0,0,0,0,0,0,0,0,0,0,0,0,0,0,0,0
0,0,0,0,0,0,0,0,0,0,0,0,0,0,0,0,0,0,0,0,0,0,0,0,0,0,0,0,0,0,0,0,0,0,0,0
0,0,0,0,0,0,0,0,0,0,0,0,0,0,0,0,0,0,0,0,0,0,0,0,0,0,0,0,0,0,0,0,0,0,0,0
0,0,0,0,0,0,0,0,0,0,0,0,0,0,0,0,0,0,0,0,0,0,0,0,0,0,0,0,0,0,0,0,0,0,0,0
0,0,0,0,0,0,0,0,0,0,0,0,0,0,0,0,0,0,0,0,0,0,0,0,0,0,0,0,0,0,0,0,0,0,0,0
0,0,0,0,0,0,0,0,0,0,0,0,0,0,0,0,0,0,0,0,0,0,0,0,0,0,0,0,0,0,0,0,0,0,0,0
0,0,0,0,0,0,0,0,0,0,0,0,0,0,0,0,0,0,0,0,0,0,0,0,0,0,0,0,0,0,0,0,0,0,0,0
0,0,0,0,0,0,0,0,0,0,0,0,0,0,0,0,0,0,0,0,0,0,0,0,0,0,0,0,0,0,0,0,0,0,0,0
0,0,0,0,0,0,0,0,0,0,0,0,0,0,0,0,0,0,0,0,0,0,0,0,0,0,0,0,0,0,0,0,0,0,0,0
0,0,0,0,0,0,0,0,0,0,0,0,0,0,0,0,0,0,0,0,0,0,0,0,0,0,0,0,0,0,0,0,0,0,0,0
0,0,0,0,0,0,0,0,0,0,0,0,0,0,0,0,0,0,0,0,0,0,0,0,0,0,0,0,0,0,0,0,0,0,0,0
0,0,0,0,0,0,0,0,0,0,0,0,0,0,0,0,0,0,0,0,0,0,0,0,0,0,0,0,0,0,0,0,0,0,0,0
endlayer

layer
0,0,0,0,0,0,0,0,0,0,0,0,0,0,0,0,0,0,0,0,0,0,0,0,0,0,0,0,0,0,0,0,0,0,0,0
0,0,0,0,0,0,0,0,0,0,0,0,0,0,0,0,0,0,0,0,0,0,0,0,0,0,0,0,0,0,0,0,0,0,0,0
0,0,0,0,0,0,0,0,0,0,0,0,0,0,0,0,0,0,0,0,0,0,0,0,0,0,0,0,0,0,0,0,0,0,0,0
0,0,0,0,0,0,0,0,0,0,0,0,0,0,0,0,0,0,0,0,0,0,0,0,0,0,0,0,0,0,0,0,0,0,0,0
0,0,0,0,0,0,0,0,0,0,0,0,0,0,0,0,0,0,0,0,0,0,0,0,0,0,0,0,0,0,0,0,0,0,0,0
0,0,0,0,0,0,0,0,0,0,0,0,0,0,0,0,0,0,0,0,0,0,0,0,0,0,0,0,0,0,0,0,0,0,0,0
0,0,0,0,0,0,0,0,0,0,0,0,0,0,0,0,0,0,0,0,0,0,0,0,0,0,0,0,0,0,0,0,0,0,0,0
0,0,0,0,0,0,0,0,0,0,0,0,0,0,0,0,0,0,0,0,0,0,0,0,0,0,0,0,0,0,0,0,0,0,0,0
0,0,0,0,0,0,0,0,0,0,0,0,0,0,0,0,0,0,0,0,0,0,0,0,0,0,0,0,0,0,0,0,0,0,0,0
0,0,0,0,0,0,0,0,0,0,0,0,0,0,0,0,0,0,0,0,0,0,0,0,0,0,0,0,0,0,0,0,0,0,0,0
0,0,0,0,0,0,0,0,0,0,0,0,0,0,0,0,0,0,0,0,0,0,0,0,0,0,0,0,0,0,0,0,0,0,0,0
0,0,0,0,0,0,0,0,0,0,0,0,0,0,0,0,0,0,0,0,0,0,0,0,0,0,0,0,0,0,0,0,0,0,0,0
0,0,0,0,0,0,0,0,0,0,0,0,0,0,0,0,0,0,0,0,0,0,0,0,0,0,0,0,0,0,0,0,0,0,0,0
0,0,0,0,0,0,0,0,0,0,0,0,0,0,0,0,0,0,0,0,0,0,0,0,0,0,0,0,0,0,0,0,0,0,0,0
0,0,0,0,0,0,0,0,0,0,0,0,0,0,0,46,46,46,0,0,0,0,0,0,0,0,0,0,0,0,0,0,0,0,0,0
0,0,0,0,0,0,0,0,0,0,0,0,0,0,46,46,46,46,46,0,0,0,0,0,0,0,0,0,0,0,0,0,0,0,0,0
0,0,0,0,0,0,0,0,0,0,0,0,0,0,46,46,46,46,46,0,0,0,0,0,0,0,0,0,0,0,0,0,0,0,0,0
0,0,0,0,0,0,0,0,0,0,0,0,0,0,46,46,46,46,46,0,0,0,0,0,0,0,0,0,0,0,0,0,0,0,0,0
0,0,0,0,0,0,0,0,0,0,0,0,0,0,0,46,46,46,0,0,0,0,0,0,0,0,0,0,0,0,0,0,0,0,0,0
0,0,0,0,0,0,0,0,0,0,0,0,0,0,0,0,0,0,0,0,0,0,0,0,0,0,0,0,0,0,0,0,0,0,0,0
0,0,0,0,0,0,0,0,0,0,0,0,0,0,0,0,0,0,0,0,0,0,0,0,0,0,0,0,0,0,0,0,0,0,0,0
0,0,0,0,0,0,0,0,0,0,0,0,0,0,0,0,0,0,0,0,0,0,0,0,0,0,0,0,0,0,0,0,0,0,0,0
0,0,0,0,0,0,0,0,0,0,0,0,0,0,0,0,0,0,0,0,0,0,0,0,0,0,0,0,0,0,0,0,0,0,0,0
0,0,0,0,0,0,0,0,0,0,0,0,0,0,0,0,0,0,0,0,0,0,0,0,0,0,0,0,0,0,0,0,0,0,0,0
0,0,0,0,0,0,0,0,0,0,0,0,0,0,0,0,0,0,0,0,0,0,0,0,0,0,0,0,0,0,0,0,0,0,0,0
0,0,0,0,0,0,0,0,0,0,0,0,0,0,0,0,0,0,0,0,0,0,0,0,0,0,0,0,0,0,0,0,0,0,0,0
0,0,0,0,0,0,0,0,0,0,0,0,0,0,0,0,0,0,0,0,0,0,0,0,0,0,0,0,0,0,0,0,0,0,0,0
0,0,0,0,0,0,0,0,0,0,0,0,0,0,0,0,0,0,0,0,0,0,0,0,0,0,0,0,0,0,0,0,0,0,0,0
0,0,0,0,0,0,0,0,0,0,0,0,0,0,0,0,0,0,0,0,0,0,0,0,0,0,0,0,0,0,0,0,0,0,0,0
0,0,0,0,0,0,0,0,0,0,0,0,0,0,0,0,0,0,0,0,0,0,0,0,0,0,0,0,0,0,0,0,0,0,0,0
0,0,0,0,0,0,0,0,0,0,0,0,0,0,0,0,0,0,0,0,0,0,0,0,0,0,0,0,0,0,0,0,0,0,0,0
0,0,0,0,0,0,0,0,0,0,0,0,0,0,0,0,0,0,0,0,0,0,0,0,0,0,0,0,0,0,0,0,0,0,0,0
0,0,0,0,0,0,0,0,0,0,0,0,0,0,0,0,0,0,0,0,0,0,0,0,0,0,0,0,0,0,0,0,0,0,0,0
0,0,0,0,0,0,0,0,0,0,0,0,0,0,0,0,0,0,0,0,0,0,0,0,0,0,0,0,0,0,0,0,0,0,0,0
0,0,0,0,0,0,0,0,0,0,0,0,0,0,0,0,0,0,0,0,0,0,0,0,0,0,0,0,0,0,0,0,0,0,0,0
0,0,0,0,0,0,0,0,0,0,0,0,0,0,0,0,0,0,0,0,0,0,0,0,0,0,0,0,0,0,0,0,0,0,0,0
0,0,0,0,0,0,0,0,0,0,0,0,0,0,0,0,0,0,0,0,0,0,0,0,0,0,0,0,0,0,0,0,0,0,0,0
0,0,0,0,0,0,0,0,0,0,0,0,0,0,0,0,0,0,0,0,0,0,0,0,0,0,0,0,0,0,0,0,0,0,0,0
endlayer

