
# Created by Ruins mod version 17.2 Ingame Parser
# authoring Player: Shage_Jack

# TEMPLATE PARAMETER SETTINGS:
#
# criterion expression specifying mod ids required to load template
# may include plus (AND), minus (AND NOT), comma (OR), and parentheses
# all required mods listed must be present; no prohibited mods can be
requiredMods=
#
# likelihood this template will be chosen relative to all others
# e.g., a weight=6 template is chosen 3X as often as one with weight=2
weight=1
#
# list of dimensions in which this template may spawn, even if generic
# one or more dimension names, separated by commas (blank = all)
dimensionsToSpawnIn=
#
# list of other biomes in which this template may spawn
# biome corresponding to directory is always assumed, listed or not
# generic templates should leave this list empty
biomesToSpawnIn=
#
# criterion expression specifying types of biome where template spawns
# this is in addition to those explicitly listed as biomesToSpawnIn
# generic templates should leave this list empty
biomeTypesToSpawnIn=
#
# list of biomes in which this template may not spawn
# takes precedence over biomeTypesToSpawnIn, but NOT biomesToSpawnIn
# should be empty if biomeTypesToSpawnIn is empty
biomesToNotSpawnIn=
#
# depth template is pushed down into the surface when built
# offset is min/max range of random additional bury depth
embed_into_distance=0
random_height_offset=0,0
#
# whitelist/blacklist of block types on which template may be built
# specify one, not both; leave the other empty (both empty = allow all)
acceptable_target_blocks=
unacceptable_target_blocks=flowing_water,water,flowing_lava,lava
#
# size of template (#layers, #rows per layer, #blocks per row)
dimensions=8,32,32
#
# max number of missing blocks allowed in surface beneath template
allowable_overhang=0
#
# depth/height limit affected by terrain leveling
# also maximum bumpiness tolerated in surface beneath template
max_leveling=2
#
# padding applied to all sides of template horizontal footprint
# expands area affected by terrain leveling (-1 = no leveling)
leveling_buffer=0
#
# do not rotate template randomly when built (1 = no rotation)
preventRotation=0
#
# treat water/lava blocks as air and protect them from rule0 (1 = yes)
preserve_water=0
preserve_lava=0
#
# minimum distance this template must have from instances of itself
uniqueMinDistance=0
#
# min/max distances this template can be from world spawn (0 = no limit)
# only applies to overworld--i.e., dimension 0
spawnMinDistance=0
spawnMaxDistance=0
#
# other template built nearby whenever this one is
# syntax: <name>;<relativeX>;<maxYdifference>;<relativeZ>[;<chance>]
# may be used more than once to specify multiple neighbors
adjoining_template=

rule1=0,100,minecraft:grass-0
rule2=0,100,minecraft:dirt-0
rule3=0,100,soviet:nii_blocks-2
rule4=0,100,minecraft:dirt-1
rule5=0,100,gregtech:meta_block_compressed_6-14
rule6=0,100,primal:cinis_block-0
rule7=0,100,primal:ore_bog_iron-2
rule8=0,100,soviet:soviet_bricks_crack-0
rule9=0,100,minecraft:tallgrass-1
rule10=0,100,minecraft:double_plant-2
rule11=0,100,ChestGenHook:chests/apartmentbuilding1:5-5
rule12=0,100,soviet:soviet_box-1
rule13=0,100,minecraft:double_plant-3
rule14=0,100,minecraft:yellow_flower-0
rule15=0,100,minecraft:red_flower-0
rule16=0,100,minecraft:red_flower-3
rule17=0,100,minecraft:log-0
rule18=0,100,primal:rush-3
rule19=0,100,minecraft:red_flower-8
rule20=0,100,soviet:rubbish-0
rule21=0,100,soviet:physical/copper_rings-1
rule22=0,100,soviet:rubbish-1
rule23=0,100,soviet:soviet_chair_wood-2
rule24=0,100,bibliocraft:table-5
rule25=0,100,soviet:soviet_chair_wood-0
rule26=0,100,soviet:rubbish-2
rule27=0,100,minecraft:red_flower-7
rule28=0,100,soviet:street_fence-1
rule29=0,100,soviet:beton_with_ralling-6
rule30=0,100,minecraft:red_flower-4
rule31=0,100,minecraft:red_flower-5
rule32=0,100,IInventory;immcraft:in_world_placer;primal:bone_point#1#0#0+gregtech:meta_item_1#1#93#3-2
rule33=0,100,IInventory;immcraft:in_world_placer;primal:bone_point#1#0#0-3
rule34=0,100,IInventory;immcraft:in_world_placer;primal:bone_knapp#1#0#0+primal:bone_knapp#1#0#1+gregtech:meta_item_1#1#93#3-3
rule35=0,100,soviet:rubbish-3
rule36=0,100,soviet:rusty_ralling-0
rule37=0,100,minecraft:double_plant-10
rule38=0,100,primal:rush-4
rule39=0,100,minecraft:leaves-0
rule40=0,100,primal:rush-12
rule41=0,100,soviet:n-2
rule42=0,100,soviet:a-2
rule43=0,100,soviet:o-2
rule44=0,100,soviet:d-2
rule45=0,100,soviet:ui-2
rule46=0,100,soviet:ia-2
rule47=0,100,soviet:p-2
rule48=0,100,soviet:r-2
rule49=0,100,soviet:k-2

layer
1,1,1,1,1,1,1,1,1,1,1,1,1,1,1,2,2,2,2,1,1,1,1,1,1,1,1,1,1,1,1,1
1,2,2,2,2,2,2,2,2,2,2,2,2,2,2,2,2,2,2,2,2,2,2,2,2,2,2,2,2,2,2,1
1,2,1,1,1,1,1,1,1,1,1,1,1,1,1,1,1,1,1,1,1,1,1,1,1,1,1,1,1,1,2,1
1,2,1,1,1,1,1,1,1,1,1,1,1,1,1,1,1,1,1,1,1,1,1,1,1,1,1,1,1,1,2,1
1,2,1,1,1,1,1,1,1,1,1,1,1,1,1,1,1,2,1,1,1,1,1,1,1,1,1,1,1,1,2,1
1,2,1,1,1,1,1,1,1,1,1,1,1,1,1,1,1,1,1,1,1,1,1,2,1,1,1,1,1,1,2,1
1,2,1,1,1,1,1,1,1,2,1,1,1,1,1,1,1,1,1,1,1,1,1,1,1,1,1,1,1,1,2,1
1,2,1,1,1,1,1,1,1,1,1,3,3,3,3,3,3,3,3,3,3,3,3,1,1,1,1,2,1,1,2,1
1,2,1,1,1,1,1,1,1,1,1,3,3,3,3,3,3,3,3,3,3,3,3,3,1,1,1,1,1,1,2,1
1,2,1,1,2,1,1,1,1,3,3,3,3,1,1,1,1,1,1,1,1,1,3,3,3,3,1,1,1,1,2,1
1,2,1,1,1,1,1,1,3,3,3,3,3,1,1,1,1,1,1,1,1,1,1,1,3,3,3,1,1,1,2,1
1,2,1,1,1,1,1,3,3,3,1,1,1,1,1,1,1,1,1,1,1,1,1,1,1,3,3,1,1,1,2,1
1,2,1,1,1,1,3,3,3,1,1,1,1,1,1,1,1,2,1,1,1,1,1,1,1,3,3,2,1,1,1,1
1,2,1,1,1,3,3,3,1,1,1,1,2,1,1,1,1,1,1,1,1,1,1,1,1,3,3,1,1,1,1,1
1,3,3,3,3,3,3,1,1,1,1,1,1,1,1,1,1,1,1,1,1,1,2,1,1,3,3,1,1,1,2,1
1,3,3,3,3,3,3,1,1,1,1,1,1,1,1,4,4,4,4,1,1,1,1,1,1,3,3,1,1,1,2,1
1,3,3,3,3,3,1,1,1,1,1,1,1,1,4,2,2,2,4,4,1,1,1,1,1,3,3,1,1,1,2,1
1,3,3,3,3,3,1,1,1,1,1,1,1,4,2,2,2,2,2,4,4,1,1,1,1,3,3,1,1,1,2,1
1,2,1,1,3,3,1,1,1,2,1,1,4,2,2,5,6,5,4,2,4,1,1,1,1,3,3,2,1,1,2,1
1,2,1,1,3,3,3,1,1,1,1,4,2,2,5,6,7,6,5,2,2,4,1,1,1,3,3,1,1,1,2,1
1,2,1,1,3,3,3,1,1,1,1,4,2,2,5,6,6,7,5,2,2,4,1,1,3,3,3,1,1,1,2,1
1,2,1,1,2,3,3,1,1,1,1,1,2,2,2,5,6,5,5,2,4,1,3,3,3,3,1,1,1,1,2,1
1,2,1,1,1,3,3,3,1,1,1,1,1,2,2,2,5,5,2,2,1,1,3,3,3,1,1,1,1,1,2,1
1,2,1,1,1,1,3,3,3,3,1,1,1,1,1,2,2,2,4,3,3,3,3,3,1,1,1,1,1,1,2,1
1,2,1,1,1,1,3,3,3,3,3,3,1,1,1,4,4,4,3,3,3,3,3,1,1,1,1,1,1,1,2,1
1,2,1,1,1,1,1,2,1,3,3,3,3,3,3,3,3,3,3,3,1,1,1,1,1,1,1,1,1,1,2,1
1,2,1,1,1,1,1,1,2,1,1,3,3,3,3,3,3,3,3,1,2,1,1,1,1,1,2,1,1,1,2,1
1,2,1,1,1,1,1,1,1,1,1,1,1,2,1,1,1,2,1,1,1,1,1,1,1,1,1,1,1,1,2,1
1,2,1,1,1,1,1,1,1,1,1,1,1,1,1,1,1,1,1,1,1,1,1,1,1,1,1,1,1,1,2,1
1,2,1,1,1,1,1,1,1,1,1,1,1,1,1,1,1,1,1,1,1,1,1,1,1,1,1,1,1,1,2,1
1,2,2,2,2,2,2,2,2,2,2,2,2,2,2,2,2,2,2,2,2,2,2,2,2,2,2,2,2,2,2,1
1,1,1,1,1,1,1,1,1,1,1,1,1,2,2,1,1,1,1,1,1,1,1,1,1,1,1,1,1,1,1,1
endlayer

layer
0,0,0,0,0,0,0,0,0,0,0,0,0,0,0,8,8,8,8,0,0,0,0,0,0,0,0,0,0,0,0,0
0,8,8,8,8,8,8,8,8,8,8,8,8,8,8,8,8,8,8,8,8,8,8,8,8,8,8,8,8,8,8,0
0,8,0,0,0,0,0,0,0,0,0,0,0,0,9,9,13,13,10,0,13,12,11,0,9,10,9,0,0,0,8,0
0,8,0,0,0,0,0,0,0,9,0,9,9,9,0,9,13,0,0,10,13,15,13,10,9,9,14,10,0,0,8,0
0,8,0,0,0,0,0,9,0,0,10,10,18,9,9,9,0,17,0,13,13,13,13,0,16,9,9,9,14,0,8,0
0,8,0,0,0,0,0,0,0,0,9,0,10,10,18,16,0,0,0,10,9,9,0,17,0,9,0,0,0,9,8,0
0,8,0,0,0,9,9,9,9,17,18,0,0,0,0,0,10,0,10,10,19,13,18,10,0,0,0,0,0,0,8,0
0,8,0,0,0,9,9,18,10,13,0,0,0,0,0,0,0,20,21,20,0,0,0,0,18,0,0,17,0,0,8,0
0,8,0,0,0,9,9,19,9,9,0,0,0,0,0,0,0,20,21,0,0,0,0,0,0,0,0,9,9,9,8,0
0,8,0,0,17,9,0,20,20,0,0,0,0,0,0,0,13,13,21,0,9,9,0,0,0,0,9,9,16,9,8,0
0,8,0,9,9,0,9,0,0,0,0,0,0,0,0,0,0,0,0,0,9,15,0,0,22,0,0,9,18,9,8,0
0,8,0,9,0,18,0,0,0,20,0,10,9,25,24,23,0,0,0,9,10,9,9,10,0,0,0,9,9,9,8,0
0,8,9,9,27,0,0,0,0,0,0,10,0,0,9,9,0,17,0,9,10,9,10,0,9,0,0,17,9,0,26,0
0,8,9,9,10,0,0,0,0,10,20,0,17,9,9,0,0,13,0,9,0,0,9,0,0,0,0,0,0,0,26,9
0,0,0,0,0,0,0,9,0,18,9,9,9,16,15,18,9,0,26,0,13,9,17,0,0,0,0,10,22,18,8,0
0,28,0,0,0,0,0,9,18,0,9,9,16,9,22,0,22,0,22,0,0,0,26,9,9,0,0,9,18,9,8,0
0,28,0,0,0,0,18,30,9,9,9,18,0,26,29,4,4,4,29,22,0,9,0,0,9,0,22,14,9,9,8,0
0,28,0,0,0,0,18,31,18,9,0,0,13,0,6,5,5,5,6,0,0,9,15,26,14,0,0,10,9,9,8,0
0,8,10,0,0,0,0,0,0,17,0,18,0,6,6,0,0,0,5,6,0,9,18,14,9,0,0,17,14,0,8,0
0,8,0,0,0,0,0,0,18,0,0,0,6,5,0,33,32,0,0,5,4,13,9,26,0,0,0,0,0,0,8,0
0,8,0,0,0,0,0,0,9,9,9,35,4,5,0,0,34,0,0,5,4,29,0,0,0,0,0,10,0,0,8,0
0,8,0,10,17,0,0,35,0,9,9,9,4,6,5,0,0,0,5,6,26,35,26,0,0,0,0,10,0,18,8,0
0,8,10,0,16,0,0,0,0,18,9,29,29,4,6,5,5,5,6,4,0,0,0,0,0,9,10,9,0,0,8,0
0,8,0,0,9,18,0,0,0,0,9,9,18,26,0,6,6,6,0,26,0,0,0,35,9,9,9,9,0,18,8,0
0,8,10,9,18,9,0,0,0,0,0,0,0,19,10,0,26,0,0,0,0,0,0,10,9,9,9,0,0,18,8,0
0,8,0,15,10,18,9,17,0,0,0,0,0,0,0,0,0,0,0,0,18,0,0,0,9,9,9,0,0,0,8,0
0,8,0,9,0,0,10,0,17,9,18,0,0,0,0,0,0,0,0,0,17,0,10,9,0,0,17,0,0,0,8,0
0,8,0,9,0,0,0,0,0,9,9,9,0,17,9,19,9,17,0,0,10,0,10,0,0,0,0,0,0,0,8,0
0,8,0,0,10,0,0,0,10,9,10,9,18,0,10,9,10,0,0,0,0,10,0,0,0,0,0,0,0,0,8,0
0,8,0,10,0,0,0,0,9,0,0,9,0,0,9,0,10,0,0,10,0,0,0,0,10,0,0,0,0,0,8,0
0,8,8,8,8,8,8,8,8,8,8,8,8,8,8,8,8,8,8,8,8,8,8,8,8,8,8,8,8,8,8,0
0,0,0,0,0,0,0,0,0,0,0,0,0,8,8,0,0,0,0,0,0,0,0,0,0,0,0,0,0,0,0,0
endlayer

layer
0,0,0,0,0,0,0,0,0,0,0,0,0,0,0,0,36,36,0,0,0,0,0,0,0,0,0,0,0,0,0,0
0,8,8,8,8,8,8,8,8,8,8,8,8,8,8,8,0,0,8,8,8,8,8,8,8,8,8,8,8,8,8,0
0,8,0,0,0,0,0,0,0,0,0,0,0,0,0,0,37,37,37,0,37,0,0,0,0,37,0,0,0,0,8,0
0,8,0,0,0,0,0,0,0,0,0,0,0,0,0,0,37,0,0,37,37,0,37,37,0,0,0,37,0,0,8,0
0,8,0,0,0,0,0,0,0,0,37,37,38,0,0,0,0,17,0,37,37,37,37,0,0,0,0,0,0,0,8,0
0,8,0,0,0,0,0,0,0,0,0,0,37,37,40,0,0,0,0,37,0,0,0,17,0,39,39,39,39,0,8,0
0,8,0,0,0,0,0,0,0,17,40,0,0,0,0,0,37,0,37,37,0,37,38,37,0,39,39,39,39,39,8,0
0,8,39,39,39,39,0,38,37,37,0,0,0,0,0,0,0,0,0,0,0,0,0,0,38,39,39,17,39,39,8,0
0,8,39,39,39,39,39,0,0,0,0,0,0,0,0,0,0,0,0,0,0,0,0,0,0,39,39,39,39,39,8,0
0,8,39,39,17,39,39,0,0,0,0,0,0,0,0,0,37,37,0,0,0,0,0,0,0,39,39,39,39,0,8,0
0,8,39,39,39,39,39,0,0,0,0,0,0,0,0,0,0,0,0,0,0,0,0,0,0,0,0,0,38,0,8,0
0,8,39,39,39,40,39,0,0,0,0,37,0,0,0,0,0,0,0,0,37,0,0,37,0,0,0,0,0,0,22,0
0,8,0,0,0,0,0,0,0,0,0,37,0,0,0,0,0,17,0,0,37,0,37,0,0,0,0,17,0,0,0,0
0,8,0,0,37,0,0,0,0,37,0,0,17,0,0,0,0,37,0,0,0,0,0,0,0,0,0,0,0,0,0,0
0,0,0,0,0,0,0,0,0,40,0,0,0,0,0,40,0,0,0,0,37,0,17,0,0,0,0,37,0,40,35,0
0,0,0,0,0,0,0,0,38,0,0,0,0,0,0,0,0,0,0,0,0,0,0,0,0,0,0,0,38,0,8,0
0,0,0,0,0,0,38,0,0,0,0,38,0,0,0,0,13,22,0,0,0,0,0,0,0,0,0,0,0,0,8,0
0,0,0,0,0,0,40,0,38,0,0,0,37,0,0,0,0,0,0,0,0,0,0,0,0,0,0,37,0,0,8,0
0,8,37,0,0,0,0,0,0,17,0,40,0,0,0,0,0,0,0,0,0,0,38,0,0,0,0,17,0,0,8,0
0,8,0,0,0,0,0,0,38,0,0,0,0,0,0,0,0,0,0,0,22,37,0,0,0,0,0,0,0,0,8,0
0,8,0,0,0,0,0,0,0,0,0,0,0,0,0,0,0,0,0,0,0,0,0,0,0,0,0,37,0,0,8,0
0,8,0,37,17,0,0,0,0,0,0,0,35,0,0,0,0,0,0,0,0,0,0,0,0,0,0,37,0,38,8,0
0,8,37,0,0,0,0,0,0,40,0,0,0,0,0,0,0,0,0,0,0,0,0,0,0,0,37,0,0,0,8,0
0,8,0,0,0,38,0,0,0,0,0,0,40,0,0,0,0,0,0,0,0,0,0,0,0,0,0,0,0,40,8,0
0,8,37,0,40,0,0,0,0,0,0,0,0,0,37,0,0,0,0,0,0,0,0,37,0,39,39,39,0,38,8,0
0,8,0,0,37,38,0,17,0,0,0,0,0,0,0,0,0,0,0,0,38,0,0,0,39,39,39,39,39,0,8,0
0,8,0,0,0,0,37,0,17,0,40,0,0,0,0,0,0,0,0,0,17,0,37,0,39,39,17,39,39,0,8,0
0,8,0,0,0,0,0,0,0,0,0,0,0,17,0,0,0,17,0,0,37,0,37,0,39,39,39,39,39,0,8,0
0,8,0,0,37,0,0,0,37,0,37,0,38,0,37,0,37,0,0,0,0,37,0,0,39,39,39,39,39,0,8,0
0,8,0,37,0,0,0,0,0,0,0,0,0,0,0,0,37,0,0,37,0,0,0,0,37,0,0,0,0,0,8,0
0,8,8,8,8,8,8,8,8,8,8,8,0,0,0,0,8,8,8,8,8,8,8,8,8,8,8,8,8,8,8,0
0,0,0,0,0,0,0,0,0,0,0,0,0,36,36,0,0,0,0,0,0,0,0,0,0,0,0,0,0,0,0,0
endlayer

layer
0,0,0,0,0,0,0,0,0,0,0,0,0,0,0,0,0,0,0,0,0,0,0,0,0,0,0,0,0,0,0,0
0,8,8,8,8,8,8,8,8,8,8,8,8,8,8,0,0,0,0,0,8,8,8,8,8,8,8,8,8,8,8,0
0,8,0,0,0,0,0,0,0,0,0,0,0,0,0,0,39,39,39,39,0,0,0,0,0,0,0,0,0,0,8,0
0,8,0,0,0,0,0,0,0,0,0,0,0,0,0,39,39,39,39,39,0,0,0,0,0,0,0,0,0,0,8,0
0,8,0,0,0,0,0,0,0,0,0,0,0,0,0,39,39,17,39,39,0,0,0,0,0,0,0,0,0,0,8,0
0,8,0,0,0,0,0,0,0,0,0,0,0,0,0,39,39,39,39,39,0,0,0,17,0,39,39,39,39,39,8,0
0,8,0,0,0,0,0,0,0,17,0,0,0,0,0,39,39,39,39,39,0,0,0,0,0,39,39,39,39,39,8,0
0,8,0,39,39,39,0,0,0,0,0,0,0,0,0,0,0,0,0,0,0,0,0,0,0,39,39,17,39,39,8,0
0,8,39,39,39,39,39,0,0,0,0,0,0,0,0,0,0,0,0,0,0,0,0,0,0,39,39,39,39,39,8,0
0,8,39,39,17,39,39,0,0,0,0,0,0,0,0,0,0,0,0,0,0,0,0,0,0,0,39,39,39,0,8,0
0,8,39,39,39,39,39,0,0,0,0,0,0,0,0,0,39,39,39,0,0,0,0,0,0,0,0,0,0,0,8,0
0,8,39,39,39,39,0,0,0,0,0,0,0,0,0,39,39,39,39,39,0,0,0,0,0,0,0,0,0,0,0,0
0,8,0,0,0,0,0,0,0,0,0,0,0,0,0,39,39,17,39,39,0,39,39,39,39,0,0,17,0,0,0,0
0,8,0,0,0,0,0,0,0,0,0,0,17,0,0,39,39,39,39,39,39,39,39,39,39,0,0,0,0,0,0,0
0,0,0,0,0,0,0,0,0,0,0,0,0,0,0,0,39,39,39,0,39,39,17,39,39,0,0,0,0,0,0,0
0,0,0,0,0,0,0,0,0,0,0,0,0,0,0,0,0,0,0,0,39,39,39,39,39,0,0,0,0,0,0,0
0,0,0,0,0,0,0,0,0,0,0,0,0,0,0,0,37,0,0,0,39,39,39,39,39,0,0,0,0,0,8,0
0,0,0,0,0,0,0,0,0,0,0,0,0,0,0,0,0,0,0,0,0,0,0,0,0,0,0,0,0,0,8,0
0,8,0,0,0,0,0,0,0,17,0,0,0,0,0,0,0,0,0,0,0,0,0,0,0,0,0,17,0,0,8,0
0,8,0,0,0,0,0,0,0,0,0,0,0,0,0,0,0,0,0,0,0,0,0,0,0,0,0,0,0,0,8,0
0,8,0,0,0,0,0,0,0,0,0,0,0,0,0,0,0,0,0,0,0,0,0,0,0,0,0,0,0,0,8,0
0,8,0,0,17,0,0,0,0,0,0,0,0,0,0,0,0,0,0,0,0,0,0,0,0,0,0,0,0,0,8,0
0,8,0,0,0,0,0,0,0,0,0,0,0,0,0,0,0,0,0,0,0,0,0,0,0,0,0,0,0,0,8,0
0,8,0,0,0,0,0,0,0,0,0,0,0,0,0,0,0,0,0,0,0,0,0,0,0,0,0,0,0,0,8,0
0,8,0,0,0,0,0,0,0,0,0,0,0,0,0,0,0,0,0,39,39,39,39,0,0,39,39,39,39,0,8,0
0,8,0,0,0,0,0,17,0,0,0,0,0,0,0,0,0,0,39,39,39,39,39,0,39,39,39,39,39,0,8,0
0,8,0,0,0,0,0,0,17,0,0,0,0,0,0,0,0,0,39,39,17,39,39,0,39,39,17,39,39,0,8,0
0,8,0,0,0,0,0,0,0,0,0,0,0,17,0,0,0,17,39,39,39,39,39,0,39,39,39,39,39,0,8,0
0,8,0,0,0,0,0,0,0,0,0,0,0,0,0,0,0,0,39,39,39,39,39,0,0,39,39,39,39,0,8,0
0,8,0,0,0,0,0,0,0,0,0,0,0,0,0,0,0,0,0,0,0,0,0,0,0,0,0,0,0,0,8,0
0,8,8,8,8,8,8,8,8,8,36,0,0,0,0,0,8,8,8,8,8,8,8,8,8,8,8,8,8,8,8,0
0,0,0,0,0,0,0,0,0,0,0,0,0,0,0,0,0,0,0,0,0,0,0,0,0,0,0,0,0,0,0,0
endlayer

layer
0,0,0,0,0,0,0,0,0,0,0,0,0,0,0,0,0,0,0,0,0,0,0,0,0,0,0,0,0,0,0,0
0,36,36,36,36,36,36,36,36,36,36,36,36,36,0,0,0,0,0,0,36,36,36,36,36,36,36,36,36,36,36,0
0,36,0,0,0,0,0,0,0,0,0,0,0,0,0,39,39,39,39,39,0,0,0,0,0,0,0,0,0,0,36,0
0,36,0,0,0,0,0,0,0,0,0,0,0,0,0,39,39,39,39,39,0,39,39,39,39,39,0,0,0,0,36,0
0,0,0,0,0,0,0,39,39,39,39,0,0,0,0,39,39,17,39,39,0,39,39,39,39,39,0,0,0,0,36,0
0,0,0,0,0,0,0,39,39,39,39,39,0,0,0,39,39,39,39,39,0,39,39,17,39,39,0,0,0,0,36,0
0,41,0,0,0,0,0,39,39,17,39,39,0,0,0,39,39,39,39,39,0,39,39,39,39,39,0,39,0,0,36,0
0,42,0,0,0,0,0,39,39,39,39,39,0,0,0,0,0,0,0,0,0,0,39,39,39,39,39,17,39,0,36,0
0,43,0,0,39,39,0,39,39,39,39,39,0,0,0,0,0,0,0,0,0,0,0,0,0,0,39,39,0,0,36,0
0,44,0,39,17,39,0,0,0,0,0,0,0,0,0,0,0,0,0,0,0,0,0,0,0,0,0,0,0,0,0,0
0,41,0,0,39,39,0,0,0,0,0,0,0,0,0,0,39,39,39,39,0,0,0,0,0,0,39,39,39,0,0,0
0,45,0,0,0,0,0,0,0,0,39,39,39,39,39,39,39,39,39,39,0,0,0,0,0,39,39,39,39,39,0,0
0,46,0,0,0,0,0,0,0,0,39,39,39,39,39,39,39,17,39,39,0,39,39,39,0,39,39,17,39,39,0,0
0,0,0,0,0,0,0,0,0,0,39,39,17,39,39,39,39,39,39,39,39,39,39,39,39,39,39,39,39,39,0,0
0,0,0,0,0,0,0,0,0,0,39,39,39,39,39,0,39,39,39,39,39,39,17,39,39,0,39,39,39,39,0,0
0,0,0,0,0,0,0,0,0,0,0,39,39,39,39,0,0,0,0,0,39,39,39,39,39,0,0,0,0,0,0,0
0,0,0,0,0,0,0,39,39,39,39,0,0,0,0,0,0,0,0,0,0,39,39,39,0,39,39,39,39,39,0,0
0,0,0,0,0,0,0,39,39,39,39,39,0,0,0,0,0,0,0,0,0,0,0,0,0,39,39,39,39,39,0,0
0,0,0,0,0,0,0,39,39,17,39,39,0,0,0,0,0,0,0,0,0,0,0,0,0,39,39,17,39,39,0,0
0,47,39,39,39,39,0,39,39,39,39,39,0,0,0,0,0,0,0,0,0,0,0,0,0,39,39,39,39,39,0,0
0,42,39,39,39,39,39,39,39,39,39,0,0,0,0,0,0,0,0,0,0,0,0,0,0,39,39,39,39,39,0,0
0,48,39,39,17,39,39,0,0,0,0,0,0,0,0,0,0,0,0,0,0,0,0,0,0,0,0,0,0,0,36,0
0,49,39,39,39,39,39,0,0,0,0,0,0,0,0,0,0,0,0,0,0,0,0,0,0,0,0,0,0,0,36,0
0,0,39,39,39,39,39,39,39,39,0,0,0,0,0,0,0,0,0,0,0,0,0,0,0,0,0,0,0,0,36,0
0,0,0,0,0,39,39,39,39,39,39,0,0,0,0,0,0,0,39,39,39,39,39,0,0,0,0,0,0,0,36,0
0,36,0,0,0,39,39,17,39,39,39,0,39,39,39,0,39,39,39,39,39,39,39,0,0,39,39,39,0,0,36,0
0,36,0,0,0,39,39,39,17,39,39,39,39,39,39,39,39,39,39,39,17,39,39,0,0,39,17,39,0,0,36,0
0,36,0,0,0,0,39,39,39,39,39,39,39,17,39,39,39,17,39,39,39,39,39,0,0,39,39,39,0,0,36,0
0,36,0,0,0,0,39,39,39,39,0,39,39,39,39,39,39,39,39,39,39,39,39,0,0,0,0,0,0,0,36,0
0,36,0,0,0,0,0,0,0,0,0,39,39,39,39,0,39,39,39,0,0,0,0,0,0,0,0,0,0,0,36,0
0,36,36,36,36,36,36,36,36,36,0,0,0,0,0,0,36,36,36,36,36,36,36,36,36,36,36,36,36,36,36,0
0,0,0,0,0,0,0,0,0,0,0,0,0,0,0,0,0,0,0,0,0,0,0,0,0,0,0,0,0,0,0,0
endlayer

layer
0,0,0,0,0,0,0,0,0,0,0,0,0,0,0,0,0,0,0,0,0,0,0,0,0,0,0,0,0,0,0,0
0,0,0,0,0,0,0,0,0,0,0,0,0,0,0,0,0,0,0,0,0,0,0,0,0,0,0,0,0,0,0,0
0,0,0,0,0,0,0,0,0,0,0,0,0,0,0,0,0,0,0,0,0,0,0,0,0,0,0,0,0,0,0,0
0,0,0,0,0,0,0,0,0,0,0,0,0,0,0,0,0,39,0,0,0,0,39,39,39,39,0,0,0,0,0,0
0,0,0,0,0,0,0,0,39,39,39,0,0,0,0,0,39,17,39,0,0,39,39,39,39,39,0,0,0,0,0,0
0,0,0,0,0,0,0,39,39,39,39,39,0,0,0,0,0,39,0,0,0,39,39,17,39,39,0,0,0,0,0,0
0,0,0,0,0,0,0,39,39,17,39,39,0,0,0,0,0,0,0,0,0,39,39,39,39,39,0,39,0,0,0,0
0,0,0,0,0,0,0,39,39,39,39,39,0,0,0,0,0,0,0,0,0,39,39,39,39,0,39,39,39,0,0,0
0,0,0,0,39,0,0,39,39,39,39,39,0,0,0,0,0,0,0,0,0,0,0,0,0,0,0,39,0,0,0,0
0,0,0,39,39,39,0,0,0,0,0,0,0,0,0,0,0,0,0,0,0,0,0,0,0,0,0,0,0,0,0,0
0,0,0,0,39,0,0,0,0,0,0,0,0,0,0,0,0,0,0,0,0,0,0,0,0,0,39,39,39,39,0,0
0,0,0,0,0,0,0,0,0,0,0,39,39,39,39,0,39,39,0,0,0,0,0,0,0,39,39,39,39,39,0,0
0,0,0,0,0,0,0,0,0,0,39,39,39,39,39,0,39,17,39,0,0,0,0,0,0,39,39,17,39,39,0,0
0,0,0,0,0,0,0,0,0,0,39,39,17,39,39,0,39,39,39,0,0,39,39,39,0,39,39,39,39,39,0,0
0,0,0,0,0,0,0,0,0,0,39,39,39,39,39,0,0,0,0,0,0,39,17,39,0,39,39,39,39,39,0,0
0,0,0,0,0,0,0,0,0,0,39,39,39,39,0,0,0,0,0,0,0,0,39,0,0,0,0,0,0,0,0,0
0,0,0,0,0,0,0,39,39,39,39,0,0,0,0,0,0,0,0,0,0,0,0,0,0,39,39,39,39,39,0,0
0,0,0,0,0,0,0,39,39,39,39,39,0,0,0,0,0,0,0,0,0,0,0,0,0,39,39,39,39,39,0,0
0,0,0,0,0,0,0,39,39,17,39,39,0,0,0,0,0,0,0,0,0,0,0,0,0,39,39,17,39,39,0,0
0,0,0,39,39,39,0,39,39,39,39,39,0,0,0,0,0,0,0,0,0,0,0,0,0,39,39,39,39,39,0,0
0,0,39,39,39,39,39,0,39,39,39,39,0,0,0,0,0,0,0,0,0,0,0,0,0,39,39,39,39,39,0,0
0,0,39,39,17,39,39,0,0,0,0,0,0,0,0,0,0,0,0,0,0,0,0,0,0,0,0,0,0,0,0,0
0,0,39,39,39,39,39,0,0,0,0,0,0,0,0,0,0,0,0,0,0,0,0,0,0,0,0,0,0,0,0,0
0,0,39,39,39,39,39,39,39,39,0,0,0,0,0,0,0,0,0,0,0,0,0,0,0,0,0,0,0,0,0,0
0,0,0,0,0,39,39,39,39,39,39,0,0,0,0,0,0,0,0,0,0,0,0,0,0,0,0,0,0,0,0,0
0,0,0,0,0,39,39,17,39,39,39,0,39,39,39,0,39,39,39,39,39,0,0,0,0,0,39,0,0,0,0,0
0,0,0,0,0,39,39,39,17,39,39,39,39,39,39,39,39,39,39,39,17,39,0,0,0,39,39,39,0,0,0,0
0,0,0,0,0,0,39,39,39,39,39,39,39,17,39,39,39,17,39,39,39,0,0,0,0,0,39,0,0,0,0,0
0,0,0,0,0,0,0,39,39,39,0,39,39,39,39,39,39,39,39,39,0,0,0,0,0,0,0,0,0,0,0,0
0,0,0,0,0,0,0,0,0,0,0,0,39,39,39,0,39,39,39,0,0,0,0,0,0,0,0,0,0,0,0,0
0,0,0,0,0,0,0,0,0,0,0,0,0,0,0,0,0,0,0,0,0,0,0,0,0,0,0,0,0,0,0,0
0,0,0,0,0,0,0,0,0,0,0,0,0,0,0,0,0,0,0,0,0,0,0,0,0,0,0,0,0,0,0,0
endlayer

layer
0,0,0,0,0,0,0,0,0,0,0,0,0,0,0,0,0,0,0,0,0,0,0,0,0,0,0,0,0,0,0,0
0,0,0,0,0,0,0,0,0,0,0,0,0,0,0,0,0,0,0,0,0,0,0,0,0,0,0,0,0,0,0,0
0,0,0,0,0,0,0,0,0,0,0,0,0,0,0,0,0,0,0,0,0,0,0,0,0,0,0,0,0,0,0,0
0,0,0,0,0,0,0,0,0,0,0,0,0,0,0,0,0,39,0,0,0,0,0,0,0,0,0,0,0,0,0,0
0,0,0,0,0,0,0,0,0,0,0,0,0,0,0,0,39,39,39,0,0,0,39,39,0,0,0,0,0,0,0,0
0,0,0,0,0,0,0,0,0,39,0,0,0,0,0,0,0,39,0,0,0,0,39,17,39,0,0,0,0,0,0,0
0,0,0,0,0,0,0,0,39,17,39,0,0,0,0,0,0,0,0,0,0,0,0,39,0,0,0,0,0,0,0,0
0,0,0,0,0,0,0,0,0,39,0,0,0,0,0,0,0,0,0,0,0,0,0,0,0,0,0,0,0,0,0,0
0,0,0,0,0,0,0,0,0,0,0,0,0,0,0,0,0,0,0,0,0,0,0,0,0,0,0,0,0,0,0,0
0,0,0,0,0,0,0,0,0,0,0,0,0,0,0,0,0,0,0,0,0,0,0,0,0,0,0,0,0,0,0,0
0,0,0,0,0,0,0,0,0,0,0,0,0,0,0,0,0,0,0,0,0,0,0,0,0,0,0,0,0,0,0,0
0,0,0,0,0,0,0,0,0,0,0,0,0,0,0,0,0,39,0,0,0,0,0,0,0,0,0,39,0,0,0,0
0,0,0,0,0,0,0,0,0,0,0,0,39,39,0,0,39,39,39,0,0,0,0,0,0,0,39,17,39,0,0,0
0,0,0,0,0,0,0,0,0,0,0,39,17,39,0,0,0,39,0,0,0,0,39,0,0,0,0,39,0,0,0,0
0,0,0,0,0,0,0,0,0,0,0,39,39,0,0,0,0,0,0,0,0,39,39,39,0,0,0,0,0,0,0,0
0,0,0,0,0,0,0,0,0,0,0,0,0,0,0,0,0,0,0,0,0,0,39,0,0,0,0,0,0,0,0,0
0,0,0,0,0,0,0,0,0,0,0,0,0,0,0,0,0,0,0,0,0,0,0,0,0,0,0,0,0,0,0,0
0,0,0,0,0,0,0,0,0,39,0,0,0,0,0,0,0,0,0,0,0,0,0,0,0,0,39,39,0,0,0,0
0,0,0,0,0,0,0,0,39,17,39,0,0,0,0,0,0,0,0,0,0,0,0,0,0,0,39,17,39,0,0,0
0,0,0,0,0,0,0,0,0,39,39,0,0,0,0,0,0,0,0,0,0,0,0,0,0,0,39,39,39,0,0,0
0,0,0,0,39,39,0,0,0,0,0,0,0,0,0,0,0,0,0,0,0,0,0,0,0,0,0,0,0,0,0,0
0,0,0,39,17,39,0,0,0,0,0,0,0,0,0,0,0,0,0,0,0,0,0,0,0,0,0,0,0,0,0,0
0,0,0,0,39,0,0,0,0,0,0,0,0,0,0,0,0,0,0,0,0,0,0,0,0,0,0,0,0,0,0,0
0,0,0,0,0,0,0,0,0,0,0,0,0,0,0,0,0,0,0,0,0,0,0,0,0,0,0,0,0,0,0,0
0,0,0,0,0,0,39,39,39,0,0,0,0,0,0,0,0,0,0,0,0,0,0,0,0,0,0,0,0,0,0,0
0,0,0,0,0,0,39,17,39,0,0,0,0,0,0,0,0,0,0,0,39,0,0,0,0,0,0,0,0,0,0,0
0,0,0,0,0,0,39,39,17,39,0,0,0,39,39,0,39,39,0,39,39,39,0,0,0,0,0,0,0,0,0,0
0,0,0,0,0,0,0,0,39,0,0,0,39,17,39,0,39,17,39,0,39,0,0,0,0,0,0,0,0,0,0,0
0,0,0,0,0,0,0,0,0,0,0,0,0,39,39,0,0,39,0,0,0,0,0,0,0,0,0,0,0,0,0,0
0,0,0,0,0,0,0,0,0,0,0,0,0,0,0,0,0,0,0,0,0,0,0,0,0,0,0,0,0,0,0,0
0,0,0,0,0,0,0,0,0,0,0,0,0,0,0,0,0,0,0,0,0,0,0,0,0,0,0,0,0,0,0,0
0,0,0,0,0,0,0,0,0,0,0,0,0,0,0,0,0,0,0,0,0,0,0,0,0,0,0,0,0,0,0,0
endlayer

layer
0,0,0,0,0,0,0,0,0,0,0,0,0,0,0,0,0,0,0,0,0,0,0,0,0,0,0,0,0,0,0,0
0,0,0,0,0,0,0,0,0,0,0,0,0,0,0,0,0,0,0,0,0,0,0,0,0,0,0,0,0,0,0,0
0,0,0,0,0,0,0,0,0,0,0,0,0,0,0,0,0,0,0,0,0,0,0,0,0,0,0,0,0,0,0,0
0,0,0,0,0,0,0,0,0,0,0,0,0,0,0,0,0,0,0,0,0,0,0,0,0,0,0,0,0,0,0,0
0,0,0,0,0,0,0,0,0,0,0,0,0,0,0,0,0,0,0,0,0,0,0,39,0,0,0,0,0,0,0,0
0,0,0,0,0,0,0,0,0,39,0,0,0,0,0,0,0,0,0,0,0,0,39,39,39,0,0,0,0,0,0,0
0,0,0,0,0,0,0,0,39,39,39,0,0,0,0,0,0,0,0,0,0,0,0,39,0,0,0,0,0,0,0,0
0,0,0,0,0,0,0,0,0,39,0,0,0,0,0,0,0,0,0,0,0,0,0,0,0,0,0,0,0,0,0,0
0,0,0,0,0,0,0,0,0,0,0,0,0,0,0,0,0,0,0,0,0,0,0,0,0,0,0,0,0,0,0,0
0,0,0,0,0,0,0,0,0,0,0,0,0,0,0,0,0,0,0,0,0,0,0,0,0,0,0,0,0,0,0,0
0,0,0,0,0,0,0,0,0,0,0,0,0,0,0,0,0,0,0,0,0,0,0,0,0,0,0,0,0,0,0,0
0,0,0,0,0,0,0,0,0,0,0,0,0,0,0,0,0,0,0,0,0,0,0,0,0,0,0,39,0,0,0,0
0,0,0,0,0,0,0,0,0,0,0,0,39,0,0,0,0,0,0,0,0,0,0,0,0,0,39,39,39,0,0,0
0,0,0,0,0,0,0,0,0,0,0,39,39,39,0,0,0,0,0,0,0,0,0,0,0,0,0,39,0,0,0,0
0,0,0,0,0,0,0,0,0,0,0,0,39,0,0,0,0,0,0,0,0,0,0,0,0,0,0,0,0,0,0,0
0,0,0,0,0,0,0,0,0,0,0,0,0,0,0,0,0,0,0,0,0,0,0,0,0,0,0,0,0,0,0,0
0,0,0,0,0,0,0,0,0,0,0,0,0,0,0,0,0,0,0,0,0,0,0,0,0,0,0,0,0,0,0,0
0,0,0,0,0,0,0,0,0,39,0,0,0,0,0,0,0,0,0,0,0,0,0,0,0,0,0,39,0,0,0,0
0,0,0,0,0,0,0,0,39,39,39,0,0,0,0,0,0,0,0,0,0,0,0,0,0,0,39,39,39,0,0,0
0,0,0,0,0,0,0,0,0,39,0,0,0,0,0,0,0,0,0,0,0,0,0,0,0,0,0,39,0,0,0,0
0,0,0,0,39,0,0,0,0,0,0,0,0,0,0,0,0,0,0,0,0,0,0,0,0,0,0,0,0,0,0,0
0,0,0,39,39,39,0,0,0,0,0,0,0,0,0,0,0,0,0,0,0,0,0,0,0,0,0,0,0,0,0,0
0,0,0,0,39,0,0,0,0,0,0,0,0,0,0,0,0,0,0,0,0,0,0,0,0,0,0,0,0,0,0,0
0,0,0,0,0,0,0,0,0,0,0,0,0,0,0,0,0,0,0,0,0,0,0,0,0,0,0,0,0,0,0,0
0,0,0,0,0,0,0,39,0,0,0,0,0,0,0,0,0,0,0,0,0,0,0,0,0,0,0,0,0,0,0,0
0,0,0,0,0,0,39,39,39,0,0,0,0,0,0,0,0,0,0,0,0,0,0,0,0,0,0,0,0,0,0,0
0,0,0,0,0,0,0,39,39,39,0,0,0,39,0,0,0,39,0,0,0,0,0,0,0,0,0,0,0,0,0,0
0,0,0,0,0,0,0,0,39,0,0,0,39,39,39,0,39,39,39,0,0,0,0,0,0,0,0,0,0,0,0,0
0,0,0,0,0,0,0,0,0,0,0,0,0,39,0,0,0,39,0,0,0,0,0,0,0,0,0,0,0,0,0,0
0,0,0,0,0,0,0,0,0,0,0,0,0,0,0,0,0,0,0,0,0,0,0,0,0,0,0,0,0,0,0,0
0,0,0,0,0,0,0,0,0,0,0,0,0,0,0,0,0,0,0,0,0,0,0,0,0,0,0,0,0,0,0,0
0,0,0,0,0,0,0,0,0,0,0,0,0,0,0,0,0,0,0,0,0,0,0,0,0,0,0,0,0,0,0,0
endlayer

